2020-05-03 21:48:04.562 [error] <0.432.0> gen_server <0.432.0> terminated with reason: {socket_error,timeout}
2020-05-03 21:48:04.562 [error] <0.460.0> gen_server <0.460.0> terminated with reason: {socket_error,timeout}
2020-05-03 21:48:04.562 [error] <0.463.0> gen_server <0.463.0> terminated with reason: {socket_error,timeout}
2020-05-03 21:48:04.562 [error] <0.428.0> gen_server <0.428.0> terminated with reason: {socket_error,timeout}
2020-05-03 21:48:04.563 [error] <0.462.0> gen_server <0.462.0> terminated with reason: {socket_error,timeout}
2020-05-03 21:48:04.563 [error] <0.461.0> gen_server <0.461.0> terminated with reason: {socket_error,timeout}
2020-05-03 21:48:04.563 [error] <0.435.0> gen_server <0.435.0> terminated with reason: {socket_error,timeout}
2020-05-03 21:48:04.563 [error] <0.459.0> gen_server <0.459.0> terminated with reason: {socket_error,timeout}
2020-05-03 21:48:04.564 [error] <0.438.0> gen_server <0.438.0> terminated with reason: {socket_error,timeout}
2020-05-03 21:48:04.564 [error] <0.441.0> gen_server <0.441.0> terminated with reason: {socket_error,timeout}
2020-05-03 21:48:04.566 [error] <0.432.0> CRASH REPORT Process <0.432.0> with 0 neighbours exited with reason: {socket_error,timeout} in gen_server:handle_common_reply/8 line 751
2020-05-03 21:48:04.566 [error] <0.438.0> CRASH REPORT Process <0.438.0> with 0 neighbours exited with reason: {socket_error,timeout} in gen_server:handle_common_reply/8 line 751
2020-05-03 21:48:04.567 [error] <0.435.0> CRASH REPORT Process <0.435.0> with 0 neighbours exited with reason: {socket_error,timeout} in gen_server:handle_common_reply/8 line 751
2020-05-03 21:48:04.567 [error] <0.428.0> CRASH REPORT Process <0.428.0> with 0 neighbours exited with reason: {socket_error,timeout} in gen_server:handle_common_reply/8 line 751
2020-05-03 21:48:04.568 [error] <0.430.0> Supervisor {<0.430.0>,amqp_connection_sup} had child connection started with amqp_gen_connection:start_link(<0.431.0>, {amqp_params_network,<<"guest">>,<<"WXbiYoxjNQsnjd4ZoauYGc4O3FX3KPAu9H7as3jStJB+pBMveI4Fv9O1ijDTm2...">>,...}) at <0.432.0> exit with reason {socket_error,timeout} in context child_terminated
2020-05-03 21:48:04.568 [error] <0.430.0> Supervisor {<0.430.0>,amqp_connection_sup} had child connection started with amqp_gen_connection:start_link(<0.431.0>, {amqp_params_network,<<"guest">>,<<"WXbiYoxjNQsnjd4ZoauYGc4O3FX3KPAu9H7as3jStJB+pBMveI4Fv9O1ijDTm2...">>,...}) at <0.432.0> exit with reason reached_max_restart_intensity in context shutdown
2020-05-03 21:48:04.569 [error] <0.433.0> Supervisor {<0.433.0>,amqp_connection_sup} had child connection started with amqp_gen_connection:start_link(<0.434.0>, {amqp_params_network,<<"guest">>,<<"3OX+VbgKjbZy34/i6XEVvcDvpEwHD4rioXGBSO8MN0s8x/e8iNRNdFtKlxTUTf...">>,...}) at <0.435.0> exit with reason {socket_error,timeout} in context child_terminated
2020-05-03 21:48:04.569 [error] <0.441.0> CRASH REPORT Process <0.441.0> with 0 neighbours exited with reason: {socket_error,timeout} in gen_server:handle_common_reply/8 line 751
2020-05-03 21:48:04.570 [error] <0.433.0> Supervisor {<0.433.0>,amqp_connection_sup} had child connection started with amqp_gen_connection:start_link(<0.434.0>, {amqp_params_network,<<"guest">>,<<"3OX+VbgKjbZy34/i6XEVvcDvpEwHD4rioXGBSO8MN0s8x/e8iNRNdFtKlxTUTf...">>,...}) at <0.435.0> exit with reason reached_max_restart_intensity in context shutdown
2020-05-03 21:48:04.571 [error] <0.439.0> Supervisor {<0.439.0>,amqp_connection_sup} had child connection started with amqp_gen_connection:start_link(<0.440.0>, {amqp_params_network,<<"guest">>,<<"ZdUFJn+7a+0IQsyBglUbFmQe0NdL3AlRKOCzj23LnjTikDmhLgzBc8roWL4i4i...">>,...}) at <0.441.0> exit with reason {socket_error,timeout} in context child_terminated
2020-05-03 21:48:04.571 [error] <0.424.0> Supervisor {<0.424.0>,amqp_connection_sup} had child connection started with amqp_gen_connection:start_link(<0.427.0>, {amqp_params_network,<<"guest">>,<<"Ws9MTE8zmFKDPlfYxxfl2rauC5tfVWUnJwS4GYXRQm7f9gVzO1UhAFH1nDgwPV...">>,...}) at <0.428.0> exit with reason {socket_error,timeout} in context child_terminated
2020-05-03 21:48:04.572 [error] <0.436.0> Supervisor {<0.436.0>,amqp_connection_sup} had child connection started with amqp_gen_connection:start_link(<0.437.0>, {amqp_params_network,<<"guest">>,<<"CSmf1buCokUep23isY48LLAL4c7sW1A1ksWhayvNATAejQKvyWJkVt6Unyr2lo...">>,...}) at <0.438.0> exit with reason {socket_error,timeout} in context child_terminated
2020-05-03 21:48:04.572 [error] <0.439.0> Supervisor {<0.439.0>,amqp_connection_sup} had child connection started with amqp_gen_connection:start_link(<0.440.0>, {amqp_params_network,<<"guest">>,<<"ZdUFJn+7a+0IQsyBglUbFmQe0NdL3AlRKOCzj23LnjTikDmhLgzBc8roWL4i4i...">>,...}) at <0.441.0> exit with reason reached_max_restart_intensity in context shutdown
2020-05-03 21:48:04.573 [error] <0.424.0> Supervisor {<0.424.0>,amqp_connection_sup} had child connection started with amqp_gen_connection:start_link(<0.427.0>, {amqp_params_network,<<"guest">>,<<"Ws9MTE8zmFKDPlfYxxfl2rauC5tfVWUnJwS4GYXRQm7f9gVzO1UhAFH1nDgwPV...">>,...}) at <0.428.0> exit with reason reached_max_restart_intensity in context shutdown
2020-05-03 21:48:04.574 [error] <0.436.0> Supervisor {<0.436.0>,amqp_connection_sup} had child connection started with amqp_gen_connection:start_link(<0.437.0>, {amqp_params_network,<<"guest">>,<<"CSmf1buCokUep23isY48LLAL4c7sW1A1ksWhayvNATAejQKvyWJkVt6Unyr2lo...">>,...}) at <0.438.0> exit with reason reached_max_restart_intensity in context shutdown
2020-05-03 22:51:01.424 [error] <0.586.0> gen_server <0.586.0> terminated with reason: {socket_error,timeout}
2020-05-03 22:51:01.424 [error] <0.589.0> gen_server <0.589.0> terminated with reason: {socket_error,timeout}
2020-05-03 22:51:01.424 [error] <0.585.0> gen_server <0.585.0> terminated with reason: {socket_error,timeout}
2020-05-03 22:51:01.424 [error] <0.560.0> gen_server <0.560.0> terminated with reason: {socket_error,timeout}
2020-05-03 22:51:01.425 [error] <0.587.0> gen_server <0.587.0> terminated with reason: {socket_error,timeout}
2020-05-03 22:51:01.425 [error] <0.589.0> CRASH REPORT Process <0.589.0> with 0 neighbours exited with reason: {socket_error,timeout} in gen_server:handle_common_reply/8 line 751
2020-05-03 22:51:01.425 [error] <0.588.0> gen_server <0.588.0> terminated with reason: {socket_error,timeout}
2020-05-03 22:51:01.426 [error] <0.586.0> CRASH REPORT Process <0.586.0> with 0 neighbours exited with reason: {socket_error,timeout} in gen_server:handle_common_reply/8 line 751
2020-05-03 22:51:01.426 [error] <0.585.0> CRASH REPORT Process <0.585.0> with 0 neighbours exited with reason: {socket_error,timeout} in gen_server:handle_common_reply/8 line 751
2020-05-03 22:51:01.426 [error] <0.566.0> gen_server <0.566.0> terminated with reason: socket_closed_unexpectedly
2020-05-03 22:51:01.427 [error] <0.562.0> Supervisor {<0.562.0>,amqp_connection_type_sup} had child main_reader started with amqp_main_reader:start_link(#Port<0.12>, <0.563.0>, <0.575.0>, {method,rabbit_framing_amqp_0_9_1}, <<"client 192.168.1.73:40325 -> 192.168.1.64:32771">>) at <0.586.0> exit with reason {socket_error,timeout} in context child_terminated
2020-05-03 22:51:01.427 [error] <0.587.0> CRASH REPORT Process <0.587.0> with 0 neighbours exited with reason: {socket_error,timeout} in gen_server:handle_common_reply/8 line 751
2020-05-03 22:51:01.427 [error] <0.563.0> gen_server <0.563.0> terminated with reason: {socket_error,timeout}
2020-05-03 22:51:01.428 [error] <0.562.0> Supervisor {<0.562.0>,amqp_connection_type_sup} had child main_reader started with amqp_main_reader:start_link(#Port<0.12>, <0.563.0>, <0.575.0>, {method,rabbit_framing_amqp_0_9_1}, <<"client 192.168.1.73:40325 -> 192.168.1.64:32771">>) at <0.586.0> exit with reason reached_max_restart_intensity in context shutdown
2020-05-03 22:51:01.429 [error] <0.557.0> gen_server <0.557.0> terminated with reason: {socket_error,timeout}
2020-05-03 22:51:01.430 [error] <0.559.0> Supervisor {<0.559.0>,amqp_connection_type_sup} had child main_reader started with amqp_main_reader:start_link(#Port<0.14>, <0.560.0>, <0.579.0>, {method,rabbit_framing_amqp_0_9_1}, <<"client 192.168.1.73:41503 -> 192.168.1.64:32771">>) at <0.589.0> exit with reason {socket_error,timeout} in context child_terminated
2020-05-03 22:51:01.430 [error] <0.588.0> CRASH REPORT Process <0.588.0> with 0 neighbours exited with reason: {socket_error,timeout} in gen_server:handle_common_reply/8 line 751
2020-05-03 22:51:01.430 [error] <0.559.0> Supervisor {<0.559.0>,amqp_connection_type_sup} had child main_reader started with amqp_main_reader:start_link(#Port<0.14>, <0.560.0>, <0.579.0>, {method,rabbit_framing_amqp_0_9_1}, <<"client 192.168.1.73:41503 -> 192.168.1.64:32771">>) at <0.589.0> exit with reason reached_max_restart_intensity in context shutdown
2020-05-03 22:51:01.431 [error] <0.565.0> Supervisor {<0.565.0>,amqp_connection_type_sup} had child main_reader started with amqp_main_reader:start_link(#Port<0.13>, <0.566.0>, <0.576.0>, {method,rabbit_framing_amqp_0_9_1}, <<"client 192.168.1.73:49675 -> 192.168.1.64:32771">>) at <0.587.0> exit with reason {socket_error,timeout} in context child_terminated
2020-05-03 22:51:01.432 [error] <0.565.0> Supervisor {<0.565.0>,amqp_connection_type_sup} had child main_reader started with amqp_main_reader:start_link(#Port<0.13>, <0.566.0>, <0.576.0>, {method,rabbit_framing_amqp_0_9_1}, <<"client 192.168.1.73:49675 -> 192.168.1.64:32771">>) at <0.587.0> exit with reason reached_max_restart_intensity in context shutdown
2020-05-03 22:51:01.432 [error] <0.556.0> Supervisor {<0.556.0>,amqp_connection_type_sup} had child main_reader started with amqp_main_reader:start_link(#Port<0.15>, <0.557.0>, <0.577.0>, {method,rabbit_framing_amqp_0_9_1}, <<"client 192.168.1.73:47097 -> 192.168.1.64:32771">>) at <0.588.0> exit with reason {socket_error,timeout} in context child_terminated
2020-05-03 22:51:01.433 [error] <0.556.0> Supervisor {<0.556.0>,amqp_connection_type_sup} had child main_reader started with amqp_main_reader:start_link(#Port<0.15>, <0.557.0>, <0.577.0>, {method,rabbit_framing_amqp_0_9_1}, <<"client 192.168.1.73:47097 -> 192.168.1.64:32771">>) at <0.588.0> exit with reason reached_max_restart_intensity in context shutdown
2020-05-03 22:51:01.434 [error] <0.569.0> gen_server <0.569.0> terminated with reason: {socket_error,timeout}
2020-05-03 22:51:01.435 [error] <0.568.0> Supervisor {<0.568.0>,amqp_connection_type_sup} had child main_reader started with amqp_main_reader:start_link(#Port<0.16>, <0.569.0>, <0.578.0>, {method,rabbit_framing_amqp_0_9_1}, <<"client 192.168.1.73:53547 -> 192.168.1.64:32771">>) at <0.585.0> exit with reason {socket_error,timeout} in context child_terminated
2020-05-03 22:51:01.435 [error] <0.568.0> Supervisor {<0.568.0>,amqp_connection_type_sup} had child main_reader started with amqp_main_reader:start_link(#Port<0.16>, <0.569.0>, <0.578.0>, {method,rabbit_framing_amqp_0_9_1}, <<"client 192.168.1.73:53547 -> 192.168.1.64:32771">>) at <0.585.0> exit with reason reached_max_restart_intensity in context shutdown
2020-05-03 22:51:01.436 [error] <0.566.0> CRASH REPORT Process <0.566.0> with 0 neighbours exited with reason: socket_closed_unexpectedly in gen_server:handle_common_reply/8 line 751
2020-05-03 22:51:01.436 [error] <0.560.0> CRASH REPORT Process <0.560.0> with 0 neighbours exited with reason: {socket_error,timeout} in gen_server:handle_common_reply/8 line 751
2020-05-03 22:51:01.437 [error] <0.564.0> Supervisor {<0.564.0>,amqp_connection_sup} had child connection started with amqp_gen_connection:start_link(<0.565.0>, {amqp_params_network,<<"guest">>,<<"9DHkNif3RAHUjblFV6yscTuHd7vNQ/1NbKAzCIqPHL0FmFVAf7FNRQn0Sah6nV...">>,...}) at <0.566.0> exit with reason socket_closed_unexpectedly in context child_terminated
2020-05-03 22:51:01.437 [error] <0.564.0> Supervisor {<0.564.0>,amqp_connection_sup} had child connection started with amqp_gen_connection:start_link(<0.565.0>, {amqp_params_network,<<"guest">>,<<"9DHkNif3RAHUjblFV6yscTuHd7vNQ/1NbKAzCIqPHL0FmFVAf7FNRQn0Sah6nV...">>,...}) at <0.566.0> exit with reason reached_max_restart_intensity in context shutdown
2020-05-03 22:51:01.438 [error] <0.558.0> Supervisor {<0.558.0>,amqp_connection_sup} had child connection started with amqp_gen_connection:start_link(<0.559.0>, {amqp_params_network,<<"guest">>,<<"E+KVjD/a67Gvw6LRyd7oLsN8kGxUE/z6hDshyxhf786+KrjHfW/i6KL0HS7LcX...">>,...}) at <0.560.0> exit with reason {socket_error,timeout} in context child_terminated
2020-05-03 22:51:01.438 [error] <0.557.0> CRASH REPORT Process <0.557.0> with 0 neighbours exited with reason: {socket_error,timeout} in gen_server:handle_common_reply/8 line 751
2020-05-03 22:51:01.439 [error] <0.558.0> Supervisor {<0.558.0>,amqp_connection_sup} had child connection started with amqp_gen_connection:start_link(<0.559.0>, {amqp_params_network,<<"guest">>,<<"E+KVjD/a67Gvw6LRyd7oLsN8kGxUE/z6hDshyxhf786+KrjHfW/i6KL0HS7LcX...">>,...}) at <0.560.0> exit with reason reached_max_restart_intensity in context shutdown
2020-05-03 22:51:01.439 [error] <0.555.0> Supervisor {<0.555.0>,amqp_connection_sup} had child connection started with amqp_gen_connection:start_link(<0.556.0>, {amqp_params_network,<<"guest">>,<<"8Gu9gjdGcHuHcp4aAQ+3lqxNXJNutGd5AUunbfH9Wr8/5X/99EFjpBSXTF3V+Q...">>,...}) at <0.557.0> exit with reason {socket_error,timeout} in context child_terminated
2020-05-03 22:51:01.440 [error] <0.555.0> Supervisor {<0.555.0>,amqp_connection_sup} had child connection started with amqp_gen_connection:start_link(<0.556.0>, {amqp_params_network,<<"guest">>,<<"8Gu9gjdGcHuHcp4aAQ+3lqxNXJNutGd5AUunbfH9Wr8/5X/99EFjpBSXTF3V+Q...">>,...}) at <0.557.0> exit with reason reached_max_restart_intensity in context shutdown
2020-05-03 22:51:01.440 [error] <0.563.0> CRASH REPORT Process <0.563.0> with 0 neighbours exited with reason: {socket_error,timeout} in gen_server:handle_common_reply/8 line 751
2020-05-03 22:51:01.440 [error] <0.569.0> CRASH REPORT Process <0.569.0> with 0 neighbours exited with reason: {socket_error,timeout} in gen_server:handle_common_reply/8 line 751
2020-05-03 22:51:01.441 [error] <0.561.0> Supervisor {<0.561.0>,amqp_connection_sup} had child connection started with amqp_gen_connection:start_link(<0.562.0>, {amqp_params_network,<<"guest">>,<<"LBpfNCbyP9bAQKYnXlWDHVXHM1cmc0TX6GzQQfD6FT3cNCDd8MS+BBUH9HbZMi...">>,...}) at <0.563.0> exit with reason {socket_error,timeout} in context child_terminated
2020-05-03 22:51:01.441 [error] <0.561.0> Supervisor {<0.561.0>,amqp_connection_sup} had child connection started with amqp_gen_connection:start_link(<0.562.0>, {amqp_params_network,<<"guest">>,<<"LBpfNCbyP9bAQKYnXlWDHVXHM1cmc0TX6GzQQfD6FT3cNCDd8MS+BBUH9HbZMi...">>,...}) at <0.563.0> exit with reason reached_max_restart_intensity in context shutdown
2020-05-03 22:51:01.442 [error] <0.567.0> Supervisor {<0.567.0>,amqp_connection_sup} had child connection started with amqp_gen_connection:start_link(<0.568.0>, {amqp_params_network,<<"guest">>,<<"Tvvo2DcezHo+NdTUtyFRdmFAipdYBLk/PNx/KNseMPn0X6FalysKDSJiDjJkih...">>,...}) at <0.569.0> exit with reason {socket_error,timeout} in context child_terminated
2020-05-03 22:51:01.442 [error] <0.567.0> Supervisor {<0.567.0>,amqp_connection_sup} had child connection started with amqp_gen_connection:start_link(<0.568.0>, {amqp_params_network,<<"guest">>,<<"Tvvo2DcezHo+NdTUtyFRdmFAipdYBLk/PNx/KNseMPn0X6FalysKDSJiDjJkih...">>,...}) at <0.569.0> exit with reason reached_max_restart_intensity in context shutdown
2020-05-05 22:07:20.466 [error] <0.488.0> gen_server <0.488.0> terminated with reason: socket_closed_unexpectedly
2020-05-05 22:07:20.482 [error] <0.488.0> CRASH REPORT Process <0.488.0> with 0 neighbours exited with reason: socket_closed_unexpectedly in gen_server:handle_common_reply/8 line 751
2020-05-05 22:07:20.483 [error] <0.486.0> Supervisor {<0.486.0>,amqp_connection_sup} had child connection started with amqp_gen_connection:start_link(<0.487.0>, {amqp_params_network,<<"guest">>,<<"pKnPEuoDauD8iwxVqtZHpdLvFF1VNH+vjHuXPZTlLseplkxOfE/1HZIb8EoObz...">>,...}) at <0.488.0> exit with reason socket_closed_unexpectedly in context child_terminated
2020-05-05 22:07:20.484 [error] <0.486.0> Supervisor {<0.486.0>,amqp_connection_sup} had child connection started with amqp_gen_connection:start_link(<0.487.0>, {amqp_params_network,<<"guest">>,<<"pKnPEuoDauD8iwxVqtZHpdLvFF1VNH+vjHuXPZTlLseplkxOfE/1HZIb8EoObz...">>,...}) at <0.488.0> exit with reason reached_max_restart_intensity in context shutdown
2020-05-05 22:07:20.490 [error] <0.491.0> gen_server <0.491.0> terminated with reason: socket_closed_unexpectedly
2020-05-05 22:07:20.490 [error] <0.494.0> gen_server <0.494.0> terminated with reason: socket_closed_unexpectedly
2020-05-05 22:07:20.490 [error] <0.494.0> CRASH REPORT Process <0.494.0> with 0 neighbours exited with reason: socket_closed_unexpectedly in gen_server:handle_common_reply/8 line 751
2020-05-05 22:07:20.491 [error] <0.492.0> Supervisor {<0.492.0>,amqp_connection_sup} had child connection started with amqp_gen_connection:start_link(<0.493.0>, {amqp_params_network,<<"guest">>,<<"0p0CKsVml1ZPfGuov9zn5KkEUbHYmuHTsqH+QpniRe51fGI+i/7iPxCpm/Keho...">>,...}) at <0.494.0> exit with reason socket_closed_unexpectedly in context child_terminated
2020-05-05 22:07:20.491 [error] <0.482.0> gen_server <0.482.0> terminated with reason: socket_closed_unexpectedly
2020-05-05 22:07:20.492 [error] <0.492.0> Supervisor {<0.492.0>,amqp_connection_sup} had child connection started with amqp_gen_connection:start_link(<0.493.0>, {amqp_params_network,<<"guest">>,<<"0p0CKsVml1ZPfGuov9zn5KkEUbHYmuHTsqH+QpniRe51fGI+i/7iPxCpm/Keho...">>,...}) at <0.494.0> exit with reason reached_max_restart_intensity in context shutdown
2020-05-05 22:07:20.492 [error] <0.485.0> gen_server <0.485.0> terminated with reason: socket_closed_unexpectedly
2020-05-05 22:07:20.492 [error] <0.491.0> CRASH REPORT Process <0.491.0> with 0 neighbours exited with reason: socket_closed_unexpectedly in gen_server:handle_common_reply/8 line 751
2020-05-05 22:07:20.493 [error] <0.489.0> Supervisor {<0.489.0>,amqp_connection_sup} had child connection started with amqp_gen_connection:start_link(<0.490.0>, {amqp_params_network,<<"guest">>,<<"8V8Bq9pcsFwECJc70gs32GFDtNMhwBINFZiX/R8I1BsSY+GJuwaQkxp90XGx2B...">>,...}) at <0.491.0> exit with reason socket_closed_unexpectedly in context child_terminated
2020-05-05 22:07:20.493 [error] <0.489.0> Supervisor {<0.489.0>,amqp_connection_sup} had child connection started with amqp_gen_connection:start_link(<0.490.0>, {amqp_params_network,<<"guest">>,<<"8V8Bq9pcsFwECJc70gs32GFDtNMhwBINFZiX/R8I1BsSY+GJuwaQkxp90XGx2B...">>,...}) at <0.491.0> exit with reason reached_max_restart_intensity in context shutdown
2020-05-05 22:07:20.494 [error] <0.482.0> CRASH REPORT Process <0.482.0> with 0 neighbours exited with reason: socket_closed_unexpectedly in gen_server:handle_common_reply/8 line 751
2020-05-05 22:07:20.494 [error] <0.477.0> Supervisor {<0.477.0>,amqp_connection_sup} had child connection started with amqp_gen_connection:start_link(<0.480.0>, {amqp_params_network,<<"guest">>,<<"kZ3jtHcJjW+S/gJKskCch0o0j//S4Srr5Z/98k2KXppNkrd8GwLjO7mQojHWNE...">>,...}) at <0.482.0> exit with reason socket_closed_unexpectedly in context child_terminated
2020-05-05 22:07:20.495 [error] <0.477.0> Supervisor {<0.477.0>,amqp_connection_sup} had child connection started with amqp_gen_connection:start_link(<0.480.0>, {amqp_params_network,<<"guest">>,<<"kZ3jtHcJjW+S/gJKskCch0o0j//S4Srr5Z/98k2KXppNkrd8GwLjO7mQojHWNE...">>,...}) at <0.482.0> exit with reason reached_max_restart_intensity in context shutdown
2020-05-05 22:07:20.495 [error] <0.485.0> CRASH REPORT Process <0.485.0> with 0 neighbours exited with reason: socket_closed_unexpectedly in gen_server:handle_common_reply/8 line 751
2020-05-05 22:07:20.496 [error] <0.483.0> Supervisor {<0.483.0>,amqp_connection_sup} had child connection started with amqp_gen_connection:start_link(<0.484.0>, {amqp_params_network,<<"guest">>,<<"hsrzaRrgwQpGY7wz78K4XpKktgSAodLHl8hN/2il2jxd/p6pMP1HlY06Wlz7BJ...">>,...}) at <0.485.0> exit with reason socket_closed_unexpectedly in context child_terminated
2020-05-05 22:07:20.496 [error] <0.483.0> Supervisor {<0.483.0>,amqp_connection_sup} had child connection started with amqp_gen_connection:start_link(<0.484.0>, {amqp_params_network,<<"guest">>,<<"hsrzaRrgwQpGY7wz78K4XpKktgSAodLHl8hN/2il2jxd/p6pMP1HlY06Wlz7BJ...">>,...}) at <0.485.0> exit with reason reached_max_restart_intensity in context shutdown
2020-05-12 22:50:46.261 [error] <0.8842.0> gen_server 'Elixir.FidelityRuleEngine.Consumer.Broadway.Producer_0' terminated with reason: #{'__exception__' => true,'__struct__' => 'Elixir.RuntimeError',message => <<"unexpected error when connecting to RabbitMQ broker">>} in 'Elixir.BroadwayRabbitMQ.Producer':handle_connection_failure/2 line 425
2020-05-12 22:50:46.261 [error] <0.8845.0> gen_server 'Elixir.FidelityRuleEngine.Consumer.Broadway.Producer_3' terminated with reason: #{'__exception__' => true,'__struct__' => 'Elixir.RuntimeError',message => <<"unexpected error when connecting to RabbitMQ broker">>} in 'Elixir.BroadwayRabbitMQ.Producer':handle_connection_failure/2 line 425
2020-05-12 22:50:46.262 [error] <0.8846.0> gen_server 'Elixir.FidelityRuleEngine.Consumer.Broadway.Producer_4' terminated with reason: #{'__exception__' => true,'__struct__' => 'Elixir.RuntimeError',message => <<"unexpected error when connecting to RabbitMQ broker">>} in 'Elixir.BroadwayRabbitMQ.Producer':handle_connection_failure/2 line 425
2020-05-12 22:50:46.262 [error] <0.8843.0> gen_server 'Elixir.FidelityRuleEngine.Consumer.Broadway.Producer_1' terminated with reason: #{'__exception__' => true,'__struct__' => 'Elixir.RuntimeError',message => <<"unexpected error when connecting to RabbitMQ broker">>} in 'Elixir.BroadwayRabbitMQ.Producer':handle_connection_failure/2 line 425
2020-05-12 22:50:46.262 [error] <0.8844.0> gen_server 'Elixir.FidelityRuleEngine.Consumer.Broadway.Producer_2' terminated with reason: #{'__exception__' => true,'__struct__' => 'Elixir.RuntimeError',message => <<"unexpected error when connecting to RabbitMQ broker">>} in 'Elixir.BroadwayRabbitMQ.Producer':handle_connection_failure/2 line 425
2020-05-12 22:50:46.262 [error] <0.8845.0> CRASH REPORT Process 'Elixir.FidelityRuleEngine.Consumer.Broadway.Producer_3' with 0 neighbours crashed with reason: #{'__exception__' => true,'__struct__' => 'Elixir.RuntimeError',message => <<"unexpected error when connecting to RabbitMQ broker">>} in 'Elixir.BroadwayRabbitMQ.Producer':handle_connection_failure/2 line 425
2020-05-12 22:50:46.263 [error] <0.8841.0> Supervisor 'Elixir.FidelityRuleEngine.Consumer.Broadway.ProducerSupervisor' had child 'Elixir.FidelityRuleEngine.Consumer.Broadway.Producer_3' started with 'Elixir.Broadway.Producer':start_link([{broadway,[{hibernate_after,15000},{batchers,[]},{context,context_not_set},{resubscribe_interval,...},...]},...], 3, [{name,'Elixir.FidelityRuleEngine.Consumer.Broadway.Producer_3'},{hibernate_after,15000}]) at <0.8845.0> exit with reason #{'__exception__' => true,'__struct__' => 'Elixir.RuntimeError',message => <<"unexpected error when connecting to RabbitMQ broker">>} in 'Elixir.BroadwayRabbitMQ.Producer':handle_connection_failure/2 line 425 in context child_terminated
2020-05-12 22:50:46.263 [error] <0.8844.0> CRASH REPORT Process 'Elixir.FidelityRuleEngine.Consumer.Broadway.Producer_2' with 0 neighbours crashed with reason: #{'__exception__' => true,'__struct__' => 'Elixir.RuntimeError',message => <<"unexpected error when connecting to RabbitMQ broker">>} in 'Elixir.BroadwayRabbitMQ.Producer':handle_connection_failure/2 line 425
2020-05-12 22:50:46.263 [error] <0.8843.0> CRASH REPORT Process 'Elixir.FidelityRuleEngine.Consumer.Broadway.Producer_1' with 0 neighbours crashed with reason: #{'__exception__' => true,'__struct__' => 'Elixir.RuntimeError',message => <<"unexpected error when connecting to RabbitMQ broker">>} in 'Elixir.BroadwayRabbitMQ.Producer':handle_connection_failure/2 line 425
2020-05-12 22:50:46.263 [error] <0.8846.0> CRASH REPORT Process 'Elixir.FidelityRuleEngine.Consumer.Broadway.Producer_4' with 0 neighbours crashed with reason: #{'__exception__' => true,'__struct__' => 'Elixir.RuntimeError',message => <<"unexpected error when connecting to RabbitMQ broker">>} in 'Elixir.BroadwayRabbitMQ.Producer':handle_connection_failure/2 line 425
2020-05-12 22:50:46.264 [error] <0.8841.0> Supervisor 'Elixir.FidelityRuleEngine.Consumer.Broadway.ProducerSupervisor' had child 'Elixir.FidelityRuleEngine.Consumer.Broadway.Producer_2' started with 'Elixir.Broadway.Producer':start_link([{broadway,[{hibernate_after,15000},{batchers,[]},{context,context_not_set},{resubscribe_interval,...},...]},...], 2, [{name,'Elixir.FidelityRuleEngine.Consumer.Broadway.Producer_2'},{hibernate_after,15000}]) at <0.8844.0> exit with reason #{'__exception__' => true,'__struct__' => 'Elixir.RuntimeError',message => <<"unexpected error when connecting to RabbitMQ broker">>} in 'Elixir.BroadwayRabbitMQ.Producer':handle_connection_failure/2 line 425 in context child_terminated
2020-05-12 22:50:46.265 [error] <0.8841.0> Supervisor 'Elixir.FidelityRuleEngine.Consumer.Broadway.ProducerSupervisor' had child 'Elixir.FidelityRuleEngine.Consumer.Broadway.Producer_1' started with 'Elixir.Broadway.Producer':start_link([{broadway,[{hibernate_after,15000},{batchers,[]},{context,context_not_set},{resubscribe_interval,...},...]},...], 1, [{name,'Elixir.FidelityRuleEngine.Consumer.Broadway.Producer_1'},{hibernate_after,15000}]) at <0.8843.0> exit with reason #{'__exception__' => true,'__struct__' => 'Elixir.RuntimeError',message => <<"unexpected error when connecting to RabbitMQ broker">>} in 'Elixir.BroadwayRabbitMQ.Producer':handle_connection_failure/2 line 425 in context child_terminated
2020-05-12 22:50:46.265 [error] <0.8841.0> Supervisor 'Elixir.FidelityRuleEngine.Consumer.Broadway.ProducerSupervisor' had child 'Elixir.FidelityRuleEngine.Consumer.Broadway.Producer_4' started with 'Elixir.Broadway.Producer':start_link([{broadway,[{hibernate_after,15000},{batchers,[]},{context,context_not_set},{resubscribe_interval,...},...]},...], 4, [{name,'Elixir.FidelityRuleEngine.Consumer.Broadway.Producer_4'},{hibernate_after,15000}]) at <0.8846.0> exit with reason #{'__exception__' => true,'__struct__' => 'Elixir.RuntimeError',message => <<"unexpected error when connecting to RabbitMQ broker">>} in 'Elixir.BroadwayRabbitMQ.Producer':handle_connection_failure/2 line 425 in context child_terminated
2020-05-12 22:50:46.266 [error] <0.8842.0> CRASH REPORT Process 'Elixir.FidelityRuleEngine.Consumer.Broadway.Producer_0' with 0 neighbours crashed with reason: #{'__exception__' => true,'__struct__' => 'Elixir.RuntimeError',message => <<"unexpected error when connecting to RabbitMQ broker">>} in 'Elixir.BroadwayRabbitMQ.Producer':handle_connection_failure/2 line 425
2020-05-12 22:50:46.266 [error] <0.8841.0> Supervisor 'Elixir.FidelityRuleEngine.Consumer.Broadway.ProducerSupervisor' had child 'Elixir.FidelityRuleEngine.Consumer.Broadway.Producer_0' started with 'Elixir.Broadway.Producer':start_link([{broadway,[{hibernate_after,15000},{batchers,[]},{context,context_not_set},{resubscribe_interval,...},...]},...], 0, [{name,'Elixir.FidelityRuleEngine.Consumer.Broadway.Producer_0'},{hibernate_after,15000}]) at <0.8842.0> exit with reason #{'__exception__' => true,'__struct__' => 'Elixir.RuntimeError',message => <<"unexpected error when connecting to RabbitMQ broker">>} in 'Elixir.BroadwayRabbitMQ.Producer':handle_connection_failure/2 line 425 in context child_terminated
2020-05-12 22:50:49.331 [error] <0.9031.0> gen_server 'Elixir.FidelityRuleEngine.Consumer.Broadway.Producer_2' terminated with reason: #{'__exception__' => true,'__struct__' => 'Elixir.RuntimeError',message => <<"unexpected error when connecting to RabbitMQ broker">>} in 'Elixir.BroadwayRabbitMQ.Producer':handle_connection_failure/2 line 425
2020-05-12 22:50:49.333 [error] <0.9030.0> gen_server 'Elixir.FidelityRuleEngine.Consumer.Broadway.Producer_3' terminated with reason: #{'__exception__' => true,'__struct__' => 'Elixir.RuntimeError',message => <<"unexpected error when connecting to RabbitMQ broker">>} in 'Elixir.BroadwayRabbitMQ.Producer':handle_connection_failure/2 line 425
2020-05-12 22:50:49.333 [error] <0.9032.0> gen_server 'Elixir.FidelityRuleEngine.Consumer.Broadway.Producer_1' terminated with reason: #{'__exception__' => true,'__struct__' => 'Elixir.RuntimeError',message => <<"unexpected error when connecting to RabbitMQ broker">>} in 'Elixir.BroadwayRabbitMQ.Producer':handle_connection_failure/2 line 425
2020-05-12 22:50:49.334 [error] <0.9033.0> gen_server 'Elixir.FidelityRuleEngine.Consumer.Broadway.Producer_4' terminated with reason: #{'__exception__' => true,'__struct__' => 'Elixir.RuntimeError',message => <<"unexpected error when connecting to RabbitMQ broker">>} in 'Elixir.BroadwayRabbitMQ.Producer':handle_connection_failure/2 line 425
2020-05-12 22:50:49.334 [error] <0.9034.0> gen_server 'Elixir.FidelityRuleEngine.Consumer.Broadway.Producer_0' terminated with reason: #{'__exception__' => true,'__struct__' => 'Elixir.RuntimeError',message => <<"unexpected error when connecting to RabbitMQ broker">>} in 'Elixir.BroadwayRabbitMQ.Producer':handle_connection_failure/2 line 425
2020-05-12 22:50:49.334 [error] <0.9033.0> CRASH REPORT Process 'Elixir.FidelityRuleEngine.Consumer.Broadway.Producer_4' with 0 neighbours crashed with reason: #{'__exception__' => true,'__struct__' => 'Elixir.RuntimeError',message => <<"unexpected error when connecting to RabbitMQ broker">>} in 'Elixir.BroadwayRabbitMQ.Producer':handle_connection_failure/2 line 425
2020-05-12 22:50:49.336 [error] <0.8841.0> Supervisor 'Elixir.FidelityRuleEngine.Consumer.Broadway.ProducerSupervisor' had child 'Elixir.FidelityRuleEngine.Consumer.Broadway.Producer_4' started with 'Elixir.Broadway.Producer':start_link([{broadway,[{hibernate_after,15000},{batchers,[]},{context,context_not_set},{resubscribe_interval,...},...]},...], 4, [{name,'Elixir.FidelityRuleEngine.Consumer.Broadway.Producer_4'},{hibernate_after,15000}]) at <0.9033.0> exit with reason #{'__exception__' => true,'__struct__' => 'Elixir.RuntimeError',message => <<"unexpected error when connecting to RabbitMQ broker">>} in 'Elixir.BroadwayRabbitMQ.Producer':handle_connection_failure/2 line 425 in context child_terminated
2020-05-12 22:50:49.336 [error] <0.9031.0> CRASH REPORT Process 'Elixir.FidelityRuleEngine.Consumer.Broadway.Producer_2' with 0 neighbours crashed with reason: #{'__exception__' => true,'__struct__' => 'Elixir.RuntimeError',message => <<"unexpected error when connecting to RabbitMQ broker">>} in 'Elixir.BroadwayRabbitMQ.Producer':handle_connection_failure/2 line 425
2020-05-12 22:50:49.337 [error] <0.8841.0> Supervisor 'Elixir.FidelityRuleEngine.Consumer.Broadway.ProducerSupervisor' had child 'Elixir.FidelityRuleEngine.Consumer.Broadway.Producer_2' started with 'Elixir.Broadway.Producer':start_link([{broadway,[{hibernate_after,15000},{batchers,[]},{context,context_not_set},{resubscribe_interval,...},...]},...], 2, [{name,'Elixir.FidelityRuleEngine.Consumer.Broadway.Producer_2'},{hibernate_after,15000}]) at <0.9031.0> exit with reason #{'__exception__' => true,'__struct__' => 'Elixir.RuntimeError',message => <<"unexpected error when connecting to RabbitMQ broker">>} in 'Elixir.BroadwayRabbitMQ.Producer':handle_connection_failure/2 line 425 in context child_terminated
2020-05-12 22:50:49.338 [error] <0.9030.0> CRASH REPORT Process 'Elixir.FidelityRuleEngine.Consumer.Broadway.Producer_3' with 0 neighbours crashed with reason: #{'__exception__' => true,'__struct__' => 'Elixir.RuntimeError',message => <<"unexpected error when connecting to RabbitMQ broker">>} in 'Elixir.BroadwayRabbitMQ.Producer':handle_connection_failure/2 line 425
2020-05-12 22:50:49.339 [error] <0.8841.0> Supervisor 'Elixir.FidelityRuleEngine.Consumer.Broadway.ProducerSupervisor' had child 'Elixir.FidelityRuleEngine.Consumer.Broadway.Producer_3' started with 'Elixir.Broadway.Producer':start_link([{broadway,[{hibernate_after,15000},{batchers,[]},{context,context_not_set},{resubscribe_interval,...},...]},...], 3, [{name,'Elixir.FidelityRuleEngine.Consumer.Broadway.Producer_3'},{hibernate_after,15000}]) at <0.9030.0> exit with reason #{'__exception__' => true,'__struct__' => 'Elixir.RuntimeError',message => <<"unexpected error when connecting to RabbitMQ broker">>} in 'Elixir.BroadwayRabbitMQ.Producer':handle_connection_failure/2 line 425 in context child_terminated
2020-05-12 22:50:49.340 [error] <0.9034.0> CRASH REPORT Process 'Elixir.FidelityRuleEngine.Consumer.Broadway.Producer_0' with 0 neighbours crashed with reason: #{'__exception__' => true,'__struct__' => 'Elixir.RuntimeError',message => <<"unexpected error when connecting to RabbitMQ broker">>} in 'Elixir.BroadwayRabbitMQ.Producer':handle_connection_failure/2 line 425
2020-05-12 22:50:49.340 [error] <0.9032.0> CRASH REPORT Process 'Elixir.FidelityRuleEngine.Consumer.Broadway.Producer_1' with 0 neighbours crashed with reason: #{'__exception__' => true,'__struct__' => 'Elixir.RuntimeError',message => <<"unexpected error when connecting to RabbitMQ broker">>} in 'Elixir.BroadwayRabbitMQ.Producer':handle_connection_failure/2 line 425
2020-05-12 22:50:49.341 [error] <0.8841.0> Supervisor 'Elixir.FidelityRuleEngine.Consumer.Broadway.ProducerSupervisor' had child 'Elixir.FidelityRuleEngine.Consumer.Broadway.Producer_0' started with 'Elixir.Broadway.Producer':start_link([{broadway,[{hibernate_after,15000},{batchers,[]},{context,context_not_set},{resubscribe_interval,...},...]},...], 0, [{name,'Elixir.FidelityRuleEngine.Consumer.Broadway.Producer_0'},{hibernate_after,15000}]) at <0.9034.0> exit with reason #{'__exception__' => true,'__struct__' => 'Elixir.RuntimeError',message => <<"unexpected error when connecting to RabbitMQ broker">>} in 'Elixir.BroadwayRabbitMQ.Producer':handle_connection_failure/2 line 425 in context child_terminated
2020-05-12 22:50:49.343 [error] <0.8841.0> Supervisor 'Elixir.FidelityRuleEngine.Consumer.Broadway.ProducerSupervisor' had child 'Elixir.FidelityRuleEngine.Consumer.Broadway.Producer_1' started with 'Elixir.Broadway.Producer':start_link([{broadway,[{hibernate_after,15000},{batchers,[]},{context,context_not_set},{resubscribe_interval,...},...]},...], 1, [{name,'Elixir.FidelityRuleEngine.Consumer.Broadway.Producer_1'},{hibernate_after,15000}]) at <0.9032.0> exit with reason #{'__exception__' => true,'__struct__' => 'Elixir.RuntimeError',message => <<"unexpected error when connecting to RabbitMQ broker">>} in 'Elixir.BroadwayRabbitMQ.Producer':handle_connection_failure/2 line 425 in context child_terminated
2020-05-12 22:50:52.397 [error] <0.9050.0> gen_server 'Elixir.FidelityRuleEngine.Consumer.Broadway.Producer_4' terminated with reason: #{'__exception__' => true,'__struct__' => 'Elixir.RuntimeError',message => <<"unexpected error when connecting to RabbitMQ broker">>} in 'Elixir.BroadwayRabbitMQ.Producer':handle_connection_failure/2 line 425
2020-05-12 22:50:52.398 [error] <0.9054.0> gen_server 'Elixir.FidelityRuleEngine.Consumer.Broadway.Producer_1' terminated with reason: #{'__exception__' => true,'__struct__' => 'Elixir.RuntimeError',message => <<"unexpected error when connecting to RabbitMQ broker">>} in 'Elixir.BroadwayRabbitMQ.Producer':handle_connection_failure/2 line 425
2020-05-12 22:50:52.399 [error] <0.9052.0> gen_server 'Elixir.FidelityRuleEngine.Consumer.Broadway.Producer_3' terminated with reason: #{'__exception__' => true,'__struct__' => 'Elixir.RuntimeError',message => <<"unexpected error when connecting to RabbitMQ broker">>} in 'Elixir.BroadwayRabbitMQ.Producer':handle_connection_failure/2 line 425
2020-05-12 22:50:52.399 [error] <0.9053.0> gen_server 'Elixir.FidelityRuleEngine.Consumer.Broadway.Producer_0' terminated with reason: #{'__exception__' => true,'__struct__' => 'Elixir.RuntimeError',message => <<"unexpected error when connecting to RabbitMQ broker">>} in 'Elixir.BroadwayRabbitMQ.Producer':handle_connection_failure/2 line 425
2020-05-12 22:50:52.400 [error] <0.9051.0> gen_server 'Elixir.FidelityRuleEngine.Consumer.Broadway.Producer_2' terminated with reason: #{'__exception__' => true,'__struct__' => 'Elixir.RuntimeError',message => <<"unexpected error when connecting to RabbitMQ broker">>} in 'Elixir.BroadwayRabbitMQ.Producer':handle_connection_failure/2 line 425
2020-05-12 22:50:52.401 [error] <0.9050.0> CRASH REPORT Process 'Elixir.FidelityRuleEngine.Consumer.Broadway.Producer_4' with 0 neighbours crashed with reason: #{'__exception__' => true,'__struct__' => 'Elixir.RuntimeError',message => <<"unexpected error when connecting to RabbitMQ broker">>} in 'Elixir.BroadwayRabbitMQ.Producer':handle_connection_failure/2 line 425
2020-05-12 22:50:52.402 [error] <0.8841.0> Supervisor 'Elixir.FidelityRuleEngine.Consumer.Broadway.ProducerSupervisor' had child 'Elixir.FidelityRuleEngine.Consumer.Broadway.Producer_4' started with 'Elixir.Broadway.Producer':start_link([{broadway,[{hibernate_after,15000},{batchers,[]},{context,context_not_set},{resubscribe_interval,...},...]},...], 4, [{name,'Elixir.FidelityRuleEngine.Consumer.Broadway.Producer_4'},{hibernate_after,15000}]) at <0.9050.0> exit with reason #{'__exception__' => true,'__struct__' => 'Elixir.RuntimeError',message => <<"unexpected error when connecting to RabbitMQ broker">>} in 'Elixir.BroadwayRabbitMQ.Producer':handle_connection_failure/2 line 425 in context child_terminated
2020-05-12 22:50:52.403 [error] <0.9051.0> CRASH REPORT Process 'Elixir.FidelityRuleEngine.Consumer.Broadway.Producer_2' with 0 neighbours crashed with reason: #{'__exception__' => true,'__struct__' => 'Elixir.RuntimeError',message => <<"unexpected error when connecting to RabbitMQ broker">>} in 'Elixir.BroadwayRabbitMQ.Producer':handle_connection_failure/2 line 425
2020-05-12 22:50:52.403 [error] <0.9052.0> CRASH REPORT Process 'Elixir.FidelityRuleEngine.Consumer.Broadway.Producer_3' with 0 neighbours crashed with reason: #{'__exception__' => true,'__struct__' => 'Elixir.RuntimeError',message => <<"unexpected error when connecting to RabbitMQ broker">>} in 'Elixir.BroadwayRabbitMQ.Producer':handle_connection_failure/2 line 425
2020-05-12 22:50:52.404 [error] <0.9054.0> CRASH REPORT Process 'Elixir.FidelityRuleEngine.Consumer.Broadway.Producer_1' with 0 neighbours crashed with reason: #{'__exception__' => true,'__struct__' => 'Elixir.RuntimeError',message => <<"unexpected error when connecting to RabbitMQ broker">>} in 'Elixir.BroadwayRabbitMQ.Producer':handle_connection_failure/2 line 425
2020-05-12 22:50:52.405 [error] <0.8841.0> Supervisor 'Elixir.FidelityRuleEngine.Consumer.Broadway.ProducerSupervisor' had child 'Elixir.FidelityRuleEngine.Consumer.Broadway.Producer_2' started with 'Elixir.Broadway.Producer':start_link([{broadway,[{hibernate_after,15000},{batchers,[]},{context,context_not_set},{resubscribe_interval,...},...]},...], 2, [{name,'Elixir.FidelityRuleEngine.Consumer.Broadway.Producer_2'},{hibernate_after,15000}]) at <0.9051.0> exit with reason #{'__exception__' => true,'__struct__' => 'Elixir.RuntimeError',message => <<"unexpected error when connecting to RabbitMQ broker">>} in 'Elixir.BroadwayRabbitMQ.Producer':handle_connection_failure/2 line 425 in context child_terminated
2020-05-12 22:50:52.405 [error] <0.9053.0> CRASH REPORT Process 'Elixir.FidelityRuleEngine.Consumer.Broadway.Producer_0' with 0 neighbours crashed with reason: #{'__exception__' => true,'__struct__' => 'Elixir.RuntimeError',message => <<"unexpected error when connecting to RabbitMQ broker">>} in 'Elixir.BroadwayRabbitMQ.Producer':handle_connection_failure/2 line 425
2020-05-12 22:50:52.407 [error] <0.8841.0> Supervisor 'Elixir.FidelityRuleEngine.Consumer.Broadway.ProducerSupervisor' had child 'Elixir.FidelityRuleEngine.Consumer.Broadway.Producer_3' started with 'Elixir.Broadway.Producer':start_link([{broadway,[{hibernate_after,15000},{batchers,[]},{context,context_not_set},{resubscribe_interval,...},...]},...], 3, [{name,'Elixir.FidelityRuleEngine.Consumer.Broadway.Producer_3'},{hibernate_after,15000}]) at <0.9052.0> exit with reason #{'__exception__' => true,'__struct__' => 'Elixir.RuntimeError',message => <<"unexpected error when connecting to RabbitMQ broker">>} in 'Elixir.BroadwayRabbitMQ.Producer':handle_connection_failure/2 line 425 in context child_terminated
2020-05-12 22:50:52.408 [error] <0.8841.0> Supervisor 'Elixir.FidelityRuleEngine.Consumer.Broadway.ProducerSupervisor' had child 'Elixir.FidelityRuleEngine.Consumer.Broadway.Producer_1' started with 'Elixir.Broadway.Producer':start_link([{broadway,[{hibernate_after,15000},{batchers,[]},{context,context_not_set},{resubscribe_interval,...},...]},...], 1, [{name,'Elixir.FidelityRuleEngine.Consumer.Broadway.Producer_1'},{hibernate_after,15000}]) at <0.9054.0> exit with reason #{'__exception__' => true,'__struct__' => 'Elixir.RuntimeError',message => <<"unexpected error when connecting to RabbitMQ broker">>} in 'Elixir.BroadwayRabbitMQ.Producer':handle_connection_failure/2 line 425 in context child_terminated
2020-05-12 22:50:52.409 [error] <0.8841.0> Supervisor 'Elixir.FidelityRuleEngine.Consumer.Broadway.ProducerSupervisor' had child 'Elixir.FidelityRuleEngine.Consumer.Broadway.Producer_0' started with 'Elixir.Broadway.Producer':start_link([{broadway,[{hibernate_after,15000},{batchers,[]},{context,context_not_set},{resubscribe_interval,...},...]},...], 0, [{name,'Elixir.FidelityRuleEngine.Consumer.Broadway.Producer_0'},{hibernate_after,15000}]) at <0.9053.0> exit with reason #{'__exception__' => true,'__struct__' => 'Elixir.RuntimeError',message => <<"unexpected error when connecting to RabbitMQ broker">>} in 'Elixir.BroadwayRabbitMQ.Producer':handle_connection_failure/2 line 425 in context child_terminated
2020-05-12 22:50:55.472 [error] <0.9073.0> gen_server 'Elixir.FidelityRuleEngine.Consumer.Broadway.Producer_1' terminated with reason: #{'__exception__' => true,'__struct__' => 'Elixir.RuntimeError',message => <<"unexpected error when connecting to RabbitMQ broker">>} in 'Elixir.BroadwayRabbitMQ.Producer':handle_connection_failure/2 line 425
2020-05-12 22:50:55.473 [error] <0.9070.0> gen_server 'Elixir.FidelityRuleEngine.Consumer.Broadway.Producer_4' terminated with reason: #{'__exception__' => true,'__struct__' => 'Elixir.RuntimeError',message => <<"unexpected error when connecting to RabbitMQ broker">>} in 'Elixir.BroadwayRabbitMQ.Producer':handle_connection_failure/2 line 425
2020-05-12 22:50:55.474 [error] <0.9071.0> gen_server 'Elixir.FidelityRuleEngine.Consumer.Broadway.Producer_2' terminated with reason: #{'__exception__' => true,'__struct__' => 'Elixir.RuntimeError',message => <<"unexpected error when connecting to RabbitMQ broker">>} in 'Elixir.BroadwayRabbitMQ.Producer':handle_connection_failure/2 line 425
2020-05-12 22:50:55.474 [error] <0.9072.0> gen_server 'Elixir.FidelityRuleEngine.Consumer.Broadway.Producer_3' terminated with reason: #{'__exception__' => true,'__struct__' => 'Elixir.RuntimeError',message => <<"unexpected error when connecting to RabbitMQ broker">>} in 'Elixir.BroadwayRabbitMQ.Producer':handle_connection_failure/2 line 425
2020-05-12 22:50:55.475 [error] <0.9074.0> gen_server 'Elixir.FidelityRuleEngine.Consumer.Broadway.Producer_0' terminated with reason: #{'__exception__' => true,'__struct__' => 'Elixir.RuntimeError',message => <<"unexpected error when connecting to RabbitMQ broker">>} in 'Elixir.BroadwayRabbitMQ.Producer':handle_connection_failure/2 line 425
2020-05-12 22:50:55.475 [error] <0.9072.0> CRASH REPORT Process 'Elixir.FidelityRuleEngine.Consumer.Broadway.Producer_3' with 0 neighbours crashed with reason: #{'__exception__' => true,'__struct__' => 'Elixir.RuntimeError',message => <<"unexpected error when connecting to RabbitMQ broker">>} in 'Elixir.BroadwayRabbitMQ.Producer':handle_connection_failure/2 line 425
2020-05-12 22:50:55.476 [error] <0.8841.0> Supervisor 'Elixir.FidelityRuleEngine.Consumer.Broadway.ProducerSupervisor' had child 'Elixir.FidelityRuleEngine.Consumer.Broadway.Producer_3' started with 'Elixir.Broadway.Producer':start_link([{broadway,[{hibernate_after,15000},{batchers,[]},{context,context_not_set},{resubscribe_interval,...},...]},...], 3, [{name,'Elixir.FidelityRuleEngine.Consumer.Broadway.Producer_3'},{hibernate_after,15000}]) at <0.9072.0> exit with reason #{'__exception__' => true,'__struct__' => 'Elixir.RuntimeError',message => <<"unexpected error when connecting to RabbitMQ broker">>} in 'Elixir.BroadwayRabbitMQ.Producer':handle_connection_failure/2 line 425 in context child_terminated
2020-05-12 22:50:55.477 [error] <0.9071.0> CRASH REPORT Process 'Elixir.FidelityRuleEngine.Consumer.Broadway.Producer_2' with 0 neighbours crashed with reason: #{'__exception__' => true,'__struct__' => 'Elixir.RuntimeError',message => <<"unexpected error when connecting to RabbitMQ broker">>} in 'Elixir.BroadwayRabbitMQ.Producer':handle_connection_failure/2 line 425
2020-05-12 22:50:55.477 [error] <0.9070.0> CRASH REPORT Process 'Elixir.FidelityRuleEngine.Consumer.Broadway.Producer_4' with 0 neighbours crashed with reason: #{'__exception__' => true,'__struct__' => 'Elixir.RuntimeError',message => <<"unexpected error when connecting to RabbitMQ broker">>} in 'Elixir.BroadwayRabbitMQ.Producer':handle_connection_failure/2 line 425
2020-05-12 22:50:55.478 [error] <0.8841.0> Supervisor 'Elixir.FidelityRuleEngine.Consumer.Broadway.ProducerSupervisor' had child 'Elixir.FidelityRuleEngine.Consumer.Broadway.Producer_2' started with 'Elixir.Broadway.Producer':start_link([{broadway,[{hibernate_after,15000},{batchers,[]},{context,context_not_set},{resubscribe_interval,...},...]},...], 2, [{name,'Elixir.FidelityRuleEngine.Consumer.Broadway.Producer_2'},{hibernate_after,15000}]) at <0.9071.0> exit with reason #{'__exception__' => true,'__struct__' => 'Elixir.RuntimeError',message => <<"unexpected error when connecting to RabbitMQ broker">>} in 'Elixir.BroadwayRabbitMQ.Producer':handle_connection_failure/2 line 425 in context child_terminated
2020-05-12 22:50:55.480 [error] <0.8841.0> Supervisor 'Elixir.FidelityRuleEngine.Consumer.Broadway.ProducerSupervisor' had child 'Elixir.FidelityRuleEngine.Consumer.Broadway.Producer_4' started with 'Elixir.Broadway.Producer':start_link([{broadway,[{hibernate_after,15000},{batchers,[]},{context,context_not_set},{resubscribe_interval,...},...]},...], 4, [{name,'Elixir.FidelityRuleEngine.Consumer.Broadway.Producer_4'},{hibernate_after,15000}]) at <0.9070.0> exit with reason #{'__exception__' => true,'__struct__' => 'Elixir.RuntimeError',message => <<"unexpected error when connecting to RabbitMQ broker">>} in 'Elixir.BroadwayRabbitMQ.Producer':handle_connection_failure/2 line 425 in context child_terminated
2020-05-12 22:50:55.480 [error] <0.9073.0> CRASH REPORT Process 'Elixir.FidelityRuleEngine.Consumer.Broadway.Producer_1' with 0 neighbours crashed with reason: #{'__exception__' => true,'__struct__' => 'Elixir.RuntimeError',message => <<"unexpected error when connecting to RabbitMQ broker">>} in 'Elixir.BroadwayRabbitMQ.Producer':handle_connection_failure/2 line 425
2020-05-12 22:50:55.482 [error] <0.8841.0> Supervisor 'Elixir.FidelityRuleEngine.Consumer.Broadway.ProducerSupervisor' had child 'Elixir.FidelityRuleEngine.Consumer.Broadway.Producer_1' started with 'Elixir.Broadway.Producer':start_link([{broadway,[{hibernate_after,15000},{batchers,[]},{context,context_not_set},{resubscribe_interval,...},...]},...], 1, [{name,'Elixir.FidelityRuleEngine.Consumer.Broadway.Producer_1'},{hibernate_after,15000}]) at <0.9073.0> exit with reason #{'__exception__' => true,'__struct__' => 'Elixir.RuntimeError',message => <<"unexpected error when connecting to RabbitMQ broker">>} in 'Elixir.BroadwayRabbitMQ.Producer':handle_connection_failure/2 line 425 in context child_terminated
2020-05-12 22:50:55.482 [error] <0.9074.0> CRASH REPORT Process 'Elixir.FidelityRuleEngine.Consumer.Broadway.Producer_0' with 0 neighbours crashed with reason: #{'__exception__' => true,'__struct__' => 'Elixir.RuntimeError',message => <<"unexpected error when connecting to RabbitMQ broker">>} in 'Elixir.BroadwayRabbitMQ.Producer':handle_connection_failure/2 line 425
2020-05-12 22:50:55.484 [error] <0.8841.0> Supervisor 'Elixir.FidelityRuleEngine.Consumer.Broadway.ProducerSupervisor' had child 'Elixir.FidelityRuleEngine.Consumer.Broadway.Producer_0' started with 'Elixir.Broadway.Producer':start_link([{broadway,[{hibernate_after,15000},{batchers,[]},{context,context_not_set},{resubscribe_interval,...},...]},...], 0, [{name,'Elixir.FidelityRuleEngine.Consumer.Broadway.Producer_0'},{hibernate_after,15000}]) at <0.9074.0> exit with reason #{'__exception__' => true,'__struct__' => 'Elixir.RuntimeError',message => <<"unexpected error when connecting to RabbitMQ broker">>} in 'Elixir.BroadwayRabbitMQ.Producer':handle_connection_failure/2 line 425 in context child_terminated
2020-05-12 22:50:58.541 [error] <0.9091.0> gen_server 'Elixir.FidelityRuleEngine.Consumer.Broadway.Producer_2' terminated with reason: #{'__exception__' => true,'__struct__' => 'Elixir.RuntimeError',message => <<"unexpected error when connecting to RabbitMQ broker">>} in 'Elixir.BroadwayRabbitMQ.Producer':handle_connection_failure/2 line 425
2020-05-12 22:50:58.541 [error] <0.9092.0> gen_server 'Elixir.FidelityRuleEngine.Consumer.Broadway.Producer_4' terminated with reason: #{'__exception__' => true,'__struct__' => 'Elixir.RuntimeError',message => <<"unexpected error when connecting to RabbitMQ broker">>} in 'Elixir.BroadwayRabbitMQ.Producer':handle_connection_failure/2 line 425
2020-05-12 22:50:58.542 [error] <0.9093.0> gen_server 'Elixir.FidelityRuleEngine.Consumer.Broadway.Producer_1' terminated with reason: #{'__exception__' => true,'__struct__' => 'Elixir.RuntimeError',message => <<"unexpected error when connecting to RabbitMQ broker">>} in 'Elixir.BroadwayRabbitMQ.Producer':handle_connection_failure/2 line 425
2020-05-12 22:50:58.543 [error] <0.9090.0> gen_server 'Elixir.FidelityRuleEngine.Consumer.Broadway.Producer_3' terminated with reason: #{'__exception__' => true,'__struct__' => 'Elixir.RuntimeError',message => <<"unexpected error when connecting to RabbitMQ broker">>} in 'Elixir.BroadwayRabbitMQ.Producer':handle_connection_failure/2 line 425
2020-05-12 22:50:58.543 [error] <0.9094.0> gen_server 'Elixir.FidelityRuleEngine.Consumer.Broadway.Producer_0' terminated with reason: #{'__exception__' => true,'__struct__' => 'Elixir.RuntimeError',message => <<"unexpected error when connecting to RabbitMQ broker">>} in 'Elixir.BroadwayRabbitMQ.Producer':handle_connection_failure/2 line 425
2020-05-12 22:50:58.546 [error] <0.9091.0> CRASH REPORT Process 'Elixir.FidelityRuleEngine.Consumer.Broadway.Producer_2' with 0 neighbours crashed with reason: #{'__exception__' => true,'__struct__' => 'Elixir.RuntimeError',message => <<"unexpected error when connecting to RabbitMQ broker">>} in 'Elixir.BroadwayRabbitMQ.Producer':handle_connection_failure/2 line 425
2020-05-12 22:50:58.547 [error] <0.8841.0> Supervisor 'Elixir.FidelityRuleEngine.Consumer.Broadway.ProducerSupervisor' had child 'Elixir.FidelityRuleEngine.Consumer.Broadway.Producer_2' started with 'Elixir.Broadway.Producer':start_link([{broadway,[{hibernate_after,15000},{batchers,[]},{context,context_not_set},{resubscribe_interval,...},...]},...], 2, [{name,'Elixir.FidelityRuleEngine.Consumer.Broadway.Producer_2'},{hibernate_after,15000}]) at <0.9091.0> exit with reason #{'__exception__' => true,'__struct__' => 'Elixir.RuntimeError',message => <<"unexpected error when connecting to RabbitMQ broker">>} in 'Elixir.BroadwayRabbitMQ.Producer':handle_connection_failure/2 line 425 in context child_terminated
2020-05-12 22:50:58.548 [error] <0.9093.0> CRASH REPORT Process 'Elixir.FidelityRuleEngine.Consumer.Broadway.Producer_1' with 0 neighbours crashed with reason: #{'__exception__' => true,'__struct__' => 'Elixir.RuntimeError',message => <<"unexpected error when connecting to RabbitMQ broker">>} in 'Elixir.BroadwayRabbitMQ.Producer':handle_connection_failure/2 line 425
2020-05-12 22:50:58.549 [error] <0.9092.0> CRASH REPORT Process 'Elixir.FidelityRuleEngine.Consumer.Broadway.Producer_4' with 0 neighbours crashed with reason: #{'__exception__' => true,'__struct__' => 'Elixir.RuntimeError',message => <<"unexpected error when connecting to RabbitMQ broker">>} in 'Elixir.BroadwayRabbitMQ.Producer':handle_connection_failure/2 line 425
2020-05-12 22:50:58.550 [error] <0.8841.0> Supervisor 'Elixir.FidelityRuleEngine.Consumer.Broadway.ProducerSupervisor' had child 'Elixir.FidelityRuleEngine.Consumer.Broadway.Producer_1' started with 'Elixir.Broadway.Producer':start_link([{broadway,[{hibernate_after,15000},{batchers,[]},{context,context_not_set},{resubscribe_interval,...},...]},...], 1, [{name,'Elixir.FidelityRuleEngine.Consumer.Broadway.Producer_1'},{hibernate_after,15000}]) at <0.9093.0> exit with reason #{'__exception__' => true,'__struct__' => 'Elixir.RuntimeError',message => <<"unexpected error when connecting to RabbitMQ broker">>} in 'Elixir.BroadwayRabbitMQ.Producer':handle_connection_failure/2 line 425 in context child_terminated
2020-05-12 22:50:58.550 [error] <0.9094.0> CRASH REPORT Process 'Elixir.FidelityRuleEngine.Consumer.Broadway.Producer_0' with 0 neighbours crashed with reason: #{'__exception__' => true,'__struct__' => 'Elixir.RuntimeError',message => <<"unexpected error when connecting to RabbitMQ broker">>} in 'Elixir.BroadwayRabbitMQ.Producer':handle_connection_failure/2 line 425
2020-05-12 22:50:58.552 [error] <0.8841.0> Supervisor 'Elixir.FidelityRuleEngine.Consumer.Broadway.ProducerSupervisor' had child 'Elixir.FidelityRuleEngine.Consumer.Broadway.Producer_4' started with 'Elixir.Broadway.Producer':start_link([{broadway,[{hibernate_after,15000},{batchers,[]},{context,context_not_set},{resubscribe_interval,...},...]},...], 4, [{name,'Elixir.FidelityRuleEngine.Consumer.Broadway.Producer_4'},{hibernate_after,15000}]) at <0.9092.0> exit with reason #{'__exception__' => true,'__struct__' => 'Elixir.RuntimeError',message => <<"unexpected error when connecting to RabbitMQ broker">>} in 'Elixir.BroadwayRabbitMQ.Producer':handle_connection_failure/2 line 425 in context child_terminated
2020-05-12 22:50:58.552 [error] <0.9090.0> CRASH REPORT Process 'Elixir.FidelityRuleEngine.Consumer.Broadway.Producer_3' with 0 neighbours crashed with reason: #{'__exception__' => true,'__struct__' => 'Elixir.RuntimeError',message => <<"unexpected error when connecting to RabbitMQ broker">>} in 'Elixir.BroadwayRabbitMQ.Producer':handle_connection_failure/2 line 425
2020-05-12 22:50:58.555 [error] <0.8841.0> Supervisor 'Elixir.FidelityRuleEngine.Consumer.Broadway.ProducerSupervisor' had child 'Elixir.FidelityRuleEngine.Consumer.Broadway.Producer_0' started with 'Elixir.Broadway.Producer':start_link([{broadway,[{hibernate_after,15000},{batchers,[]},{context,context_not_set},{resubscribe_interval,...},...]},...], 0, [{name,'Elixir.FidelityRuleEngine.Consumer.Broadway.Producer_0'},{hibernate_after,15000}]) at <0.9094.0> exit with reason #{'__exception__' => true,'__struct__' => 'Elixir.RuntimeError',message => <<"unexpected error when connecting to RabbitMQ broker">>} in 'Elixir.BroadwayRabbitMQ.Producer':handle_connection_failure/2 line 425 in context child_terminated
2020-05-12 22:50:58.556 [error] <0.8841.0> Supervisor 'Elixir.FidelityRuleEngine.Consumer.Broadway.ProducerSupervisor' had child 'Elixir.FidelityRuleEngine.Consumer.Broadway.Producer_3' started with 'Elixir.Broadway.Producer':start_link([{broadway,[{hibernate_after,15000},{batchers,[]},{context,context_not_set},{resubscribe_interval,...},...]},...], 3, [{name,'Elixir.FidelityRuleEngine.Consumer.Broadway.Producer_3'},{hibernate_after,15000}]) at <0.9090.0> exit with reason #{'__exception__' => true,'__struct__' => 'Elixir.RuntimeError',message => <<"unexpected error when connecting to RabbitMQ broker">>} in 'Elixir.BroadwayRabbitMQ.Producer':handle_connection_failure/2 line 425 in context child_terminated
2020-06-17 17:09:41.557 [error] <0.4090.0> CRASH REPORT Process <0.4090.0> with 0 neighbours exited with reason: {{#{'__exception__' => true,'__struct__' => 'Elixir.Phoenix.Router.NoRouteError',conn => #{'__struct__' => 'Elixir.Plug.Conn',adapter => {'Elixir.Plug.Cowboy.Conn',#{bindings => #{},body_length => 0,cert => undefined,has_body => false,headers => #{<<"accept">> => <<"text/html,application/xhtml+xml,application/xml;q=0.9,image/webp,image/apng,*/*;q=0.8,application/signed-exchange;v=b3;q=0.9">>,<<"accept-encoding">> => <<"gzip, deflate, br">>,<<"accept-language">> => <<"en-US,en;q=0.9,pt-PT...">>,...},...}},...},...},...},...} in 'Elixir.Phoenix.Endpoint.Cowboy2Handler':exit_on_error/4 line 130 in 'Elixir.Phoenix.Endpoint.Cowboy2Handler':exit_on_error/4 line 130
2020-06-17 17:09:41.579 [error] <0.4090.0> Cowboy stream 1 with ranch listener 'Elixir.GqlgatewayWeb.Endpoint.HTTP' and connection process <0.4088.0> had its request process exit with reason: {{#{'__exception__' => true,'__struct__' => 'Elixir.Phoenix.Router.NoRouteError',conn => #{'__struct__' => 'Elixir.Plug.Conn',adapter => {'Elixir.Plug.Cowboy.Conn',#{bindings => #{},body_length => 0,cert => undefined,has_body => false,headers => #{<<"accept">> => <<"text/html,application/xhtml+xml,application/xml;q=0.9,image/webp,image/apng,*/*;q=0.8,application/signed-exchange;v=b3;q=0.9">>,<<"accept-encoding">> => <<"gzip, deflate, br">>,<<"accept-language">> => <<"en-US,en;q=0.9,pt-PT...">>,...},...}},...},...},...},...} in 'Elixir.Phoenix.Endpoint.Cowboy2Handler':exit_on_error/4 line 130
2020-06-18 22:46:33.620 [error] <0.874.0> CRASH REPORT Process <0.874.0> with 0 neighbours exited with reason: {{#{'__exception__' => true,'__struct__' => 'Elixir.UndefinedFunctionError',arity => 1,function => init,message => nil,module => 'Elixir.Phoenix.LiveView.Flash',reason => nil},[{'Elixir.Phoenix.LiveView.Flash',init,[[]],[]},{'Elixir.GqlgatewayWeb.Router',browser,2,[]},{'Elixir.GqlgatewayWeb.Router','__pipe_through2__',1,[{file,"lib/gqlgateway_web/router.ex"},{line,1}]},{'Elixir.Phoenix.Router','__call__',2,[{file,"lib/phoenix/router.ex"},{line,347}]},{'Elixir.GqlgatewayWeb.Endpoint',plug_builder_call,...},...]},...} in 'Elixir.Phoenix.Endpoint.Cowboy2Handler':exit_on_error/4 line 130 in 'Elixir.Phoenix.Endpoint.Cowboy2Handler':exit_on_error/4 line 130
2020-06-18 22:46:33.624 [error] <0.874.0> Cowboy stream 1 with ranch listener 'Elixir.GqlgatewayWeb.Endpoint.HTTP' and connection process <0.873.0> had its request process exit with reason: {{#{'__exception__' => true,'__struct__' => 'Elixir.UndefinedFunctionError',arity => 1,function => init,message => nil,module => 'Elixir.Phoenix.LiveView.Flash',reason => nil},[{'Elixir.Phoenix.LiveView.Flash',init,[[]],[]},{'Elixir.GqlgatewayWeb.Router',browser,2,[]},{'Elixir.GqlgatewayWeb.Router','__pipe_through2__',1,[{file,"lib/gqlgateway_web/router.ex"},{line,1}]},{'Elixir.Phoenix.Router','__call__',2,[{file,"lib/phoenix/router.ex"},{line,347}]},{'Elixir.GqlgatewayWeb.Endpoint',plug_builder_call,...},...]},...} in 'Elixir.Phoenix.Endpoint.Cowboy2Handler':exit_on_error/4 line 130
2020-06-18 22:46:34.079 [error] <0.876.0> CRASH REPORT Process <0.876.0> with 0 neighbours exited with reason: {{#{'__exception__' => true,'__struct__' => 'Elixir.UndefinedFunctionError',arity => 1,function => init,message => nil,module => 'Elixir.Phoenix.LiveView.Flash',reason => nil},[{'Elixir.Phoenix.LiveView.Flash',init,[[]],[]},{'Elixir.GqlgatewayWeb.Router',browser,2,[]},{'Elixir.GqlgatewayWeb.Router','__pipe_through0__',1,[{file,"lib/gqlgateway_web/router.ex"},{line,1}]},{'Elixir.Phoenix.Router','__call__',2,[{file,"lib/phoenix/router.ex"},{line,347}]},{'Elixir.GqlgatewayWeb.Endpoint',plug_builder_call,...},...]},...} in 'Elixir.Phoenix.Endpoint.Cowboy2Handler':exit_on_error/4 line 130 in 'Elixir.Phoenix.Endpoint.Cowboy2Handler':exit_on_error/4 line 130
2020-06-18 22:46:34.080 [error] <0.876.0> Cowboy stream 2 with ranch listener 'Elixir.GqlgatewayWeb.Endpoint.HTTP' and connection process <0.873.0> had its request process exit with reason: {{#{'__exception__' => true,'__struct__' => 'Elixir.UndefinedFunctionError',arity => 1,function => init,message => nil,module => 'Elixir.Phoenix.LiveView.Flash',reason => nil},[{'Elixir.Phoenix.LiveView.Flash',init,[[]],[]},{'Elixir.GqlgatewayWeb.Router',browser,2,[]},{'Elixir.GqlgatewayWeb.Router','__pipe_through0__',1,[{file,"lib/gqlgateway_web/router.ex"},{line,1}]},{'Elixir.Phoenix.Router','__call__',2,[{file,"lib/phoenix/router.ex"},{line,347}]},{'Elixir.GqlgatewayWeb.Endpoint',plug_builder_call,...},...]},...} in 'Elixir.Phoenix.Endpoint.Cowboy2Handler':exit_on_error/4 line 130
2020-06-18 22:46:35.831 [error] <0.877.0> CRASH REPORT Process <0.877.0> with 0 neighbours exited with reason: {{#{'__exception__' => true,'__struct__' => 'Elixir.UndefinedFunctionError',arity => 1,function => init,message => nil,module => 'Elixir.Phoenix.LiveView.Flash',reason => nil},[{'Elixir.Phoenix.LiveView.Flash',init,[[]],[]},{'Elixir.GqlgatewayWeb.Router',browser,2,[]},{'Elixir.GqlgatewayWeb.Router','__pipe_through2__',1,[{file,"lib/gqlgateway_web/router.ex"},{line,1}]},{'Elixir.Phoenix.Router','__call__',2,[{file,"lib/phoenix/router.ex"},{line,347}]},{'Elixir.GqlgatewayWeb.Endpoint',plug_builder_call,...},...]},...} in 'Elixir.Phoenix.Endpoint.Cowboy2Handler':exit_on_error/4 line 130 in 'Elixir.Phoenix.Endpoint.Cowboy2Handler':exit_on_error/4 line 130
2020-06-18 22:46:35.831 [error] <0.877.0> Cowboy stream 3 with ranch listener 'Elixir.GqlgatewayWeb.Endpoint.HTTP' and connection process <0.873.0> had its request process exit with reason: {{#{'__exception__' => true,'__struct__' => 'Elixir.UndefinedFunctionError',arity => 1,function => init,message => nil,module => 'Elixir.Phoenix.LiveView.Flash',reason => nil},[{'Elixir.Phoenix.LiveView.Flash',init,[[]],[]},{'Elixir.GqlgatewayWeb.Router',browser,2,[]},{'Elixir.GqlgatewayWeb.Router','__pipe_through2__',1,[{file,"lib/gqlgateway_web/router.ex"},{line,1}]},{'Elixir.Phoenix.Router','__call__',2,[{file,"lib/phoenix/router.ex"},{line,347}]},{'Elixir.GqlgatewayWeb.Endpoint',plug_builder_call,...},...]},...} in 'Elixir.Phoenix.Endpoint.Cowboy2Handler':exit_on_error/4 line 130
2020-06-18 23:05:23.781 [error] <0.851.0> CRASH REPORT Process <0.851.0> with 0 neighbours exited with reason: {{#{'__exception__' => true,'__struct__' => 'Elixir.UndefinedFunctionError',arity => 1,function => init,message => nil,module => 'Elixir.Phoenix.LiveView.Flash',reason => nil},[{'Elixir.Phoenix.LiveView.Flash',init,[[]],[]},{'Elixir.GqlgatewayWeb.Router',browser,2,[]},{'Elixir.GqlgatewayWeb.Router','__pipe_through0__',1,[{file,"lib/gqlgateway_web/router.ex"},{line,1}]},{'Elixir.Phoenix.Router','__call__',2,[{file,"lib/phoenix/router.ex"},{line,347}]},{'Elixir.GqlgatewayWeb.Endpoint',plug_builder_call,...},...]},...} in 'Elixir.Phoenix.Endpoint.Cowboy2Handler':exit_on_error/4 line 130 in 'Elixir.Phoenix.Endpoint.Cowboy2Handler':exit_on_error/4 line 130
2020-06-18 23:05:23.791 [error] <0.851.0> Cowboy stream 1 with ranch listener 'Elixir.GqlgatewayWeb.Endpoint.HTTP' and connection process <0.849.0> had its request process exit with reason: {{#{'__exception__' => true,'__struct__' => 'Elixir.UndefinedFunctionError',arity => 1,function => init,message => nil,module => 'Elixir.Phoenix.LiveView.Flash',reason => nil},[{'Elixir.Phoenix.LiveView.Flash',init,[[]],[]},{'Elixir.GqlgatewayWeb.Router',browser,2,[]},{'Elixir.GqlgatewayWeb.Router','__pipe_through0__',1,[{file,"lib/gqlgateway_web/router.ex"},{line,1}]},{'Elixir.Phoenix.Router','__call__',2,[{file,"lib/phoenix/router.ex"},{line,347}]},{'Elixir.GqlgatewayWeb.Endpoint',plug_builder_call,...},...]},...} in 'Elixir.Phoenix.Endpoint.Cowboy2Handler':exit_on_error/4 line 130
2020-06-18 23:05:31.428 [error] <0.853.0> CRASH REPORT Process <0.853.0> with 0 neighbours exited with reason: {{#{'__exception__' => true,'__struct__' => 'Elixir.UndefinedFunctionError',arity => 1,function => init,message => nil,module => 'Elixir.Phoenix.LiveView.Flash',reason => nil},[{'Elixir.Phoenix.LiveView.Flash',init,[[]],[]},{'Elixir.GqlgatewayWeb.Router',browser,2,[]},{'Elixir.GqlgatewayWeb.Router','__pipe_through0__',1,[{file,"lib/gqlgateway_web/router.ex"},{line,1}]},{'Elixir.Phoenix.Router','__call__',2,[{file,"lib/phoenix/router.ex"},{line,347}]},{'Elixir.GqlgatewayWeb.Endpoint',plug_builder_call,...},...]},...} in 'Elixir.Phoenix.Endpoint.Cowboy2Handler':exit_on_error/4 line 130 in 'Elixir.Phoenix.Endpoint.Cowboy2Handler':exit_on_error/4 line 130
2020-06-18 23:05:31.429 [error] <0.853.0> Cowboy stream 2 with ranch listener 'Elixir.GqlgatewayWeb.Endpoint.HTTP' and connection process <0.849.0> had its request process exit with reason: {{#{'__exception__' => true,'__struct__' => 'Elixir.UndefinedFunctionError',arity => 1,function => init,message => nil,module => 'Elixir.Phoenix.LiveView.Flash',reason => nil},[{'Elixir.Phoenix.LiveView.Flash',init,[[]],[]},{'Elixir.GqlgatewayWeb.Router',browser,2,[]},{'Elixir.GqlgatewayWeb.Router','__pipe_through0__',1,[{file,"lib/gqlgateway_web/router.ex"},{line,1}]},{'Elixir.Phoenix.Router','__call__',2,[{file,"lib/phoenix/router.ex"},{line,347}]},{'Elixir.GqlgatewayWeb.Endpoint',plug_builder_call,...},...]},...} in 'Elixir.Phoenix.Endpoint.Cowboy2Handler':exit_on_error/4 line 130
2020-06-18 23:05:38.983 [error] <0.855.0> CRASH REPORT Process <0.855.0> with 0 neighbours exited with reason: {{#{'__exception__' => true,'__struct__' => 'Elixir.UndefinedFunctionError',arity => 1,function => init,message => nil,module => 'Elixir.Phoenix.LiveView.Flash',reason => nil},[{'Elixir.Phoenix.LiveView.Flash',init,[[]],[]},{'Elixir.GqlgatewayWeb.Router',browser,2,[]},{'Elixir.GqlgatewayWeb.Router','__pipe_through0__',1,[{file,"lib/gqlgateway_web/router.ex"},{line,1}]},{'Elixir.Phoenix.Router','__call__',2,[{file,"lib/phoenix/router.ex"},{line,347}]},{'Elixir.GqlgatewayWeb.Endpoint',plug_builder_call,...},...]},...} in 'Elixir.Phoenix.Endpoint.Cowboy2Handler':exit_on_error/4 line 130 in 'Elixir.Phoenix.Endpoint.Cowboy2Handler':exit_on_error/4 line 130
2020-06-18 23:05:38.983 [error] <0.855.0> Cowboy stream 3 with ranch listener 'Elixir.GqlgatewayWeb.Endpoint.HTTP' and connection process <0.849.0> had its request process exit with reason: {{#{'__exception__' => true,'__struct__' => 'Elixir.UndefinedFunctionError',arity => 1,function => init,message => nil,module => 'Elixir.Phoenix.LiveView.Flash',reason => nil},[{'Elixir.Phoenix.LiveView.Flash',init,[[]],[]},{'Elixir.GqlgatewayWeb.Router',browser,2,[]},{'Elixir.GqlgatewayWeb.Router','__pipe_through0__',1,[{file,"lib/gqlgateway_web/router.ex"},{line,1}]},{'Elixir.Phoenix.Router','__call__',2,[{file,"lib/phoenix/router.ex"},{line,347}]},{'Elixir.GqlgatewayWeb.Endpoint',plug_builder_call,...},...]},...} in 'Elixir.Phoenix.Endpoint.Cowboy2Handler':exit_on_error/4 line 130
2020-06-18 23:13:20.324 [error] <0.865.0> CRASH REPORT Process <0.865.0> with 0 neighbours exited with reason: {{#{'__exception__' => true,'__struct__' => 'Elixir.UndefinedFunctionError',arity => 2,function => render,message => nil,module => 'Elixir.GqlgatewayWeb.PageView',reason => nil},[{'Elixir.GqlgatewayWeb.PageView',render,[<<"index.html">>,#{conn => #{'__struct__' => 'Elixir.Plug.Conn',adapter => {'Elixir.Plug.Cowboy.Conn',#{bindings => #{},body_length => 0,cert => undefined,has_body => false,headers => #{<<"accept">> => <<"text/html,application/xhtml+xml,application/xml;q=0.9,image/webp,im...">>,...},...}},...},...}],...},...]},...} in 'Elixir.Phoenix.Endpoint.Cowboy2Handler':exit_on_error/4 line 130 in 'Elixir.Phoenix.Endpoint.Cowboy2Handler':exit_on_error/4 line 130
2020-06-18 23:13:20.340 [error] <0.865.0> Cowboy stream 1 with ranch listener 'Elixir.GqlgatewayWeb.Endpoint.HTTP' and connection process <0.863.0> had its request process exit with reason: {{#{'__exception__' => true,'__struct__' => 'Elixir.UndefinedFunctionError',arity => 2,function => render,message => nil,module => 'Elixir.GqlgatewayWeb.PageView',reason => nil},[{'Elixir.GqlgatewayWeb.PageView',render,[<<"index.html">>,#{conn => #{'__struct__' => 'Elixir.Plug.Conn',adapter => {'Elixir.Plug.Cowboy.Conn',#{bindings => #{},body_length => 0,cert => undefined,has_body => false,headers => #{<<"accept">> => <<"text/html,application/xhtml+xml,application/xml;q=0.9,image/webp,im...">>,...},...}},...},...}],...},...]},...} in 'Elixir.Phoenix.Endpoint.Cowboy2Handler':exit_on_error/4 line 130
2020-06-18 23:22:25.652 [error] <0.1262.0> CRASH REPORT Process <0.1262.0> with 0 neighbours exited with reason: {{#{'__exception__' => true,'__struct__' => 'Elixir.Phoenix.Router.NoRouteError',conn => #{'__struct__' => 'Elixir.Plug.Conn',adapter => {'Elixir.Plug.Cowboy.Conn',#{bindings => #{},body_length => 0,cert => undefined,has_body => false,headers => #{<<"accept">> => <<"text/html,application/xhtml+xml,application/xml;q=0.9,image/webp,image/apng,*/*;q=0.8,application/signed-exchange;v=b3;q=0.9">>,<<"accept-encoding">> => <<"gzip, deflate, br">>,<<"accept-language">> => <<"en-US,en;q=0.9,pt-PT...">>,...},...}},...},...},...},...} in 'Elixir.Phoenix.Endpoint.Cowboy2Handler':exit_on_error/4 line 130 in 'Elixir.Phoenix.Endpoint.Cowboy2Handler':exit_on_error/4 line 130
2020-06-18 23:22:25.661 [error] <0.1262.0> Cowboy stream 1 with ranch listener 'Elixir.GqlgatewayWeb.Endpoint.HTTP' and connection process <0.1260.0> had its request process exit with reason: {{#{'__exception__' => true,'__struct__' => 'Elixir.Phoenix.Router.NoRouteError',conn => #{'__struct__' => 'Elixir.Plug.Conn',adapter => {'Elixir.Plug.Cowboy.Conn',#{bindings => #{},body_length => 0,cert => undefined,has_body => false,headers => #{<<"accept">> => <<"text/html,application/xhtml+xml,application/xml;q=0.9,image/webp,image/apng,*/*;q=0.8,application/signed-exchange;v=b3;q=0.9">>,<<"accept-encoding">> => <<"gzip, deflate, br">>,<<"accept-language">> => <<"en-US,en;q=0.9,pt-PT...">>,...},...}},...},...},...},...} in 'Elixir.Phoenix.Endpoint.Cowboy2Handler':exit_on_error/4 line 130
2020-06-18 23:22:48.373 [error] <0.1264.0> CRASH REPORT Process <0.1264.0> with 0 neighbours exited with reason: {{#{'__exception__' => true,'__struct__' => 'Elixir.Phoenix.Router.NoRouteError',conn => #{'__struct__' => 'Elixir.Plug.Conn',adapter => {'Elixir.Plug.Cowboy.Conn',#{bindings => #{},body_length => 0,cert => undefined,has_body => false,headers => #{<<"accept">> => <<"text/html,application/xhtml+xml,application/xml;q=0.9,image/webp,image/apng,*/*;q=0.8,application/signed-exchange;v=b3;q=0.9">>,<<"accept-encoding">> => <<"gzip, deflate, br">>,<<"accept-language">> => <<"en-US,en;q=0.9,pt-PT...">>,...},...}},...},...},...},...} in 'Elixir.Phoenix.Endpoint.Cowboy2Handler':exit_on_error/4 line 130 in 'Elixir.Phoenix.Endpoint.Cowboy2Handler':exit_on_error/4 line 130
2020-06-18 23:22:48.374 [error] <0.1264.0> Cowboy stream 2 with ranch listener 'Elixir.GqlgatewayWeb.Endpoint.HTTP' and connection process <0.1260.0> had its request process exit with reason: {{#{'__exception__' => true,'__struct__' => 'Elixir.Phoenix.Router.NoRouteError',conn => #{'__struct__' => 'Elixir.Plug.Conn',adapter => {'Elixir.Plug.Cowboy.Conn',#{bindings => #{},body_length => 0,cert => undefined,has_body => false,headers => #{<<"accept">> => <<"text/html,application/xhtml+xml,application/xml;q=0.9,image/webp,image/apng,*/*;q=0.8,application/signed-exchange;v=b3;q=0.9">>,<<"accept-encoding">> => <<"gzip, deflate, br">>,<<"accept-language">> => <<"en-US,en;q=0.9,pt-PT...">>,...},...}},...},...},...},...} in 'Elixir.Phoenix.Endpoint.Cowboy2Handler':exit_on_error/4 line 130
2020-06-18 23:22:58.333 [error] <0.1266.0> CRASH REPORT Process <0.1266.0> with 0 neighbours exited with reason: {{#{'__exception__' => true,'__struct__' => 'Elixir.UndefinedFunctionError',arity => 2,function => render,message => nil,module => 'Elixir.GqlgatewayWeb.Pow.SessionView',reason => nil},[{'Elixir.GqlgatewayWeb.Pow.SessionView',render,[<<"new.html">>,#{action => <<"/session">>,changeset => #{'__struct__' => 'Elixir.Ecto.Changeset',action => nil,changes => #{},constraints => [#{constraint => <<"users_username_index">>,error_message => <<"has already been taken">>,error_type => unique,field => ...,...},...],...},...}],...},...]},...} in 'Elixir.Phoenix.Endpoint.Cowboy2Handler':exit_on_error/4 line 130 in 'Elixir.Phoenix.Endpoint.Cowboy2Handler':exit_on_error/4 line 130
2020-06-18 23:22:58.333 [error] <0.1266.0> Cowboy stream 3 with ranch listener 'Elixir.GqlgatewayWeb.Endpoint.HTTP' and connection process <0.1260.0> had its request process exit with reason: {{#{'__exception__' => true,'__struct__' => 'Elixir.UndefinedFunctionError',arity => 2,function => render,message => nil,module => 'Elixir.GqlgatewayWeb.Pow.SessionView',reason => nil},[{'Elixir.GqlgatewayWeb.Pow.SessionView',render,[<<"new.html">>,#{action => <<"/session">>,changeset => #{'__struct__' => 'Elixir.Ecto.Changeset',action => nil,changes => #{},constraints => [#{constraint => <<"users_username_index">>,error_message => <<"has already been taken">>,error_type => unique,field => ...,...},...],...},...}],...},...]},...} in 'Elixir.Phoenix.Endpoint.Cowboy2Handler':exit_on_error/4 line 130
2020-06-18 23:24:45.497 [error] <0.849.0> CRASH REPORT Process <0.849.0> with 0 neighbours exited with reason: {{#{'__exception__' => true,'__struct__' => 'Elixir.UndefinedFunctionError',arity => 2,function => render,message => nil,module => 'Elixir.GqlgatewayWeb.Pow.SessionView',reason => nil},[{'Elixir.GqlgatewayWeb.Pow.SessionView',render,[<<"new.html">>,#{action => <<"/session">>,changeset => #{'__struct__' => 'Elixir.Ecto.Changeset',action => nil,changes => #{},constraints => [#{constraint => <<"users_username_index">>,error_message => <<"has already been taken">>,error_type => unique,field => ...,...},...],...},...}],...},...]},...} in 'Elixir.Phoenix.Endpoint.Cowboy2Handler':exit_on_error/4 line 130 in 'Elixir.Phoenix.Endpoint.Cowboy2Handler':exit_on_error/4 line 130
2020-06-18 23:24:45.508 [error] <0.849.0> Cowboy stream 1 with ranch listener 'Elixir.GqlgatewayWeb.Endpoint.HTTP' and connection process <0.847.0> had its request process exit with reason: {{#{'__exception__' => true,'__struct__' => 'Elixir.UndefinedFunctionError',arity => 2,function => render,message => nil,module => 'Elixir.GqlgatewayWeb.Pow.SessionView',reason => nil},[{'Elixir.GqlgatewayWeb.Pow.SessionView',render,[<<"new.html">>,#{action => <<"/session">>,changeset => #{'__struct__' => 'Elixir.Ecto.Changeset',action => nil,changes => #{},constraints => [#{constraint => <<"users_username_index">>,error_message => <<"has already been taken">>,error_type => unique,field => ...,...},...],...},...}],...},...]},...} in 'Elixir.Phoenix.Endpoint.Cowboy2Handler':exit_on_error/4 line 130
2020-06-18 23:25:12.683 [error] <0.851.0> CRASH REPORT Process <0.851.0> with 0 neighbours exited with reason: {{#{'__exception__' => true,'__struct__' => 'Elixir.Phoenix.Router.NoRouteError',conn => #{'__struct__' => 'Elixir.Plug.Conn',adapter => {'Elixir.Plug.Cowboy.Conn',#{bindings => #{},body_length => 0,cert => undefined,has_body => false,headers => #{<<"accept">> => <<"text/html,application/xhtml+xml,application/xml;q=0.9,image/webp,image/apng,*/*;q=0.8,application/signed-exchange;v=b3;q=0.9">>,<<"accept-encoding">> => <<"gzip, deflate, br">>,<<"accept-language">> => <<"en-US,en;q=0.9,pt-PT...">>,...},...}},...},...},...},...} in 'Elixir.Phoenix.Endpoint.Cowboy2Handler':exit_on_error/4 line 130 in 'Elixir.Phoenix.Endpoint.Cowboy2Handler':exit_on_error/4 line 130
2020-06-18 23:25:12.684 [error] <0.851.0> Cowboy stream 2 with ranch listener 'Elixir.GqlgatewayWeb.Endpoint.HTTP' and connection process <0.847.0> had its request process exit with reason: {{#{'__exception__' => true,'__struct__' => 'Elixir.Phoenix.Router.NoRouteError',conn => #{'__struct__' => 'Elixir.Plug.Conn',adapter => {'Elixir.Plug.Cowboy.Conn',#{bindings => #{},body_length => 0,cert => undefined,has_body => false,headers => #{<<"accept">> => <<"text/html,application/xhtml+xml,application/xml;q=0.9,image/webp,image/apng,*/*;q=0.8,application/signed-exchange;v=b3;q=0.9">>,<<"accept-encoding">> => <<"gzip, deflate, br">>,<<"accept-language">> => <<"en-US,en;q=0.9,pt-PT...">>,...},...}},...},...},...},...} in 'Elixir.Phoenix.Endpoint.Cowboy2Handler':exit_on_error/4 line 130
2020-06-19 00:10:04.774 [error] <0.1054.0> CRASH REPORT Process <0.1054.0> with 0 neighbours exited with reason: {{#{'__exception__' => true,'__struct__' => 'Elixir.Phoenix.Template.UndefinedError',assigns => #{action => <<"/session">>,changeset => #{'__struct__' => 'Elixir.Ecto.Changeset',action => nil,changes => #{},constraints => [#{constraint => <<"users_username_index">>,error_message => <<"has already been taken">>,error_type => unique,field => username,match => exact,type => unique},#{constraint => <<"users_email_index">>,error_message => <<"has already been taken">>,error_type => unique,field => ...,...},...],...},...},...},...},...} in 'Elixir.Phoenix.Endpoint.Cowboy2Handler':exit_on_error/4 line 130 in 'Elixir.Phoenix.Endpoint.Cowboy2Handler':exit_on_error/4 line 130
2020-06-19 00:10:04.781 [error] <0.1054.0> Cowboy stream 3 with ranch listener 'Elixir.GqlgatewayWeb.Endpoint.HTTP' and connection process <0.1049.0> had its request process exit with reason: {{#{'__exception__' => true,'__struct__' => 'Elixir.Phoenix.Template.UndefinedError',assigns => #{action => <<"/session">>,changeset => #{'__struct__' => 'Elixir.Ecto.Changeset',action => nil,changes => #{},constraints => [#{constraint => <<"users_username_index">>,error_message => <<"has already been taken">>,error_type => unique,field => username,match => exact,type => unique},#{constraint => <<"users_email_index">>,error_message => <<"has already been taken">>,error_type => unique,field => ...,...},...],...},...},...},...},...} in 'Elixir.Phoenix.Endpoint.Cowboy2Handler':exit_on_error/4 line 130
2020-06-19 00:39:54.120 [error] <0.967.0> CRASH REPORT Process <0.967.0> with 0 neighbours exited with reason: {{#{'__exception__' => true,'__struct__' => 'Elixir.Phoenix.Router.NoRouteError',conn => #{'__struct__' => 'Elixir.Plug.Conn',adapter => {'Elixir.Plug.Cowboy.Conn',#{bindings => #{},body_length => 0,cert => undefined,has_body => false,headers => #{<<"accept">> => <<"text/html,application/xhtml+xml,application/xml;q=0.9,image/webp,image/apng,*/*;q=0.8,application/signed-exchange;v=b3;q=0.9">>,<<"accept-encoding">> => <<"gzip, deflate, br">>,<<"accept-language">> => <<"en-US,en;q=0.9,pt-PT...">>,...},...}},...},...},...},...} in 'Elixir.Phoenix.Endpoint.Cowboy2Handler':exit_on_error/4 line 130 in 'Elixir.Phoenix.Endpoint.Cowboy2Handler':exit_on_error/4 line 130
2020-06-19 00:39:54.124 [error] <0.967.0> Cowboy stream 10 with ranch listener 'Elixir.GqlgatewayWeb.Endpoint.HTTP' and connection process <0.950.0> had its request process exit with reason: {{#{'__exception__' => true,'__struct__' => 'Elixir.Phoenix.Router.NoRouteError',conn => #{'__struct__' => 'Elixir.Plug.Conn',adapter => {'Elixir.Plug.Cowboy.Conn',#{bindings => #{},body_length => 0,cert => undefined,has_body => false,headers => #{<<"accept">> => <<"text/html,application/xhtml+xml,application/xml;q=0.9,image/webp,image/apng,*/*;q=0.8,application/signed-exchange;v=b3;q=0.9">>,<<"accept-encoding">> => <<"gzip, deflate, br">>,<<"accept-language">> => <<"en-US,en;q=0.9,pt-PT...">>,...},...}},...},...},...},...} in 'Elixir.Phoenix.Endpoint.Cowboy2Handler':exit_on_error/4 line 130
2020-06-19 00:40:15.176 [error] <0.972.0> CRASH REPORT Process <0.972.0> with 0 neighbours exited with reason: {{#{'__exception__' => true,'__struct__' => 'Elixir.Phoenix.Router.NoRouteError',conn => #{'__struct__' => 'Elixir.Plug.Conn',adapter => {'Elixir.Plug.Cowboy.Conn',#{bindings => #{},body_length => 0,cert => undefined,has_body => false,headers => #{<<"accept">> => <<"text/html,application/xhtml+xml,application/xml;q=0.9,image/webp,image/apng,*/*;q=0.8,application/signed-exchange;v=b3;q=0.9">>,<<"accept-encoding">> => <<"gzip, deflate, br">>,<<"accept-language">> => <<"en-US,en;q=0.9,pt-PT...">>,...},...}},...},...},...},...} in 'Elixir.Phoenix.Endpoint.Cowboy2Handler':exit_on_error/4 line 130 in 'Elixir.Phoenix.Endpoint.Cowboy2Handler':exit_on_error/4 line 130
2020-06-19 00:40:15.176 [error] <0.972.0> Cowboy stream 15 with ranch listener 'Elixir.GqlgatewayWeb.Endpoint.HTTP' and connection process <0.950.0> had its request process exit with reason: {{#{'__exception__' => true,'__struct__' => 'Elixir.Phoenix.Router.NoRouteError',conn => #{'__struct__' => 'Elixir.Plug.Conn',adapter => {'Elixir.Plug.Cowboy.Conn',#{bindings => #{},body_length => 0,cert => undefined,has_body => false,headers => #{<<"accept">> => <<"text/html,application/xhtml+xml,application/xml;q=0.9,image/webp,image/apng,*/*;q=0.8,application/signed-exchange;v=b3;q=0.9">>,<<"accept-encoding">> => <<"gzip, deflate, br">>,<<"accept-language">> => <<"en-US,en;q=0.9,pt-PT...">>,...},...}},...},...},...},...} in 'Elixir.Phoenix.Endpoint.Cowboy2Handler':exit_on_error/4 line 130
2020-06-21 16:38:08.194 [error] <0.857.0> CRASH REPORT Process <0.857.0> with 0 neighbours exited with reason: {{#{'__exception__' => true,'__struct__' => 'Elixir.Phoenix.Router.NoRouteError',conn => #{'__struct__' => 'Elixir.Plug.Conn',adapter => {'Elixir.Plug.Cowboy.Conn',#{bindings => #{},body_length => 0,cert => undefined,has_body => false,headers => #{<<"accept">> => <<"text/html,application/xhtml+xml,application/xml;q=0.9,image/webp,image/apng,*/*;q=0.8,application/signed-exchange;v=b3;q=0.9">>,<<"accept-encoding">> => <<"gzip, deflate, br">>,<<"accept-language">> => <<"en-US,en;q=0.9,pt-PT...">>,...},...}},...},...},...},...} in 'Elixir.Phoenix.Endpoint.Cowboy2Handler':exit_on_error/4 line 130 in 'Elixir.Phoenix.Endpoint.Cowboy2Handler':exit_on_error/4 line 130
2020-06-21 16:38:08.210 [error] <0.857.0> Cowboy stream 4 with ranch listener 'Elixir.GqlgatewayWeb.Endpoint.HTTP' and connection process <0.852.0> had its request process exit with reason: {{#{'__exception__' => true,'__struct__' => 'Elixir.Phoenix.Router.NoRouteError',conn => #{'__struct__' => 'Elixir.Plug.Conn',adapter => {'Elixir.Plug.Cowboy.Conn',#{bindings => #{},body_length => 0,cert => undefined,has_body => false,headers => #{<<"accept">> => <<"text/html,application/xhtml+xml,application/xml;q=0.9,image/webp,image/apng,*/*;q=0.8,application/signed-exchange;v=b3;q=0.9">>,<<"accept-encoding">> => <<"gzip, deflate, br">>,<<"accept-language">> => <<"en-US,en;q=0.9,pt-PT...">>,...},...}},...},...},...},...} in 'Elixir.Phoenix.Endpoint.Cowboy2Handler':exit_on_error/4 line 130
2020-06-21 16:38:28.290 [error] <0.858.0> CRASH REPORT Process <0.858.0> with 0 neighbours exited with reason: {{#{'__exception__' => true,'__struct__' => 'Elixir.Phoenix.Router.NoRouteError',conn => #{'__struct__' => 'Elixir.Plug.Conn',adapter => {'Elixir.Plug.Cowboy.Conn',#{bindings => #{},body_length => 0,cert => undefined,has_body => false,headers => #{<<"accept">> => <<"text/html,application/xhtml+xml,application/xml;q=0.9,image/webp,image/apng,*/*;q=0.8,application/signed-exchange;v=b3;q=0.9">>,<<"accept-encoding">> => <<"gzip, deflate, br">>,<<"accept-language">> => <<"en-US,en;q=0.9,pt-PT...">>,...},...}},...},...},...},...} in 'Elixir.Phoenix.Endpoint.Cowboy2Handler':exit_on_error/4 line 130 in 'Elixir.Phoenix.Endpoint.Cowboy2Handler':exit_on_error/4 line 130
2020-06-21 16:38:28.292 [error] <0.858.0> Cowboy stream 5 with ranch listener 'Elixir.GqlgatewayWeb.Endpoint.HTTP' and connection process <0.852.0> had its request process exit with reason: {{#{'__exception__' => true,'__struct__' => 'Elixir.Phoenix.Router.NoRouteError',conn => #{'__struct__' => 'Elixir.Plug.Conn',adapter => {'Elixir.Plug.Cowboy.Conn',#{bindings => #{},body_length => 0,cert => undefined,has_body => false,headers => #{<<"accept">> => <<"text/html,application/xhtml+xml,application/xml;q=0.9,image/webp,image/apng,*/*;q=0.8,application/signed-exchange;v=b3;q=0.9">>,<<"accept-encoding">> => <<"gzip, deflate, br">>,<<"accept-language">> => <<"en-US,en;q=0.9,pt-PT...">>,...},...}},...},...},...},...} in 'Elixir.Phoenix.Endpoint.Cowboy2Handler':exit_on_error/4 line 130
2020-06-21 16:38:31.071 [error] <0.859.0> CRASH REPORT Process <0.859.0> with 0 neighbours exited with reason: {{#{'__exception__' => true,'__struct__' => 'Elixir.Phoenix.Router.NoRouteError',conn => #{'__struct__' => 'Elixir.Plug.Conn',adapter => {'Elixir.Plug.Cowboy.Conn',#{bindings => #{},body_length => 0,cert => undefined,has_body => false,headers => #{<<"accept">> => <<"text/html,application/xhtml+xml,application/xml;q=0.9,image/webp,image/apng,*/*;q=0.8,application/signed-exchange;v=b3;q=0.9">>,<<"accept-encoding">> => <<"gzip, deflate, br">>,<<"accept-language">> => <<"en-US,en;q=0.9,pt-PT...">>,...},...}},...},...},...},...} in 'Elixir.Phoenix.Endpoint.Cowboy2Handler':exit_on_error/4 line 130 in 'Elixir.Phoenix.Endpoint.Cowboy2Handler':exit_on_error/4 line 130
2020-06-21 16:38:31.073 [error] <0.859.0> Cowboy stream 6 with ranch listener 'Elixir.GqlgatewayWeb.Endpoint.HTTP' and connection process <0.852.0> had its request process exit with reason: {{#{'__exception__' => true,'__struct__' => 'Elixir.Phoenix.Router.NoRouteError',conn => #{'__struct__' => 'Elixir.Plug.Conn',adapter => {'Elixir.Plug.Cowboy.Conn',#{bindings => #{},body_length => 0,cert => undefined,has_body => false,headers => #{<<"accept">> => <<"text/html,application/xhtml+xml,application/xml;q=0.9,image/webp,image/apng,*/*;q=0.8,application/signed-exchange;v=b3;q=0.9">>,<<"accept-encoding">> => <<"gzip, deflate, br">>,<<"accept-language">> => <<"en-US,en;q=0.9,pt-PT...">>,...},...}},...},...},...},...} in 'Elixir.Phoenix.Endpoint.Cowboy2Handler':exit_on_error/4 line 130
2020-06-21 16:38:38.644 [error] <0.860.0> CRASH REPORT Process <0.860.0> with 0 neighbours exited with reason: {{#{'__exception__' => true,'__struct__' => 'Elixir.UndefinedFunctionError',arity => 1,function => init,message => nil,module => 'Elixir.GqlgatewayWeb.Plugs.EnsureRolePlug',reason => nil},[{'Elixir.GqlgatewayWeb.Plugs.EnsureRolePlug',init,[admin],[]},{'Elixir.GqlgatewayWeb.Router',admin,2,[]},{'Elixir.GqlgatewayWeb.Router','__pipe_through2__',1,[{file,"lib/gqlgateway_web/router.ex"},{line,1}]},{'Elixir.Phoenix.Router','__call__',2,[{file,"lib/phoenix/router.ex"},{line,347}]},{'Elixir.GqlgatewayWeb.Endpoint',...},...]},...} in 'Elixir.Phoenix.Endpoint.Cowboy2Handler':exit_on_error/4 line 130 in 'Elixir.Phoenix.Endpoint.Cowboy2Handler':exit_on_error/4 line 130
2020-06-21 16:38:38.651 [error] <0.860.0> Cowboy stream 7 with ranch listener 'Elixir.GqlgatewayWeb.Endpoint.HTTP' and connection process <0.852.0> had its request process exit with reason: {{#{'__exception__' => true,'__struct__' => 'Elixir.UndefinedFunctionError',arity => 1,function => init,message => nil,module => 'Elixir.GqlgatewayWeb.Plugs.EnsureRolePlug',reason => nil},[{'Elixir.GqlgatewayWeb.Plugs.EnsureRolePlug',init,[admin],[]},{'Elixir.GqlgatewayWeb.Router',admin,2,[]},{'Elixir.GqlgatewayWeb.Router','__pipe_through2__',1,[{file,"lib/gqlgateway_web/router.ex"},{line,1}]},{'Elixir.Phoenix.Router','__call__',2,[{file,"lib/phoenix/router.ex"},{line,347}]},{'Elixir.GqlgatewayWeb.Endpoint',...},...]},...} in 'Elixir.Phoenix.Endpoint.Cowboy2Handler':exit_on_error/4 line 130
2020-06-21 16:38:45.342 [error] <0.861.0> CRASH REPORT Process <0.861.0> with 0 neighbours exited with reason: {{#{'__exception__' => true,'__struct__' => 'Elixir.UndefinedFunctionError',arity => 1,function => init,message => nil,module => 'Elixir.GqlgatewayWeb.Plugs.EnsureRolePlug',reason => nil},[{'Elixir.GqlgatewayWeb.Plugs.EnsureRolePlug',init,[admin],[]},{'Elixir.GqlgatewayWeb.Router',admin,2,[]},{'Elixir.GqlgatewayWeb.Router','__pipe_through2__',1,[{file,"lib/gqlgateway_web/router.ex"},{line,1}]},{'Elixir.Phoenix.Router','__call__',2,[{file,"lib/phoenix/router.ex"},{line,347}]},{'Elixir.GqlgatewayWeb.Endpoint',...},...]},...} in 'Elixir.Phoenix.Endpoint.Cowboy2Handler':exit_on_error/4 line 130 in 'Elixir.Phoenix.Endpoint.Cowboy2Handler':exit_on_error/4 line 130
2020-06-21 16:38:45.344 [error] <0.861.0> Cowboy stream 8 with ranch listener 'Elixir.GqlgatewayWeb.Endpoint.HTTP' and connection process <0.852.0> had its request process exit with reason: {{#{'__exception__' => true,'__struct__' => 'Elixir.UndefinedFunctionError',arity => 1,function => init,message => nil,module => 'Elixir.GqlgatewayWeb.Plugs.EnsureRolePlug',reason => nil},[{'Elixir.GqlgatewayWeb.Plugs.EnsureRolePlug',init,[admin],[]},{'Elixir.GqlgatewayWeb.Router',admin,2,[]},{'Elixir.GqlgatewayWeb.Router','__pipe_through2__',1,[{file,"lib/gqlgateway_web/router.ex"},{line,1}]},{'Elixir.Phoenix.Router','__call__',2,[{file,"lib/phoenix/router.ex"},{line,347}]},{'Elixir.GqlgatewayWeb.Endpoint',...},...]},...} in 'Elixir.Phoenix.Endpoint.Cowboy2Handler':exit_on_error/4 line 130
2020-06-21 16:39:29.923 [error] <0.900.0> CRASH REPORT Process <0.900.0> with 0 neighbours exited with reason: {{#{'__exception__' => true,'__struct__' => 'Elixir.Phoenix.Router.NoRouteError',conn => #{'__struct__' => 'Elixir.Plug.Conn',adapter => {'Elixir.Plug.Cowboy.Conn',#{bindings => #{},body_length => 0,cert => undefined,has_body => false,headers => #{<<"accept">> => <<"text/html,application/xhtml+xml,application/xml;q=0.9,image/webp,image/apng,*/*;q=0.8,application/signed-exchange;v=b3;q=0.9">>,<<"accept-encoding">> => <<"gzip, deflate, br">>,<<"accept-language">> => <<"en-US,en;q=0.9,pt-PT...">>,...},...}},...},...},...},...} in 'Elixir.Phoenix.Endpoint.Cowboy2Handler':exit_on_error/4 line 130 in 'Elixir.Phoenix.Endpoint.Cowboy2Handler':exit_on_error/4 line 130
2020-06-21 16:39:29.925 [error] <0.900.0> Cowboy stream 3 with ranch listener 'Elixir.GqlgatewayWeb.Endpoint.HTTP' and connection process <0.894.0> had its request process exit with reason: {{#{'__exception__' => true,'__struct__' => 'Elixir.Phoenix.Router.NoRouteError',conn => #{'__struct__' => 'Elixir.Plug.Conn',adapter => {'Elixir.Plug.Cowboy.Conn',#{bindings => #{},body_length => 0,cert => undefined,has_body => false,headers => #{<<"accept">> => <<"text/html,application/xhtml+xml,application/xml;q=0.9,image/webp,image/apng,*/*;q=0.8,application/signed-exchange;v=b3;q=0.9">>,<<"accept-encoding">> => <<"gzip, deflate, br">>,<<"accept-language">> => <<"en-US,en;q=0.9,pt-PT...">>,...},...}},...},...},...},...} in 'Elixir.Phoenix.Endpoint.Cowboy2Handler':exit_on_error/4 line 130
2020-06-21 16:40:58.749 [error] <0.960.0> CRASH REPORT Process <0.960.0> with 0 neighbours exited with reason: {{#{'__exception__' => true,'__struct__' => 'Elixir.Phoenix.Router.NoRouteError',conn => #{'__struct__' => 'Elixir.Plug.Conn',adapter => {'Elixir.Plug.Cowboy.Conn',#{bindings => #{},body_length => 0,cert => undefined,has_body => false,headers => #{<<"accept">> => <<"text/html,application/xhtml+xml,application/xml;q=0.9,image/webp,image/apng,*/*;q=0.8,application/signed-exchange;v=b3;q=0.9">>,<<"accept-encoding">> => <<"gzip, deflate, br">>,<<"accept-language">> => <<"en-US,en;q=0.9,pt-PT...">>,...},...}},...},...},...},...} in 'Elixir.Phoenix.Endpoint.Cowboy2Handler':exit_on_error/4 line 130 in 'Elixir.Phoenix.Endpoint.Cowboy2Handler':exit_on_error/4 line 130
2020-06-21 16:40:58.750 [error] <0.960.0> Cowboy stream 3 with ranch listener 'Elixir.GqlgatewayWeb.Endpoint.HTTP' and connection process <0.955.0> had its request process exit with reason: {{#{'__exception__' => true,'__struct__' => 'Elixir.Phoenix.Router.NoRouteError',conn => #{'__struct__' => 'Elixir.Plug.Conn',adapter => {'Elixir.Plug.Cowboy.Conn',#{bindings => #{},body_length => 0,cert => undefined,has_body => false,headers => #{<<"accept">> => <<"text/html,application/xhtml+xml,application/xml;q=0.9,image/webp,image/apng,*/*;q=0.8,application/signed-exchange;v=b3;q=0.9">>,<<"accept-encoding">> => <<"gzip, deflate, br">>,<<"accept-language">> => <<"en-US,en;q=0.9,pt-PT...">>,...},...}},...},...},...},...} in 'Elixir.Phoenix.Endpoint.Cowboy2Handler':exit_on_error/4 line 130
2020-06-21 16:44:29.084 [error] <0.994.0> CRASH REPORT Process <0.994.0> with 0 neighbours exited with reason: {{#{'__exception__' => true,'__struct__' => 'Elixir.Phoenix.Router.NoRouteError',conn => #{'__struct__' => 'Elixir.Plug.Conn',adapter => {'Elixir.Plug.Cowboy.Conn',#{bindings => #{},body_length => 0,cert => undefined,has_body => false,headers => #{<<"accept">> => <<"text/html,application/xhtml+xml,application/xml;q=0.9,image/webp,image/apng,*/*;q=0.8,application/signed-exchange;v=b3;q=0.9">>,<<"accept-encoding">> => <<"gzip, deflate, br">>,<<"accept-language">> => <<"en-US,en;q=0.9,pt-PT...">>,...},...}},...},...},...},...} in 'Elixir.Phoenix.Endpoint.Cowboy2Handler':exit_on_error/4 line 130 in 'Elixir.Phoenix.Endpoint.Cowboy2Handler':exit_on_error/4 line 130
2020-06-21 16:44:29.086 [error] <0.994.0> Cowboy stream 3 with ranch listener 'Elixir.GqlgatewayWeb.Endpoint.HTTP' and connection process <0.989.0> had its request process exit with reason: {{#{'__exception__' => true,'__struct__' => 'Elixir.Phoenix.Router.NoRouteError',conn => #{'__struct__' => 'Elixir.Plug.Conn',adapter => {'Elixir.Plug.Cowboy.Conn',#{bindings => #{},body_length => 0,cert => undefined,has_body => false,headers => #{<<"accept">> => <<"text/html,application/xhtml+xml,application/xml;q=0.9,image/webp,image/apng,*/*;q=0.8,application/signed-exchange;v=b3;q=0.9">>,<<"accept-encoding">> => <<"gzip, deflate, br">>,<<"accept-language">> => <<"en-US,en;q=0.9,pt-PT...">>,...},...}},...},...},...},...} in 'Elixir.Phoenix.Endpoint.Cowboy2Handler':exit_on_error/4 line 130
2020-06-21 16:55:49.734 [error] <0.1035.0> CRASH REPORT Process <0.1035.0> with 0 neighbours exited with reason: {{#{'__exception__' => true,'__struct__' => 'Elixir.Phoenix.Router.NoRouteError',conn => #{'__struct__' => 'Elixir.Plug.Conn',adapter => {'Elixir.Plug.Cowboy.Conn',#{bindings => #{},body_length => 0,cert => undefined,has_body => false,headers => #{<<"accept">> => <<"text/html,application/xhtml+xml,application/xml;q=0.9,image/webp,image/apng,*/*;q=0.8,application/signed-exchange;v=b3;q=0.9">>,<<"accept-encoding">> => <<"gzip, deflate, br">>,<<"accept-language">> => <<"en-US,en;q=0.9,pt-PT...">>,...},...}},...},...},...},...} in 'Elixir.Phoenix.Endpoint.Cowboy2Handler':exit_on_error/4 line 130 in 'Elixir.Phoenix.Endpoint.Cowboy2Handler':exit_on_error/4 line 130
2020-06-21 16:55:49.735 [error] <0.1035.0> Cowboy stream 1 with ranch listener 'Elixir.GqlgatewayWeb.Endpoint.HTTP' and connection process <0.1033.0> had its request process exit with reason: {{#{'__exception__' => true,'__struct__' => 'Elixir.Phoenix.Router.NoRouteError',conn => #{'__struct__' => 'Elixir.Plug.Conn',adapter => {'Elixir.Plug.Cowboy.Conn',#{bindings => #{},body_length => 0,cert => undefined,has_body => false,headers => #{<<"accept">> => <<"text/html,application/xhtml+xml,application/xml;q=0.9,image/webp,image/apng,*/*;q=0.8,application/signed-exchange;v=b3;q=0.9">>,<<"accept-encoding">> => <<"gzip, deflate, br">>,<<"accept-language">> => <<"en-US,en;q=0.9,pt-PT...">>,...},...}},...},...},...},...} in 'Elixir.Phoenix.Endpoint.Cowboy2Handler':exit_on_error/4 line 130
2020-06-21 16:56:09.728 [error] <0.1041.0> CRASH REPORT Process <0.1041.0> with 0 neighbours exited with reason: {{#{'__exception__' => true,'__struct__' => 'Elixir.Phoenix.Router.NoRouteError',conn => #{'__struct__' => 'Elixir.Plug.Conn',adapter => {'Elixir.Plug.Cowboy.Conn',#{bindings => #{},body_length => 0,cert => undefined,has_body => false,headers => #{<<"accept">> => <<"text/html,application/xhtml+xml,application/xml;q=0.9,image/webp,image/apng,*/*;q=0.8,application/signed-exchange;v=b3;q=0.9">>,<<"accept-encoding">> => <<"gzip, deflate, br">>,<<"accept-language">> => <<"en-US,en;q=0.9,pt-PT...">>,...},...}},...},...},...},...} in 'Elixir.Phoenix.Endpoint.Cowboy2Handler':exit_on_error/4 line 130 in 'Elixir.Phoenix.Endpoint.Cowboy2Handler':exit_on_error/4 line 130
2020-06-21 16:56:09.731 [error] <0.1041.0> Cowboy stream 3 with ranch listener 'Elixir.GqlgatewayWeb.Endpoint.HTTP' and connection process <0.1036.0> had its request process exit with reason: {{#{'__exception__' => true,'__struct__' => 'Elixir.Phoenix.Router.NoRouteError',conn => #{'__struct__' => 'Elixir.Plug.Conn',adapter => {'Elixir.Plug.Cowboy.Conn',#{bindings => #{},body_length => 0,cert => undefined,has_body => false,headers => #{<<"accept">> => <<"text/html,application/xhtml+xml,application/xml;q=0.9,image/webp,image/apng,*/*;q=0.8,application/signed-exchange;v=b3;q=0.9">>,<<"accept-encoding">> => <<"gzip, deflate, br">>,<<"accept-language">> => <<"en-US,en;q=0.9,pt-PT...">>,...},...}},...},...},...},...} in 'Elixir.Phoenix.Endpoint.Cowboy2Handler':exit_on_error/4 line 130
2020-06-22 07:27:38.908 [error] <0.12336.0> CRASH REPORT Process <0.12336.0> with 0 neighbours exited with reason: {{#{'__exception__' => true,'__struct__' => 'Elixir.Phoenix.Router.NoRouteError',conn => #{'__struct__' => 'Elixir.Plug.Conn',adapter => {'Elixir.Plug.Cowboy.Conn',#{bindings => #{},body_length => 0,cert => undefined,has_body => false,headers => #{<<"accept">> => <<"text/html,application/xhtml+xml,application/xml;q=0.9,image/webp,image/apng,*/*;q=0.8,application/signed-exchange;v=b3;q=0.9">>,<<"accept-encoding">> => <<"gzip, deflate, br">>,<<"accept-language">> => <<"en-US,en;q=0.9,pt-PT...">>,...},...}},...},...},...},...} in 'Elixir.Phoenix.Endpoint.Cowboy2Handler':exit_on_error/4 line 130 in 'Elixir.Phoenix.Endpoint.Cowboy2Handler':exit_on_error/4 line 130
2020-06-22 07:27:38.910 [error] <0.12336.0> Cowboy stream 4 with ranch listener 'Elixir.GqlgatewayWeb.Endpoint.HTTP' and connection process <0.12330.0> had its request process exit with reason: {{#{'__exception__' => true,'__struct__' => 'Elixir.Phoenix.Router.NoRouteError',conn => #{'__struct__' => 'Elixir.Plug.Conn',adapter => {'Elixir.Plug.Cowboy.Conn',#{bindings => #{},body_length => 0,cert => undefined,has_body => false,headers => #{<<"accept">> => <<"text/html,application/xhtml+xml,application/xml;q=0.9,image/webp,image/apng,*/*;q=0.8,application/signed-exchange;v=b3;q=0.9">>,<<"accept-encoding">> => <<"gzip, deflate, br">>,<<"accept-language">> => <<"en-US,en;q=0.9,pt-PT...">>,...},...}},...},...},...},...} in 'Elixir.Phoenix.Endpoint.Cowboy2Handler':exit_on_error/4 line 130
2020-06-22 07:37:19.399 [error] <0.12277.0> CRASH REPORT Process <0.12277.0> with 0 neighbours exited with reason: {{#{'__exception__' => true,'__struct__' => 'Elixir.Phoenix.Router.NoRouteError',conn => #{'__struct__' => 'Elixir.Plug.Conn',adapter => {'Elixir.Plug.Cowboy.Conn',#{bindings => #{},body_length => 0,cert => undefined,has_body => false,headers => #{<<"accept">> => <<"text/html,application/xhtml+xml,application/xml;q=0.9,image/webp,image/apng,*/*;q=0.8,application/signed-exchange;v=b3;q=0.9">>,<<"accept-encoding">> => <<"gzip, deflate, br">>,<<"accept-language">> => <<"en-US,en;q=0.9,pt-PT...">>,...},...}},...},...},...},...} in 'Elixir.Phoenix.Endpoint.Cowboy2Handler':exit_on_error/4 line 130 in 'Elixir.Phoenix.Endpoint.Cowboy2Handler':exit_on_error/4 line 130
2020-06-22 07:37:19.415 [error] <0.12277.0> Cowboy stream 1 with ranch listener 'Elixir.GqlgatewayWeb.Endpoint.HTTP' and connection process <0.12275.0> had its request process exit with reason: {{#{'__exception__' => true,'__struct__' => 'Elixir.Phoenix.Router.NoRouteError',conn => #{'__struct__' => 'Elixir.Plug.Conn',adapter => {'Elixir.Plug.Cowboy.Conn',#{bindings => #{},body_length => 0,cert => undefined,has_body => false,headers => #{<<"accept">> => <<"text/html,application/xhtml+xml,application/xml;q=0.9,image/webp,image/apng,*/*;q=0.8,application/signed-exchange;v=b3;q=0.9">>,<<"accept-encoding">> => <<"gzip, deflate, br">>,<<"accept-language">> => <<"en-US,en;q=0.9,pt-PT...">>,...},...}},...},...},...},...} in 'Elixir.Phoenix.Endpoint.Cowboy2Handler':exit_on_error/4 line 130
2020-06-22 07:37:42.568 [error] <0.12288.0> CRASH REPORT Process <0.12288.0> with 0 neighbours exited with reason: {{#{'__exception__' => true,'__struct__' => 'Elixir.Phoenix.Router.NoRouteError',conn => #{'__struct__' => 'Elixir.Plug.Conn',adapter => {'Elixir.Plug.Cowboy.Conn',#{bindings => #{},body_length => 0,cert => undefined,has_body => false,headers => #{<<"accept">> => <<"text/html,application/xhtml+xml,application/xml;q=0.9,image/webp,image/apng,*/*;q=0.8,application/signed-exchange;v=b3;q=0.9">>,<<"accept-encoding">> => <<"gzip, deflate, br">>,<<"accept-language">> => <<"en-US,en;q=0.9,pt-PT...">>,...},...}},...},...},...},...} in 'Elixir.Phoenix.Endpoint.Cowboy2Handler':exit_on_error/4 line 130 in 'Elixir.Phoenix.Endpoint.Cowboy2Handler':exit_on_error/4 line 130
2020-06-22 07:37:42.568 [error] <0.12288.0> Cowboy stream 6 with ranch listener 'Elixir.GqlgatewayWeb.Endpoint.HTTP' and connection process <0.12275.0> had its request process exit with reason: {{#{'__exception__' => true,'__struct__' => 'Elixir.Phoenix.Router.NoRouteError',conn => #{'__struct__' => 'Elixir.Plug.Conn',adapter => {'Elixir.Plug.Cowboy.Conn',#{bindings => #{},body_length => 0,cert => undefined,has_body => false,headers => #{<<"accept">> => <<"text/html,application/xhtml+xml,application/xml;q=0.9,image/webp,image/apng,*/*;q=0.8,application/signed-exchange;v=b3;q=0.9">>,<<"accept-encoding">> => <<"gzip, deflate, br">>,<<"accept-language">> => <<"en-US,en;q=0.9,pt-PT...">>,...},...}},...},...},...},...} in 'Elixir.Phoenix.Endpoint.Cowboy2Handler':exit_on_error/4 line 130
2020-06-22 07:39:00.404 [error] <0.12323.0> CRASH REPORT Process <0.12323.0> with 0 neighbours exited with reason: {{#{'__exception__' => true,'__struct__' => 'Elixir.Phoenix.Router.NoRouteError',conn => #{'__struct__' => 'Elixir.Plug.Conn',adapter => {'Elixir.Plug.Cowboy.Conn',#{bindings => #{},body_length => 0,cert => undefined,has_body => false,headers => #{<<"accept">> => <<"text/html,application/xhtml+xml,application/xml;q=0.9,image/webp,image/apng,*/*;q=0.8,application/signed-exchange;v=b3;q=0.9">>,<<"accept-encoding">> => <<"gzip, deflate, br">>,<<"accept-language">> => <<"en-US,en;q=0.9,pt-PT...">>,...},...}},...},...},...},...} in 'Elixir.Phoenix.Endpoint.Cowboy2Handler':exit_on_error/4 line 130 in 'Elixir.Phoenix.Endpoint.Cowboy2Handler':exit_on_error/4 line 130
2020-06-22 07:39:00.404 [error] <0.12323.0> Cowboy stream 4 with ranch listener 'Elixir.GqlgatewayWeb.Endpoint.HTTP' and connection process <0.12317.0> had its request process exit with reason: {{#{'__exception__' => true,'__struct__' => 'Elixir.Phoenix.Router.NoRouteError',conn => #{'__struct__' => 'Elixir.Plug.Conn',adapter => {'Elixir.Plug.Cowboy.Conn',#{bindings => #{},body_length => 0,cert => undefined,has_body => false,headers => #{<<"accept">> => <<"text/html,application/xhtml+xml,application/xml;q=0.9,image/webp,image/apng,*/*;q=0.8,application/signed-exchange;v=b3;q=0.9">>,<<"accept-encoding">> => <<"gzip, deflate, br">>,<<"accept-language">> => <<"en-US,en;q=0.9,pt-PT...">>,...},...}},...},...},...},...} in 'Elixir.Phoenix.Endpoint.Cowboy2Handler':exit_on_error/4 line 130
2020-06-22 07:53:14.618 [error] <0.12467.0> CRASH REPORT Process <0.12467.0> with 0 neighbours exited with reason: {{#{'__exception__' => true,'__struct__' => 'Elixir.Phoenix.Router.NoRouteError',conn => #{'__struct__' => 'Elixir.Plug.Conn',adapter => {'Elixir.Plug.Cowboy.Conn',#{bindings => #{},body_length => 0,cert => undefined,has_body => false,headers => #{<<"accept">> => <<"text/html,application/xhtml+xml,application/xml;q=0.9,image/webp,image/apng,*/*;q=0.8,application/signed-exchange;v=b3;q=0.9">>,<<"accept-encoding">> => <<"gzip, deflate, br">>,<<"accept-language">> => <<"en-US,en;q=0.9,pt-PT...">>,...},...}},...},...},...},...} in 'Elixir.Phoenix.Endpoint.Cowboy2Handler':exit_on_error/4 line 130 in 'Elixir.Phoenix.Endpoint.Cowboy2Handler':exit_on_error/4 line 130
2020-06-22 07:53:14.618 [error] <0.12467.0> Cowboy stream 2 with ranch listener 'Elixir.GqlgatewayWeb.Endpoint.HTTP' and connection process <0.12464.0> had its request process exit with reason: {{#{'__exception__' => true,'__struct__' => 'Elixir.Phoenix.Router.NoRouteError',conn => #{'__struct__' => 'Elixir.Plug.Conn',adapter => {'Elixir.Plug.Cowboy.Conn',#{bindings => #{},body_length => 0,cert => undefined,has_body => false,headers => #{<<"accept">> => <<"text/html,application/xhtml+xml,application/xml;q=0.9,image/webp,image/apng,*/*;q=0.8,application/signed-exchange;v=b3;q=0.9">>,<<"accept-encoding">> => <<"gzip, deflate, br">>,<<"accept-language">> => <<"en-US,en;q=0.9,pt-PT...">>,...},...}},...},...},...},...} in 'Elixir.Phoenix.Endpoint.Cowboy2Handler':exit_on_error/4 line 130
2020-06-22 07:55:22.249 [error] <0.12491.0> CRASH REPORT Process <0.12491.0> with 0 neighbours exited with reason: {{#{'__exception__' => true,'__struct__' => 'Elixir.Phoenix.Router.NoRouteError',conn => #{'__struct__' => 'Elixir.Plug.Conn',adapter => {'Elixir.Plug.Cowboy.Conn',#{bindings => #{},body_length => 0,cert => undefined,has_body => false,headers => #{<<"accept">> => <<"text/html,application/xhtml+xml,application/xml;q=0.9,image/webp,image/apng,*/*;q=0.8,application/signed-exchange;v=b3;q=0.9">>,<<"accept-encoding">> => <<"gzip, deflate, br">>,<<"accept-language">> => <<"en-US,en;q=0.9,pt-PT...">>,...},...}},...},...},...},...} in 'Elixir.Phoenix.Endpoint.Cowboy2Handler':exit_on_error/4 line 130 in 'Elixir.Phoenix.Endpoint.Cowboy2Handler':exit_on_error/4 line 130
2020-06-22 07:55:22.250 [error] <0.12491.0> Cowboy stream 1 with ranch listener 'Elixir.GqlgatewayWeb.Endpoint.HTTP' and connection process <0.12490.0> had its request process exit with reason: {{#{'__exception__' => true,'__struct__' => 'Elixir.Phoenix.Router.NoRouteError',conn => #{'__struct__' => 'Elixir.Plug.Conn',adapter => {'Elixir.Plug.Cowboy.Conn',#{bindings => #{},body_length => 0,cert => undefined,has_body => false,headers => #{<<"accept">> => <<"text/html,application/xhtml+xml,application/xml;q=0.9,image/webp,image/apng,*/*;q=0.8,application/signed-exchange;v=b3;q=0.9">>,<<"accept-encoding">> => <<"gzip, deflate, br">>,<<"accept-language">> => <<"en-US,en;q=0.9,pt-PT...">>,...},...}},...},...},...},...} in 'Elixir.Phoenix.Endpoint.Cowboy2Handler':exit_on_error/4 line 130
2020-06-22 07:55:23.273 [error] <0.12492.0> CRASH REPORT Process <0.12492.0> with 0 neighbours exited with reason: {{#{'__exception__' => true,'__struct__' => 'Elixir.Phoenix.Router.NoRouteError',conn => #{'__struct__' => 'Elixir.Plug.Conn',adapter => {'Elixir.Plug.Cowboy.Conn',#{bindings => #{},body_length => 0,cert => undefined,has_body => false,headers => #{<<"accept">> => <<"text/html,application/xhtml+xml,application/xml;q=0.9,image/webp,image/apng,*/*;q=0.8,application/signed-exchange;v=b3;q=0.9">>,<<"accept-encoding">> => <<"gzip, deflate, br">>,<<"accept-language">> => <<"en-US,en;q=0.9,pt-PT...">>,...},...}},...},...},...},...} in 'Elixir.Phoenix.Endpoint.Cowboy2Handler':exit_on_error/4 line 130 in 'Elixir.Phoenix.Endpoint.Cowboy2Handler':exit_on_error/4 line 130
2020-06-22 07:55:23.273 [error] <0.12492.0> Cowboy stream 2 with ranch listener 'Elixir.GqlgatewayWeb.Endpoint.HTTP' and connection process <0.12490.0> had its request process exit with reason: {{#{'__exception__' => true,'__struct__' => 'Elixir.Phoenix.Router.NoRouteError',conn => #{'__struct__' => 'Elixir.Plug.Conn',adapter => {'Elixir.Plug.Cowboy.Conn',#{bindings => #{},body_length => 0,cert => undefined,has_body => false,headers => #{<<"accept">> => <<"text/html,application/xhtml+xml,application/xml;q=0.9,image/webp,image/apng,*/*;q=0.8,application/signed-exchange;v=b3;q=0.9">>,<<"accept-encoding">> => <<"gzip, deflate, br">>,<<"accept-language">> => <<"en-US,en;q=0.9,pt-PT...">>,...},...}},...},...},...},...} in 'Elixir.Phoenix.Endpoint.Cowboy2Handler':exit_on_error/4 line 130
2020-06-22 07:55:24.666 [error] <0.12493.0> CRASH REPORT Process <0.12493.0> with 0 neighbours exited with reason: {{#{'__exception__' => true,'__struct__' => 'Elixir.Phoenix.Router.NoRouteError',conn => #{'__struct__' => 'Elixir.Plug.Conn',adapter => {'Elixir.Plug.Cowboy.Conn',#{bindings => #{},body_length => 0,cert => undefined,has_body => false,headers => #{<<"accept">> => <<"text/html,application/xhtml+xml,application/xml;q=0.9,image/webp,image/apng,*/*;q=0.8,application/signed-exchange;v=b3;q=0.9">>,<<"accept-encoding">> => <<"gzip, deflate, br">>,<<"accept-language">> => <<"en-US,en;q=0.9,pt-PT...">>,...},...}},...},...},...},...} in 'Elixir.Phoenix.Endpoint.Cowboy2Handler':exit_on_error/4 line 130 in 'Elixir.Phoenix.Endpoint.Cowboy2Handler':exit_on_error/4 line 130
2020-06-22 07:55:24.667 [error] <0.12493.0> Cowboy stream 3 with ranch listener 'Elixir.GqlgatewayWeb.Endpoint.HTTP' and connection process <0.12490.0> had its request process exit with reason: {{#{'__exception__' => true,'__struct__' => 'Elixir.Phoenix.Router.NoRouteError',conn => #{'__struct__' => 'Elixir.Plug.Conn',adapter => {'Elixir.Plug.Cowboy.Conn',#{bindings => #{},body_length => 0,cert => undefined,has_body => false,headers => #{<<"accept">> => <<"text/html,application/xhtml+xml,application/xml;q=0.9,image/webp,image/apng,*/*;q=0.8,application/signed-exchange;v=b3;q=0.9">>,<<"accept-encoding">> => <<"gzip, deflate, br">>,<<"accept-language">> => <<"en-US,en;q=0.9,pt-PT...">>,...},...}},...},...},...},...} in 'Elixir.Phoenix.Endpoint.Cowboy2Handler':exit_on_error/4 line 130
2020-06-22 07:55:28.484 [error] <0.12495.0> CRASH REPORT Process <0.12495.0> with 0 neighbours exited with reason: {{#{'__exception__' => true,'__struct__' => 'Elixir.Phoenix.Router.NoRouteError',conn => #{'__struct__' => 'Elixir.Plug.Conn',adapter => {'Elixir.Plug.Cowboy.Conn',#{bindings => #{},body_length => 0,cert => undefined,has_body => false,headers => #{<<"accept">> => <<"text/html,application/xhtml+xml,application/xml;q=0.9,image/webp,image/apng,*/*;q=0.8,application/signed-exchange;v=b3;q=0.9">>,<<"accept-encoding">> => <<"gzip, deflate, br">>,<<"accept-language">> => <<"en-US,en;q=0.9,pt-PT...">>,...},...}},...},...},...},...} in 'Elixir.Phoenix.Endpoint.Cowboy2Handler':exit_on_error/4 line 130 in 'Elixir.Phoenix.Endpoint.Cowboy2Handler':exit_on_error/4 line 130
2020-06-22 07:55:28.484 [error] <0.12495.0> Cowboy stream 4 with ranch listener 'Elixir.GqlgatewayWeb.Endpoint.HTTP' and connection process <0.12490.0> had its request process exit with reason: {{#{'__exception__' => true,'__struct__' => 'Elixir.Phoenix.Router.NoRouteError',conn => #{'__struct__' => 'Elixir.Plug.Conn',adapter => {'Elixir.Plug.Cowboy.Conn',#{bindings => #{},body_length => 0,cert => undefined,has_body => false,headers => #{<<"accept">> => <<"text/html,application/xhtml+xml,application/xml;q=0.9,image/webp,image/apng,*/*;q=0.8,application/signed-exchange;v=b3;q=0.9">>,<<"accept-encoding">> => <<"gzip, deflate, br">>,<<"accept-language">> => <<"en-US,en;q=0.9,pt-PT...">>,...},...}},...},...},...},...} in 'Elixir.Phoenix.Endpoint.Cowboy2Handler':exit_on_error/4 line 130
2020-06-22 07:55:43.639 [error] <0.12506.0> CRASH REPORT Process <0.12506.0> with 0 neighbours exited with reason: {{#{'__exception__' => true,'__struct__' => 'Elixir.Phoenix.Router.NoRouteError',conn => #{'__struct__' => 'Elixir.Plug.Conn',adapter => {'Elixir.Plug.Cowboy.Conn',#{bindings => #{},body_length => 0,cert => undefined,has_body => false,headers => #{<<"accept">> => <<"text/html,application/xhtml+xml,application/xml;q=0.9,image/webp,image/apng,*/*;q=0.8,application/signed-exchange;v=b3;q=0.9">>,<<"accept-encoding">> => <<"gzip, deflate, br">>,<<"accept-language">> => <<"en-US,en;q=0.9,pt-PT...">>,...},...}},...},...},...},...} in 'Elixir.Phoenix.Endpoint.Cowboy2Handler':exit_on_error/4 line 130 in 'Elixir.Phoenix.Endpoint.Cowboy2Handler':exit_on_error/4 line 130
2020-06-22 07:55:43.640 [error] <0.12506.0> Cowboy stream 3 with ranch listener 'Elixir.GqlgatewayWeb.Endpoint.HTTP' and connection process <0.12498.0> had its request process exit with reason: {{#{'__exception__' => true,'__struct__' => 'Elixir.Phoenix.Router.NoRouteError',conn => #{'__struct__' => 'Elixir.Plug.Conn',adapter => {'Elixir.Plug.Cowboy.Conn',#{bindings => #{},body_length => 0,cert => undefined,has_body => false,headers => #{<<"accept">> => <<"text/html,application/xhtml+xml,application/xml;q=0.9,image/webp,image/apng,*/*;q=0.8,application/signed-exchange;v=b3;q=0.9">>,<<"accept-encoding">> => <<"gzip, deflate, br">>,<<"accept-language">> => <<"en-US,en;q=0.9,pt-PT...">>,...},...}},...},...},...},...} in 'Elixir.Phoenix.Endpoint.Cowboy2Handler':exit_on_error/4 line 130
2020-06-22 08:12:34.999 [error] <0.860.0> CRASH REPORT Process <0.860.0> with 0 neighbours exited with reason: {{#{'__exception__' => true,'__struct__' => 'Elixir.Phoenix.Router.NoRouteError',conn => #{'__struct__' => 'Elixir.Plug.Conn',adapter => {'Elixir.Plug.Cowboy.Conn',#{bindings => #{},body_length => 0,cert => undefined,has_body => false,headers => #{<<"accept">> => <<"text/html,application/xhtml+xml,application/xml;q=0.9,image/webp,image/apng,*/*;q=0.8,application/signed-exchange;v=b3;q=0.9">>,<<"accept-encoding">> => <<"gzip, deflate, br">>,<<"accept-language">> => <<"en-US,en;q=0.9,pt-PT...">>,...},...}},...},...},...},...} in 'Elixir.Phoenix.Endpoint.Cowboy2Handler':exit_on_error/4 line 130 in 'Elixir.Phoenix.Endpoint.Cowboy2Handler':exit_on_error/4 line 130
2020-06-22 08:12:35.004 [error] <0.860.0> Cowboy stream 2 with ranch listener 'Elixir.GqlgatewayWeb.Endpoint.HTTP' and connection process <0.856.0> had its request process exit with reason: {{#{'__exception__' => true,'__struct__' => 'Elixir.Phoenix.Router.NoRouteError',conn => #{'__struct__' => 'Elixir.Plug.Conn',adapter => {'Elixir.Plug.Cowboy.Conn',#{bindings => #{},body_length => 0,cert => undefined,has_body => false,headers => #{<<"accept">> => <<"text/html,application/xhtml+xml,application/xml;q=0.9,image/webp,image/apng,*/*;q=0.8,application/signed-exchange;v=b3;q=0.9">>,<<"accept-encoding">> => <<"gzip, deflate, br">>,<<"accept-language">> => <<"en-US,en;q=0.9,pt-PT...">>,...},...}},...},...},...},...} in 'Elixir.Phoenix.Endpoint.Cowboy2Handler':exit_on_error/4 line 130
2020-06-22 08:16:24.150 [error] <0.868.0> CRASH REPORT Process <0.868.0> with 0 neighbours exited with reason: {{#{'__exception__' => true,'__struct__' => 'Elixir.Phoenix.Router.NoRouteError',conn => #{'__struct__' => 'Elixir.Plug.Conn',adapter => {'Elixir.Plug.Cowboy.Conn',#{bindings => #{},body_length => 0,cert => undefined,has_body => false,headers => #{<<"accept">> => <<"text/html,application/xhtml+xml,application/xml;q=0.9,image/webp,image/apng,*/*;q=0.8,application/signed-exchange;v=b3;q=0.9">>,<<"accept-encoding">> => <<"gzip, deflate, br">>,<<"accept-language">> => <<"en-US,en;q=0.9,pt-PT...">>,...},...}},...},...},...},...} in 'Elixir.Phoenix.Endpoint.Cowboy2Handler':exit_on_error/4 line 130 in 'Elixir.Phoenix.Endpoint.Cowboy2Handler':exit_on_error/4 line 130
2020-06-22 08:16:24.156 [error] <0.868.0> Cowboy stream 7 with ranch listener 'Elixir.GqlgatewayWeb.Endpoint.HTTP' and connection process <0.851.0> had its request process exit with reason: {{#{'__exception__' => true,'__struct__' => 'Elixir.Phoenix.Router.NoRouteError',conn => #{'__struct__' => 'Elixir.Plug.Conn',adapter => {'Elixir.Plug.Cowboy.Conn',#{bindings => #{},body_length => 0,cert => undefined,has_body => false,headers => #{<<"accept">> => <<"text/html,application/xhtml+xml,application/xml;q=0.9,image/webp,image/apng,*/*;q=0.8,application/signed-exchange;v=b3;q=0.9">>,<<"accept-encoding">> => <<"gzip, deflate, br">>,<<"accept-language">> => <<"en-US,en;q=0.9,pt-PT...">>,...},...}},...},...},...},...} in 'Elixir.Phoenix.Endpoint.Cowboy2Handler':exit_on_error/4 line 130
2020-06-22 08:16:39.666 [error] <0.869.0> CRASH REPORT Process <0.869.0> with 0 neighbours exited with reason: {{#{'__exception__' => true,'__struct__' => 'Elixir.Phoenix.Router.NoRouteError',conn => #{'__struct__' => 'Elixir.Plug.Conn',adapter => {'Elixir.Plug.Cowboy.Conn',#{bindings => #{},body_length => 0,cert => undefined,has_body => false,headers => #{<<"accept">> => <<"text/html,application/xhtml+xml,application/xml;q=0.9,image/webp,image/apng,*/*;q=0.8,application/signed-exchange;v=b3;q=0.9">>,<<"accept-encoding">> => <<"gzip, deflate, br">>,<<"accept-language">> => <<"en-US,en;q=0.9,pt-PT...">>,...},...}},...},...},...},...} in 'Elixir.Phoenix.Endpoint.Cowboy2Handler':exit_on_error/4 line 130 in 'Elixir.Phoenix.Endpoint.Cowboy2Handler':exit_on_error/4 line 130
2020-06-22 08:16:39.667 [error] <0.869.0> Cowboy stream 8 with ranch listener 'Elixir.GqlgatewayWeb.Endpoint.HTTP' and connection process <0.851.0> had its request process exit with reason: {{#{'__exception__' => true,'__struct__' => 'Elixir.Phoenix.Router.NoRouteError',conn => #{'__struct__' => 'Elixir.Plug.Conn',adapter => {'Elixir.Plug.Cowboy.Conn',#{bindings => #{},body_length => 0,cert => undefined,has_body => false,headers => #{<<"accept">> => <<"text/html,application/xhtml+xml,application/xml;q=0.9,image/webp,image/apng,*/*;q=0.8,application/signed-exchange;v=b3;q=0.9">>,<<"accept-encoding">> => <<"gzip, deflate, br">>,<<"accept-language">> => <<"en-US,en;q=0.9,pt-PT...">>,...},...}},...},...},...},...} in 'Elixir.Phoenix.Endpoint.Cowboy2Handler':exit_on_error/4 line 130
2020-06-22 08:16:44.634 [error] <0.870.0> CRASH REPORT Process <0.870.0> with 0 neighbours exited with reason: {{#{'__exception__' => true,'__struct__' => 'Elixir.Phoenix.Router.NoRouteError',conn => #{'__struct__' => 'Elixir.Plug.Conn',adapter => {'Elixir.Plug.Cowboy.Conn',#{bindings => #{},body_length => 0,cert => undefined,has_body => false,headers => #{<<"accept">> => <<"text/html,application/xhtml+xml,application/xml;q=0.9,image/webp,image/apng,*/*;q=0.8,application/signed-exchange;v=b3;q=0.9">>,<<"accept-encoding">> => <<"gzip, deflate, br">>,<<"accept-language">> => <<"en-US,en;q=0.9,pt-PT...">>,...},...}},...},...},...},...} in 'Elixir.Phoenix.Endpoint.Cowboy2Handler':exit_on_error/4 line 130 in 'Elixir.Phoenix.Endpoint.Cowboy2Handler':exit_on_error/4 line 130
2020-06-22 08:16:44.634 [error] <0.870.0> Cowboy stream 9 with ranch listener 'Elixir.GqlgatewayWeb.Endpoint.HTTP' and connection process <0.851.0> had its request process exit with reason: {{#{'__exception__' => true,'__struct__' => 'Elixir.Phoenix.Router.NoRouteError',conn => #{'__struct__' => 'Elixir.Plug.Conn',adapter => {'Elixir.Plug.Cowboy.Conn',#{bindings => #{},body_length => 0,cert => undefined,has_body => false,headers => #{<<"accept">> => <<"text/html,application/xhtml+xml,application/xml;q=0.9,image/webp,image/apng,*/*;q=0.8,application/signed-exchange;v=b3;q=0.9">>,<<"accept-encoding">> => <<"gzip, deflate, br">>,<<"accept-language">> => <<"en-US,en;q=0.9,pt-PT...">>,...},...}},...},...},...},...} in 'Elixir.Phoenix.Endpoint.Cowboy2Handler':exit_on_error/4 line 130
2020-06-22 08:17:10.373 [error] <0.854.0> CRASH REPORT Process <0.854.0> with 0 neighbours exited with reason: {{#{'__exception__' => true,'__struct__' => 'Elixir.Phoenix.Router.NoRouteError',conn => #{'__struct__' => 'Elixir.Plug.Conn',adapter => {'Elixir.Plug.Cowboy.Conn',#{bindings => #{},body_length => 0,cert => undefined,has_body => false,headers => #{<<"accept">> => <<"text/html,application/xhtml+xml,application/xml;q=0.9,image/webp,image/apng,*/*;q=0.8,application/signed-exchange;v=b3;q=0.9">>,<<"accept-encoding">> => <<"gzip, deflate, br">>,<<"accept-language">> => <<"en-US,en;q=0.9,pt-PT...">>,...},...}},...},...},...},...} in 'Elixir.Phoenix.Endpoint.Cowboy2Handler':exit_on_error/4 line 130 in 'Elixir.Phoenix.Endpoint.Cowboy2Handler':exit_on_error/4 line 130
2020-06-22 08:17:10.379 [error] <0.854.0> Cowboy stream 1 with ranch listener 'Elixir.GqlgatewayWeb.Endpoint.HTTP' and connection process <0.853.0> had its request process exit with reason: {{#{'__exception__' => true,'__struct__' => 'Elixir.Phoenix.Router.NoRouteError',conn => #{'__struct__' => 'Elixir.Plug.Conn',adapter => {'Elixir.Plug.Cowboy.Conn',#{bindings => #{},body_length => 0,cert => undefined,has_body => false,headers => #{<<"accept">> => <<"text/html,application/xhtml+xml,application/xml;q=0.9,image/webp,image/apng,*/*;q=0.8,application/signed-exchange;v=b3;q=0.9">>,<<"accept-encoding">> => <<"gzip, deflate, br">>,<<"accept-language">> => <<"en-US,en;q=0.9,pt-PT...">>,...},...}},...},...},...},...} in 'Elixir.Phoenix.Endpoint.Cowboy2Handler':exit_on_error/4 line 130
2020-06-22 08:30:52.348 [error] <0.1316.0> CRASH REPORT Process <0.1316.0> with 0 neighbours exited with reason: {{#{'__exception__' => true,'__struct__' => 'Elixir.Phoenix.Router.NoRouteError',conn => #{'__struct__' => 'Elixir.Plug.Conn',adapter => {'Elixir.Plug.Cowboy.Conn',#{bindings => #{},body_length => 0,cert => undefined,has_body => false,headers => #{<<"accept">> => <<"text/html,application/xhtml+xml,application/xml;q=0.9,image/webp,image/apng,*/*;q=0.8,application/signed-exchange;v=b3;q=0.9">>,<<"accept-encoding">> => <<"gzip, deflate, br">>,<<"accept-language">> => <<"en-US,en;q=0.9,pt-PT...">>,...},...}},...},...},...},...} in 'Elixir.Phoenix.Endpoint.Cowboy2Handler':exit_on_error/4 line 130 in 'Elixir.Phoenix.Endpoint.Cowboy2Handler':exit_on_error/4 line 130
2020-06-22 08:30:52.349 [error] <0.1316.0> Cowboy stream 4 with ranch listener 'Elixir.GqlgatewayWeb.Endpoint.HTTP' and connection process <0.1306.0> had its request process exit with reason: {{#{'__exception__' => true,'__struct__' => 'Elixir.Phoenix.Router.NoRouteError',conn => #{'__struct__' => 'Elixir.Plug.Conn',adapter => {'Elixir.Plug.Cowboy.Conn',#{bindings => #{},body_length => 0,cert => undefined,has_body => false,headers => #{<<"accept">> => <<"text/html,application/xhtml+xml,application/xml;q=0.9,image/webp,image/apng,*/*;q=0.8,application/signed-exchange;v=b3;q=0.9">>,<<"accept-encoding">> => <<"gzip, deflate, br">>,<<"accept-language">> => <<"en-US,en;q=0.9,pt-PT...">>,...},...}},...},...},...},...} in 'Elixir.Phoenix.Endpoint.Cowboy2Handler':exit_on_error/4 line 130
2020-06-22 08:31:51.022 [error] <0.1343.0> CRASH REPORT Process <0.1343.0> with 0 neighbours exited with reason: {{#{'__exception__' => true,'__struct__' => 'Elixir.Phoenix.Router.NoRouteError',conn => #{'__struct__' => 'Elixir.Plug.Conn',adapter => {'Elixir.Plug.Cowboy.Conn',#{bindings => #{},body_length => 0,cert => undefined,has_body => false,headers => #{<<"accept">> => <<"text/html,application/xhtml+xml,application/xml;q=0.9,image/webp,image/apng,*/*;q=0.8,application/signed-exchange;v=b3;q=0.9">>,<<"accept-encoding">> => <<"gzip, deflate, br">>,<<"accept-language">> => <<"en-US,en;q=0.9,pt-PT...">>,...},...}},...},...},...},...} in 'Elixir.Phoenix.Endpoint.Cowboy2Handler':exit_on_error/4 line 130 in 'Elixir.Phoenix.Endpoint.Cowboy2Handler':exit_on_error/4 line 130
2020-06-22 08:31:51.023 [error] <0.1343.0> Cowboy stream 20 with ranch listener 'Elixir.GqlgatewayWeb.Endpoint.HTTP' and connection process <0.1306.0> had its request process exit with reason: {{#{'__exception__' => true,'__struct__' => 'Elixir.Phoenix.Router.NoRouteError',conn => #{'__struct__' => 'Elixir.Plug.Conn',adapter => {'Elixir.Plug.Cowboy.Conn',#{bindings => #{},body_length => 0,cert => undefined,has_body => false,headers => #{<<"accept">> => <<"text/html,application/xhtml+xml,application/xml;q=0.9,image/webp,image/apng,*/*;q=0.8,application/signed-exchange;v=b3;q=0.9">>,<<"accept-encoding">> => <<"gzip, deflate, br">>,<<"accept-language">> => <<"en-US,en;q=0.9,pt-PT...">>,...},...}},...},...},...},...} in 'Elixir.Phoenix.Endpoint.Cowboy2Handler':exit_on_error/4 line 130
2020-06-22 17:21:53.072 [error] <0.866.0> CRASH REPORT Process <0.866.0> with 0 neighbours exited with reason: {{#{'__exception__' => true,'__struct__' => 'Elixir.Phoenix.Router.NoRouteError',conn => #{'__struct__' => 'Elixir.Plug.Conn',adapter => {'Elixir.Plug.Cowboy.Conn',#{bindings => #{},body_length => 0,cert => undefined,has_body => false,headers => #{<<"accept">> => <<"text/html,application/xhtml+xml,application/xml;q=0.9,image/webp,image/apng,*/*;q=0.8,application/signed-exchange;v=b3;q=0.9">>,<<"accept-encoding">> => <<"gzip, deflate, br">>,<<"accept-language">> => <<"en-US,en;q=0.9,pt-PT...">>,...},...}},...},...},...},...} in 'Elixir.Phoenix.Endpoint.Cowboy2Handler':exit_on_error/4 line 130 in 'Elixir.Phoenix.Endpoint.Cowboy2Handler':exit_on_error/4 line 130
2020-06-22 17:21:53.087 [error] <0.866.0> Cowboy stream 9 with ranch listener 'Elixir.GqlgatewayWeb.Endpoint.HTTP' and connection process <0.851.0> had its request process exit with reason: {{#{'__exception__' => true,'__struct__' => 'Elixir.Phoenix.Router.NoRouteError',conn => #{'__struct__' => 'Elixir.Plug.Conn',adapter => {'Elixir.Plug.Cowboy.Conn',#{bindings => #{},body_length => 0,cert => undefined,has_body => false,headers => #{<<"accept">> => <<"text/html,application/xhtml+xml,application/xml;q=0.9,image/webp,image/apng,*/*;q=0.8,application/signed-exchange;v=b3;q=0.9">>,<<"accept-encoding">> => <<"gzip, deflate, br">>,<<"accept-language">> => <<"en-US,en;q=0.9,pt-PT...">>,...},...}},...},...},...},...} in 'Elixir.Phoenix.Endpoint.Cowboy2Handler':exit_on_error/4 line 130
2020-06-22 17:22:00.796 [error] <0.869.0> CRASH REPORT Process <0.869.0> with 0 neighbours exited with reason: {{#{'__exception__' => true,'__struct__' => 'Elixir.Phoenix.Router.NoRouteError',conn => #{'__struct__' => 'Elixir.Plug.Conn',adapter => {'Elixir.Plug.Cowboy.Conn',#{bindings => #{},body_length => 0,cert => undefined,has_body => false,headers => #{<<"accept">> => <<"text/html,application/xhtml+xml,application/xml;q=0.9,image/webp,image/apng,*/*;q=0.8,application/signed-exchange;v=b3;q=0.9">>,<<"accept-encoding">> => <<"gzip, deflate, br">>,<<"accept-language">> => <<"en-US,en;q=0.9,pt-PT...">>,...},...}},...},...},...},...} in 'Elixir.Phoenix.Endpoint.Cowboy2Handler':exit_on_error/4 line 130 in 'Elixir.Phoenix.Endpoint.Cowboy2Handler':exit_on_error/4 line 130
2020-06-22 17:22:00.798 [error] <0.869.0> Cowboy stream 12 with ranch listener 'Elixir.GqlgatewayWeb.Endpoint.HTTP' and connection process <0.851.0> had its request process exit with reason: {{#{'__exception__' => true,'__struct__' => 'Elixir.Phoenix.Router.NoRouteError',conn => #{'__struct__' => 'Elixir.Plug.Conn',adapter => {'Elixir.Plug.Cowboy.Conn',#{bindings => #{},body_length => 0,cert => undefined,has_body => false,headers => #{<<"accept">> => <<"text/html,application/xhtml+xml,application/xml;q=0.9,image/webp,image/apng,*/*;q=0.8,application/signed-exchange;v=b3;q=0.9">>,<<"accept-encoding">> => <<"gzip, deflate, br">>,<<"accept-language">> => <<"en-US,en;q=0.9,pt-PT...">>,...},...}},...},...},...},...} in 'Elixir.Phoenix.Endpoint.Cowboy2Handler':exit_on_error/4 line 130
2020-06-22 17:54:59.273 [error] <0.1423.0> CRASH REPORT Process <0.1423.0> with 0 neighbours exited with reason: {{#{'__exception__' => true,'__struct__' => 'Elixir.Phoenix.Router.NoRouteError',conn => #{'__struct__' => 'Elixir.Plug.Conn',adapter => {'Elixir.Plug.Cowboy.Conn',#{bindings => #{},body_length => 0,cert => undefined,has_body => false,headers => #{<<"accept">> => <<"text/html,application/xhtml+xml,application/xml;q=0.9,image/webp,image/apng,*/*;q=0.8,application/signed-exchange;v=b3;q=0.9">>,<<"accept-encoding">> => <<"gzip, deflate, br">>,<<"accept-language">> => <<"en-US,en;q=0.9,pt-PT...">>,...},...}},...},...},...},...} in 'Elixir.Phoenix.Endpoint.Cowboy2Handler':exit_on_error/4 line 130 in 'Elixir.Phoenix.Endpoint.Cowboy2Handler':exit_on_error/4 line 130
2020-06-22 17:54:59.275 [error] <0.1423.0> Cowboy stream 10 with ranch listener 'Elixir.GqlgatewayWeb.Endpoint.HTTP' and connection process <0.1395.0> had its request process exit with reason: {{#{'__exception__' => true,'__struct__' => 'Elixir.Phoenix.Router.NoRouteError',conn => #{'__struct__' => 'Elixir.Plug.Conn',adapter => {'Elixir.Plug.Cowboy.Conn',#{bindings => #{},body_length => 0,cert => undefined,has_body => false,headers => #{<<"accept">> => <<"text/html,application/xhtml+xml,application/xml;q=0.9,image/webp,image/apng,*/*;q=0.8,application/signed-exchange;v=b3;q=0.9">>,<<"accept-encoding">> => <<"gzip, deflate, br">>,<<"accept-language">> => <<"en-US,en;q=0.9,pt-PT...">>,...},...}},...},...},...},...} in 'Elixir.Phoenix.Endpoint.Cowboy2Handler':exit_on_error/4 line 130
2020-06-22 18:52:01.195 [error] <0.871.0> CRASH REPORT Process <0.871.0> with 0 neighbours exited with reason: {{#{'__exception__' => true,'__struct__' => 'Elixir.Phoenix.Router.NoRouteError',conn => #{'__struct__' => 'Elixir.Plug.Conn',adapter => {'Elixir.Plug.Cowboy.Conn',#{bindings => #{},body_length => 0,cert => undefined,has_body => false,headers => #{<<"accept">> => <<"text/html,application/xhtml+xml,application/xml;q=0.9,image/webp,image/apng,*/*;q=0.8,application/signed-exchange;v=b3;q=0.9">>,<<"accept-encoding">> => <<"gzip, deflate, br">>,<<"accept-language">> => <<"en-US,en;q=0.9,pt-PT...">>,...},...}},...},...},...},...} in 'Elixir.Phoenix.Endpoint.Cowboy2Handler':exit_on_error/4 line 130 in 'Elixir.Phoenix.Endpoint.Cowboy2Handler':exit_on_error/4 line 130
2020-06-22 18:52:01.204 [error] <0.871.0> Cowboy stream 12 with ranch listener 'Elixir.GqlgatewayWeb.Endpoint.HTTP' and connection process <0.847.0> had its request process exit with reason: {{#{'__exception__' => true,'__struct__' => 'Elixir.Phoenix.Router.NoRouteError',conn => #{'__struct__' => 'Elixir.Plug.Conn',adapter => {'Elixir.Plug.Cowboy.Conn',#{bindings => #{},body_length => 0,cert => undefined,has_body => false,headers => #{<<"accept">> => <<"text/html,application/xhtml+xml,application/xml;q=0.9,image/webp,image/apng,*/*;q=0.8,application/signed-exchange;v=b3;q=0.9">>,<<"accept-encoding">> => <<"gzip, deflate, br">>,<<"accept-language">> => <<"en-US,en;q=0.9,pt-PT...">>,...},...}},...},...},...},...} in 'Elixir.Phoenix.Endpoint.Cowboy2Handler':exit_on_error/4 line 130
2020-06-22 18:52:05.104 [error] <0.872.0> CRASH REPORT Process <0.872.0> with 0 neighbours exited with reason: {{#{'__exception__' => true,'__struct__' => 'Elixir.Phoenix.Router.NoRouteError',conn => #{'__struct__' => 'Elixir.Plug.Conn',adapter => {'Elixir.Plug.Cowboy.Conn',#{bindings => #{},body_length => 0,cert => undefined,has_body => false,headers => #{<<"accept">> => <<"text/html,application/xhtml+xml,application/xml;q=0.9,image/webp,image/apng,*/*;q=0.8,application/signed-exchange;v=b3;q=0.9">>,<<"accept-encoding">> => <<"gzip, deflate, br">>,<<"accept-language">> => <<"en-US,en;q=0.9,pt-PT...">>,...},...}},...},...},...},...} in 'Elixir.Phoenix.Endpoint.Cowboy2Handler':exit_on_error/4 line 130 in 'Elixir.Phoenix.Endpoint.Cowboy2Handler':exit_on_error/4 line 130
2020-06-22 18:52:05.106 [error] <0.872.0> Cowboy stream 13 with ranch listener 'Elixir.GqlgatewayWeb.Endpoint.HTTP' and connection process <0.847.0> had its request process exit with reason: {{#{'__exception__' => true,'__struct__' => 'Elixir.Phoenix.Router.NoRouteError',conn => #{'__struct__' => 'Elixir.Plug.Conn',adapter => {'Elixir.Plug.Cowboy.Conn',#{bindings => #{},body_length => 0,cert => undefined,has_body => false,headers => #{<<"accept">> => <<"text/html,application/xhtml+xml,application/xml;q=0.9,image/webp,image/apng,*/*;q=0.8,application/signed-exchange;v=b3;q=0.9">>,<<"accept-encoding">> => <<"gzip, deflate, br">>,<<"accept-language">> => <<"en-US,en;q=0.9,pt-PT...">>,...},...}},...},...},...},...} in 'Elixir.Phoenix.Endpoint.Cowboy2Handler':exit_on_error/4 line 130
2020-06-23 00:07:24.335 [error] <0.920.0> CRASH REPORT Process <0.920.0> with 0 neighbours exited with reason: {{#{'__exception__' => true,'__struct__' => 'Elixir.Phoenix.Router.NoRouteError',conn => #{'__struct__' => 'Elixir.Plug.Conn',adapter => {'Elixir.Plug.Cowboy.Conn',#{bindings => #{},body_length => 0,cert => undefined,has_body => false,headers => #{<<"accept">> => <<"text/html,application/xhtml+xml,application/xml;q=0.9,image/webp,image/apng,*/*;q=0.8,application/signed-exchange;v=b3;q=0.9">>,<<"accept-encoding">> => <<"gzip, deflate, br">>,<<"accept-language">> => <<"en-US,en;q=0.9,pt-PT...">>,...},...}},...},...},...},...} in 'Elixir.Phoenix.Endpoint.Cowboy2Handler':exit_on_error/4 line 130 in 'Elixir.Phoenix.Endpoint.Cowboy2Handler':exit_on_error/4 line 130
2020-06-23 00:07:24.346 [error] <0.920.0> Cowboy stream 11 with ranch listener 'Elixir.GqlgatewayWeb.Endpoint.HTTP' and connection process <0.906.0> had its request process exit with reason: {{#{'__exception__' => true,'__struct__' => 'Elixir.Phoenix.Router.NoRouteError',conn => #{'__struct__' => 'Elixir.Plug.Conn',adapter => {'Elixir.Plug.Cowboy.Conn',#{bindings => #{},body_length => 0,cert => undefined,has_body => false,headers => #{<<"accept">> => <<"text/html,application/xhtml+xml,application/xml;q=0.9,image/webp,image/apng,*/*;q=0.8,application/signed-exchange;v=b3;q=0.9">>,<<"accept-encoding">> => <<"gzip, deflate, br">>,<<"accept-language">> => <<"en-US,en;q=0.9,pt-PT...">>,...},...}},...},...},...},...} in 'Elixir.Phoenix.Endpoint.Cowboy2Handler':exit_on_error/4 line 130
2020-06-23 00:11:30.458 [error] <0.1050.0> CRASH REPORT Process <0.1050.0> with 0 neighbours exited with reason: {{#{'__exception__' => true,'__struct__' => 'Elixir.Phoenix.Router.NoRouteError',conn => #{'__struct__' => 'Elixir.Plug.Conn',adapter => {'Elixir.Plug.Cowboy.Conn',#{bindings => #{},body_length => 0,cert => undefined,has_body => false,headers => #{<<"accept">> => <<"text/html,application/xhtml+xml,application/xml;q=0.9,image/webp,image/apng,*/*;q=0.8,application/signed-exchange;v=b3;q=0.9">>,<<"accept-encoding">> => <<"gzip, deflate, br">>,<<"accept-language">> => <<"en-US,en;q=0.9,pt-PT...">>,...},...}},...},...},...},...} in 'Elixir.Phoenix.Endpoint.Cowboy2Handler':exit_on_error/4 line 130 in 'Elixir.Phoenix.Endpoint.Cowboy2Handler':exit_on_error/4 line 130
2020-06-23 00:11:30.459 [error] <0.1050.0> Cowboy stream 61 with ranch listener 'Elixir.GqlgatewayWeb.Endpoint.HTTP' and connection process <0.906.0> had its request process exit with reason: {{#{'__exception__' => true,'__struct__' => 'Elixir.Phoenix.Router.NoRouteError',conn => #{'__struct__' => 'Elixir.Plug.Conn',adapter => {'Elixir.Plug.Cowboy.Conn',#{bindings => #{},body_length => 0,cert => undefined,has_body => false,headers => #{<<"accept">> => <<"text/html,application/xhtml+xml,application/xml;q=0.9,image/webp,image/apng,*/*;q=0.8,application/signed-exchange;v=b3;q=0.9">>,<<"accept-encoding">> => <<"gzip, deflate, br">>,<<"accept-language">> => <<"en-US,en;q=0.9,pt-PT...">>,...},...}},...},...},...},...} in 'Elixir.Phoenix.Endpoint.Cowboy2Handler':exit_on_error/4 line 130
2020-06-23 00:20:27.253 [error] <0.1090.0> CRASH REPORT Process <0.1090.0> with 0 neighbours exited with reason: {{#{'__exception__' => true,'__struct__' => 'Elixir.UndefinedFunctionError',arity => 1,function => init,message => nil,module => 'Elixir.GqlgatewayWeb.UserController',reason => nil},[{'Elixir.GqlgatewayWeb.UserController',init,[index],[]},{'Elixir.Phoenix.Router','__call__',2,[{file,"lib/phoenix/router.ex"},{line,352}]},{'Elixir.GqlgatewayWeb.Endpoint',plug_builder_call,2,[{file,"lib/gqlgateway_web/endpoint.ex"},{line,1}]},{'Elixir.GqlgatewayWeb.Endpoint','call (overridable 3)',2,[{file,"l..."},...]},...]},...} in 'Elixir.Phoenix.Endpoint.Cowboy2Handler':exit_on_error/4 line 130 in 'Elixir.Phoenix.Endpoint.Cowboy2Handler':exit_on_error/4 line 130
2020-06-23 00:20:27.255 [error] <0.1090.0> Cowboy stream 5 with ranch listener 'Elixir.GqlgatewayWeb.Endpoint.HTTP' and connection process <0.1077.0> had its request process exit with reason: {{#{'__exception__' => true,'__struct__' => 'Elixir.UndefinedFunctionError',arity => 1,function => init,message => nil,module => 'Elixir.GqlgatewayWeb.UserController',reason => nil},[{'Elixir.GqlgatewayWeb.UserController',init,[index],[]},{'Elixir.Phoenix.Router','__call__',2,[{file,"lib/phoenix/router.ex"},{line,352}]},{'Elixir.GqlgatewayWeb.Endpoint',plug_builder_call,2,[{file,"lib/gqlgateway_web/endpoint.ex"},{line,1}]},{'Elixir.GqlgatewayWeb.Endpoint','call (overridable 3)',2,[{file,"l..."},...]},...]},...} in 'Elixir.Phoenix.Endpoint.Cowboy2Handler':exit_on_error/4 line 130
2020-06-23 00:22:26.472 [error] <0.1132.0> CRASH REPORT Process <0.1132.0> with 0 neighbours exited with reason: {{#{'__exception__' => true,'__struct__' => 'Elixir.UndefinedFunctionError',arity => 1,function => init,message => nil,module => 'Elixir.GqlgatewayWeb.GqlgatewayWeb.Admin.UserController',reason => nil},[{'Elixir.GqlgatewayWeb.GqlgatewayWeb.Admin.UserController',init,[index],[]},{'Elixir.Phoenix.Router','__call__',2,[{file,"lib/phoenix/router.ex"},{line,352}]},{'Elixir.GqlgatewayWeb.Endpoint',plug_builder_call,2,[{file,"lib/gqlgateway_web/endpoint.ex"},{line,1}]},{'Elixir.GqlgatewayWeb.Endpoint',...},...]},...} in 'Elixir.Phoenix.Endpoint.Cowboy2Handler':exit_on_error/4 line 130 in 'Elixir.Phoenix.Endpoint.Cowboy2Handler':exit_on_error/4 line 130
2020-06-23 00:22:26.473 [error] <0.1132.0> Cowboy stream 1 with ranch listener 'Elixir.GqlgatewayWeb.Endpoint.HTTP' and connection process <0.1131.0> had its request process exit with reason: {{#{'__exception__' => true,'__struct__' => 'Elixir.UndefinedFunctionError',arity => 1,function => init,message => nil,module => 'Elixir.GqlgatewayWeb.GqlgatewayWeb.Admin.UserController',reason => nil},[{'Elixir.GqlgatewayWeb.GqlgatewayWeb.Admin.UserController',init,[index],[]},{'Elixir.Phoenix.Router','__call__',2,[{file,"lib/phoenix/router.ex"},{line,352}]},{'Elixir.GqlgatewayWeb.Endpoint',plug_builder_call,2,[{file,"lib/gqlgateway_web/endpoint.ex"},{line,1}]},{'Elixir.GqlgatewayWeb.Endpoint',...},...]},...} in 'Elixir.Phoenix.Endpoint.Cowboy2Handler':exit_on_error/4 line 130
2020-06-23 00:22:49.948 [error] <0.1171.0> CRASH REPORT Process <0.1171.0> with 0 neighbours exited with reason: {{#{'__exception__' => true,'__struct__' => 'Elixir.UndefinedFunctionError',arity => 3,function => admin_user_path,message => nil,module => 'Elixir.GqlgatewayWeb.Router.Helpers',reason => nil},[{'Elixir.GqlgatewayWeb.Router.Helpers',admin_user_path,[#{'__struct__' => 'Elixir.Plug.Conn',adapter => {'Elixir.Plug.Cowboy.Conn',#{bindings => #{},body_length => 0,cert => undefined,has_body => false,headers => #{<<"accept">> => <<"text/html,application/xhtml+xml,application/xml;q=0.9,image/webp...">>,...},...}},...},...],...},...]},...} in 'Elixir.Phoenix.Endpoint.Cowboy2Handler':exit_on_error/4 line 130 in 'Elixir.Phoenix.Endpoint.Cowboy2Handler':exit_on_error/4 line 130
2020-06-23 00:22:49.949 [error] <0.1171.0> Cowboy stream 2 with ranch listener 'Elixir.GqlgatewayWeb.Endpoint.HTTP' and connection process <0.1131.0> had its request process exit with reason: {{#{'__exception__' => true,'__struct__' => 'Elixir.UndefinedFunctionError',arity => 3,function => admin_user_path,message => nil,module => 'Elixir.GqlgatewayWeb.Router.Helpers',reason => nil},[{'Elixir.GqlgatewayWeb.Router.Helpers',admin_user_path,[#{'__struct__' => 'Elixir.Plug.Conn',adapter => {'Elixir.Plug.Cowboy.Conn',#{bindings => #{},body_length => 0,cert => undefined,has_body => false,headers => #{<<"accept">> => <<"text/html,application/xhtml+xml,application/xml;q=0.9,image/webp...">>,...},...}},...},...],...},...]},...} in 'Elixir.Phoenix.Endpoint.Cowboy2Handler':exit_on_error/4 line 130
2020-06-23 00:24:03.853 [error] <0.1202.0> CRASH REPORT Process <0.1202.0> with 0 neighbours exited with reason: {{#{'__exception__' => true,'__struct__' => 'Elixir.UndefinedFunctionError',arity => 2,function => show,message => nil,module => 'Elixir.GqlgatewayWeb.Admin.UserController',reason => nil},[{'Elixir.GqlgatewayWeb.Admin.UserController',show,[#{'__struct__' => 'Elixir.Plug.Conn',adapter => {'Elixir.Plug.Cowboy.Conn',#{bindings => #{},body_length => 0,cert => undefined,has_body => false,headers => #{<<"accept">> => <<"text/html,application/xhtml+xml,application/xml;q=0.9,image/webp,image/apn...">>,...},...}},...},...],...},...]},...} in 'Elixir.Phoenix.Endpoint.Cowboy2Handler':exit_on_error/4 line 130 in 'Elixir.Phoenix.Endpoint.Cowboy2Handler':exit_on_error/4 line 130
2020-06-23 00:24:03.854 [error] <0.1202.0> Cowboy stream 7 with ranch listener 'Elixir.GqlgatewayWeb.Endpoint.HTTP' and connection process <0.1194.0> had its request process exit with reason: {{#{'__exception__' => true,'__struct__' => 'Elixir.UndefinedFunctionError',arity => 2,function => show,message => nil,module => 'Elixir.GqlgatewayWeb.Admin.UserController',reason => nil},[{'Elixir.GqlgatewayWeb.Admin.UserController',show,[#{'__struct__' => 'Elixir.Plug.Conn',adapter => {'Elixir.Plug.Cowboy.Conn',#{bindings => #{},body_length => 0,cert => undefined,has_body => false,headers => #{<<"accept">> => <<"text/html,application/xhtml+xml,application/xml;q=0.9,image/webp,image/apn...">>,...},...}},...},...],...},...]},...} in 'Elixir.Phoenix.Endpoint.Cowboy2Handler':exit_on_error/4 line 130
2020-06-24 00:06:41.595 [error] <0.1118.0> CRASH REPORT Process <0.1118.0> with 0 neighbours exited with reason: {{#{'__exception__' => true,'__struct__' => 'Elixir.UndefinedFunctionError',arity => 2,function => render,message => nil,module => 'Elixir.Gqlgateway.UserView',reason => nil},[{'Elixir.Gqlgateway.UserView',render,[<<"index.html">>,#{flash => #{},live_action => nil,live_module => 'Elixir.GqlgatewayWeb.UserLive.Index',socket => #{'__struct__' => 'Elixir.Phoenix.LiveView.Socket',assigns => #{'__struct__' => 'Elixir.Phoenix.LiveView.Socket.AssignsNotInSocket'},changed => #{},'connected?' => false,...}}],...},...]},...} in 'Elixir.Phoenix.Endpoint.Cowboy2Handler':exit_on_error/4 line 130 in 'Elixir.Phoenix.Endpoint.Cowboy2Handler':exit_on_error/4 line 130
2020-06-24 00:06:41.617 [error] <0.1118.0> Cowboy stream 4 with ranch listener 'Elixir.GqlgatewayWeb.Endpoint.HTTP' and connection process <0.1109.0> had its request process exit with reason: {{#{'__exception__' => true,'__struct__' => 'Elixir.UndefinedFunctionError',arity => 2,function => render,message => nil,module => 'Elixir.Gqlgateway.UserView',reason => nil},[{'Elixir.Gqlgateway.UserView',render,[<<"index.html">>,#{flash => #{},live_action => nil,live_module => 'Elixir.GqlgatewayWeb.UserLive.Index',socket => #{'__struct__' => 'Elixir.Phoenix.LiveView.Socket',assigns => #{'__struct__' => 'Elixir.Phoenix.LiveView.Socket.AssignsNotInSocket'},changed => #{},'connected?' => false,...}}],...},...]},...} in 'Elixir.Phoenix.Endpoint.Cowboy2Handler':exit_on_error/4 line 130
2020-06-24 00:08:45.398 [error] <0.1151.0> CRASH REPORT Process <0.1151.0> with 0 neighbours exited with reason: {{#{'__exception__' => true,'__struct__' => 'Elixir.ArgumentError',message => <<"assign @users not available in eex template.\n\nPlease make sure all proper assigns have been set. If this\nis a child template, ensure assigns are given explicitly by\nthe parent template as they are not automatically forwarded.\n\nAvailable assigns: [:flash, :live_action, :live_module, :socket]\n">>},[{'Elixir.Phoenix.LiveView.Engine','fetch_assign!',2,[{file,"lib/phoenix_live_view/engine.ex"},{line,861}]},{'Elixir.GqlgatewayWeb.UserView',...},...]},...} in 'Elixir.Phoenix.Endpoint.Cowboy2Handler':exit_on_error/4 line 130 in 'Elixir.Phoenix.Endpoint.Cowboy2Handler':exit_on_error/4 line 130
2020-06-24 00:08:45.404 [error] <0.1151.0> Cowboy stream 1 with ranch listener 'Elixir.GqlgatewayWeb.Endpoint.HTTP' and connection process <0.1150.0> had its request process exit with reason: {{#{'__exception__' => true,'__struct__' => 'Elixir.ArgumentError',message => <<"assign @users not available in eex template.\n\nPlease make sure all proper assigns have been set. If this\nis a child template, ensure assigns are given explicitly by\nthe parent template as they are not automatically forwarded.\n\nAvailable assigns: [:flash, :live_action, :live_module, :socket]\n">>},[{'Elixir.Phoenix.LiveView.Engine','fetch_assign!',2,[{file,"lib/phoenix_live_view/engine.ex"},{line,861}]},{'Elixir.GqlgatewayWeb.UserView',...},...]},...} in 'Elixir.Phoenix.Endpoint.Cowboy2Handler':exit_on_error/4 line 130
2020-06-24 00:10:49.552 [error] <0.1178.0> CRASH REPORT Process <0.1178.0> with 0 neighbours exited with reason: {{#{'__exception__' => true,'__struct__' => 'Elixir.ArgumentError',message => <<"assign @users not available in eex template.\n\nPlease make sure all proper assigns have been set. If this\nis a child template, ensure assigns are given explicitly by\nthe parent template as they are not automatically forwarded.\n\nAvailable assigns: [:flash, :live_action, :live_module, :socket]\n">>},[{'Elixir.Phoenix.LiveView.Engine','fetch_assign!',2,[{file,"lib/phoenix_live_view/engine.ex"},{line,861}]},{'Elixir.GqlgatewayWeb.UserView',...},...]},...} in 'Elixir.Phoenix.Endpoint.Cowboy2Handler':exit_on_error/4 line 130 in 'Elixir.Phoenix.Endpoint.Cowboy2Handler':exit_on_error/4 line 130
2020-06-24 00:10:49.555 [error] <0.1178.0> Cowboy stream 1 with ranch listener 'Elixir.GqlgatewayWeb.Endpoint.HTTP' and connection process <0.1177.0> had its request process exit with reason: {{#{'__exception__' => true,'__struct__' => 'Elixir.ArgumentError',message => <<"assign @users not available in eex template.\n\nPlease make sure all proper assigns have been set. If this\nis a child template, ensure assigns are given explicitly by\nthe parent template as they are not automatically forwarded.\n\nAvailable assigns: [:flash, :live_action, :live_module, :socket]\n">>},[{'Elixir.Phoenix.LiveView.Engine','fetch_assign!',2,[{file,"lib/phoenix_live_view/engine.ex"},{line,861}]},{'Elixir.GqlgatewayWeb.UserView',...},...]},...} in 'Elixir.Phoenix.Endpoint.Cowboy2Handler':exit_on_error/4 line 130
2020-06-24 00:12:17.299 [error] <0.1181.0> CRASH REPORT Process <0.1181.0> with 0 neighbours exited with reason: {{#{'__exception__' => true,'__struct__' => 'Elixir.Phoenix.Router.NoRouteError',conn => #{'__struct__' => 'Elixir.Plug.Conn',adapter => {'Elixir.Plug.Cowboy.Conn',#{bindings => #{},body_length => 0,cert => undefined,has_body => false,headers => #{<<"accept">> => <<"text/html,application/xhtml+xml,application/xml;q=0.9,image/webp,image/apng,*/*;q=0.8,application/signed-exchange;v=b3;q=0.9">>,<<"accept-encoding">> => <<"gzip, deflate, br">>,<<"accept-language">> => <<"en-US,en;q=0.9,pt-PT...">>,...},...}},...},...},...},...} in 'Elixir.Phoenix.Endpoint.Cowboy2Handler':exit_on_error/4 line 130 in 'Elixir.Phoenix.Endpoint.Cowboy2Handler':exit_on_error/4 line 130
2020-06-24 00:12:17.300 [error] <0.1181.0> Cowboy stream 1 with ranch listener 'Elixir.GqlgatewayWeb.Endpoint.HTTP' and connection process <0.1180.0> had its request process exit with reason: {{#{'__exception__' => true,'__struct__' => 'Elixir.Phoenix.Router.NoRouteError',conn => #{'__struct__' => 'Elixir.Plug.Conn',adapter => {'Elixir.Plug.Cowboy.Conn',#{bindings => #{},body_length => 0,cert => undefined,has_body => false,headers => #{<<"accept">> => <<"text/html,application/xhtml+xml,application/xml;q=0.9,image/webp,image/apng,*/*;q=0.8,application/signed-exchange;v=b3;q=0.9">>,<<"accept-encoding">> => <<"gzip, deflate, br">>,<<"accept-language">> => <<"en-US,en;q=0.9,pt-PT...">>,...},...}},...},...},...},...} in 'Elixir.Phoenix.Endpoint.Cowboy2Handler':exit_on_error/4 line 130
2020-06-24 00:12:25.905 [error] <0.1182.0> CRASH REPORT Process <0.1182.0> with 0 neighbours exited with reason: {{#{'__exception__' => true,'__struct__' => 'Elixir.ArgumentError',message => <<"assign @users not available in eex template.\n\nPlease make sure all proper assigns have been set. If this\nis a child template, ensure assigns are given explicitly by\nthe parent template as they are not automatically forwarded.\n\nAvailable assigns: [:flash, :live_action, :live_module, :socket]\n">>},[{'Elixir.Phoenix.LiveView.Engine','fetch_assign!',2,[{file,"lib/phoenix_live_view/engine.ex"},{line,861}]},{'Elixir.GqlgatewayWeb.UserView',...},...]},...} in 'Elixir.Phoenix.Endpoint.Cowboy2Handler':exit_on_error/4 line 130 in 'Elixir.Phoenix.Endpoint.Cowboy2Handler':exit_on_error/4 line 130
2020-06-24 00:12:25.907 [error] <0.1182.0> Cowboy stream 2 with ranch listener 'Elixir.GqlgatewayWeb.Endpoint.HTTP' and connection process <0.1180.0> had its request process exit with reason: {{#{'__exception__' => true,'__struct__' => 'Elixir.ArgumentError',message => <<"assign @users not available in eex template.\n\nPlease make sure all proper assigns have been set. If this\nis a child template, ensure assigns are given explicitly by\nthe parent template as they are not automatically forwarded.\n\nAvailable assigns: [:flash, :live_action, :live_module, :socket]\n">>},[{'Elixir.Phoenix.LiveView.Engine','fetch_assign!',2,[{file,"lib/phoenix_live_view/engine.ex"},{line,861}]},{'Elixir.GqlgatewayWeb.UserView',...},...]},...} in 'Elixir.Phoenix.Endpoint.Cowboy2Handler':exit_on_error/4 line 130
2020-06-24 00:19:23.951 [error] <0.1379.0> CRASH REPORT Process <0.1379.0> with 0 neighbours exited with reason: {{#{'__exception__' => true,'__struct__' => 'Elixir.ArgumentError',message => <<"assign @users not available in eex template.\n\nPlease make sure all proper assigns have been set. If this\nis a child template, ensure assigns are given explicitly by\nthe parent template as they are not automatically forwarded.\n\nAvailable assigns: [:flash, :live_action, :live_module, :socket]\n">>},[{'Elixir.Phoenix.LiveView.Engine','fetch_assign!',2,[{file,"lib/phoenix_live_view/engine.ex"},{line,861}]},{'Elixir.GqlgatewayWeb.UserView',...},...]},...} in 'Elixir.Phoenix.Endpoint.Cowboy2Handler':exit_on_error/4 line 130 in 'Elixir.Phoenix.Endpoint.Cowboy2Handler':exit_on_error/4 line 130
2020-06-24 00:19:23.965 [error] <0.1379.0> Cowboy stream 1 with ranch listener 'Elixir.GqlgatewayWeb.Endpoint.HTTP' and connection process <0.1378.0> had its request process exit with reason: {{#{'__exception__' => true,'__struct__' => 'Elixir.ArgumentError',message => <<"assign @users not available in eex template.\n\nPlease make sure all proper assigns have been set. If this\nis a child template, ensure assigns are given explicitly by\nthe parent template as they are not automatically forwarded.\n\nAvailable assigns: [:flash, :live_action, :live_module, :socket]\n">>},[{'Elixir.Phoenix.LiveView.Engine','fetch_assign!',2,[{file,"lib/phoenix_live_view/engine.ex"},{line,861}]},{'Elixir.GqlgatewayWeb.UserView',...},...]},...} in 'Elixir.Phoenix.Endpoint.Cowboy2Handler':exit_on_error/4 line 130
2020-06-24 00:19:34.033 [error] <0.1386.0> CRASH REPORT Process <0.1386.0> with 0 neighbours exited with reason: {{#{'__exception__' => true,'__struct__' => 'Elixir.Phoenix.Router.NoRouteError',conn => #{'__struct__' => 'Elixir.Plug.Conn',adapter => {'Elixir.Plug.Cowboy.Conn',#{bindings => #{},body_length => 0,cert => undefined,has_body => false,headers => #{<<"accept">> => <<"text/html,application/xhtml+xml,application/xml;q=0.9,image/webp,image/apng,*/*;q=0.8,application/signed-exchange;v=b3;q=0.9">>,<<"accept-encoding">> => <<"gzip, deflate, br">>,<<"accept-language">> => <<"en-US,en;q=0.9,pt-PT...">>,...},...}},...},...},...},...} in 'Elixir.Phoenix.Endpoint.Cowboy2Handler':exit_on_error/4 line 130 in 'Elixir.Phoenix.Endpoint.Cowboy2Handler':exit_on_error/4 line 130
2020-06-24 00:19:34.036 [error] <0.1386.0> Cowboy stream 4 with ranch listener 'Elixir.GqlgatewayWeb.Endpoint.HTTP' and connection process <0.1378.0> had its request process exit with reason: {{#{'__exception__' => true,'__struct__' => 'Elixir.Phoenix.Router.NoRouteError',conn => #{'__struct__' => 'Elixir.Plug.Conn',adapter => {'Elixir.Plug.Cowboy.Conn',#{bindings => #{},body_length => 0,cert => undefined,has_body => false,headers => #{<<"accept">> => <<"text/html,application/xhtml+xml,application/xml;q=0.9,image/webp,image/apng,*/*;q=0.8,application/signed-exchange;v=b3;q=0.9">>,<<"accept-encoding">> => <<"gzip, deflate, br">>,<<"accept-language">> => <<"en-US,en;q=0.9,pt-PT...">>,...},...}},...},...},...},...} in 'Elixir.Phoenix.Endpoint.Cowboy2Handler':exit_on_error/4 line 130
2020-06-24 00:20:15.463 [error] <0.1388.0> CRASH REPORT Process <0.1388.0> with 0 neighbours exited with reason: {{#{'__exception__' => true,'__struct__' => 'Elixir.ArgumentError',message => <<"assign @users not available in eex template.\n\nPlease make sure all proper assigns have been set. If this\nis a child template, ensure assigns are given explicitly by\nthe parent template as they are not automatically forwarded.\n\nAvailable assigns: [:flash, :live_action, :live_module, :socket]\n">>},[{'Elixir.Phoenix.LiveView.Engine','fetch_assign!',2,[{file,"lib/phoenix_live_view/engine.ex"},{line,861}]},{'Elixir.GqlgatewayWeb.UserView',...},...]},...} in 'Elixir.Phoenix.Endpoint.Cowboy2Handler':exit_on_error/4 line 130 in 'Elixir.Phoenix.Endpoint.Cowboy2Handler':exit_on_error/4 line 130
2020-06-24 00:20:15.472 [error] <0.1388.0> Cowboy stream 5 with ranch listener 'Elixir.GqlgatewayWeb.Endpoint.HTTP' and connection process <0.1378.0> had its request process exit with reason: {{#{'__exception__' => true,'__struct__' => 'Elixir.ArgumentError',message => <<"assign @users not available in eex template.\n\nPlease make sure all proper assigns have been set. If this\nis a child template, ensure assigns are given explicitly by\nthe parent template as they are not automatically forwarded.\n\nAvailable assigns: [:flash, :live_action, :live_module, :socket]\n">>},[{'Elixir.Phoenix.LiveView.Engine','fetch_assign!',2,[{file,"lib/phoenix_live_view/engine.ex"},{line,861}]},{'Elixir.GqlgatewayWeb.UserView',...},...]},...} in 'Elixir.Phoenix.Endpoint.Cowboy2Handler':exit_on_error/4 line 130
2020-06-24 00:35:18.004 [error] <0.939.0> CRASH REPORT Process <0.939.0> with 0 neighbours exited with reason: {{#{'__exception__' => true,'__struct__' => 'Elixir.ArgumentError',message => <<"assign @users not available in eex template.\n\nPlease make sure all proper assigns have been set. If this\nis a child template, ensure assigns are given explicitly by\nthe parent template as they are not automatically forwarded.\n\nAvailable assigns: [:flash, :live_action, :live_module, :socket]\n">>},[{'Elixir.Phoenix.LiveView.Engine','fetch_assign!',2,[{file,"lib/phoenix_live_view/engine.ex"},{line,861}]},{'Elixir.GqlgatewayWeb.UserView',...},...]},...} in 'Elixir.Phoenix.Endpoint.Cowboy2Handler':exit_on_error/4 line 130 in 'Elixir.Phoenix.Endpoint.Cowboy2Handler':exit_on_error/4 line 130
2020-06-24 00:35:18.022 [error] <0.939.0> Cowboy stream 3 with ranch listener 'Elixir.GqlgatewayWeb.Endpoint.HTTP' and connection process <0.935.0> had its request process exit with reason: {{#{'__exception__' => true,'__struct__' => 'Elixir.ArgumentError',message => <<"assign @users not available in eex template.\n\nPlease make sure all proper assigns have been set. If this\nis a child template, ensure assigns are given explicitly by\nthe parent template as they are not automatically forwarded.\n\nAvailable assigns: [:flash, :live_action, :live_module, :socket]\n">>},[{'Elixir.Phoenix.LiveView.Engine','fetch_assign!',2,[{file,"lib/phoenix_live_view/engine.ex"},{line,861}]},{'Elixir.GqlgatewayWeb.UserView',...},...]},...} in 'Elixir.Phoenix.Endpoint.Cowboy2Handler':exit_on_error/4 line 130
2020-06-24 00:37:26.975 [error] <0.577.0> gen_server <0.577.0> terminated with reason: socket_closed_unexpectedly
2020-06-24 00:37:26.976 [error] <0.574.0> gen_server <0.574.0> terminated with reason: socket_closed_unexpectedly
2020-06-24 00:37:26.976 [error] <0.580.0> gen_server <0.580.0> terminated with reason: socket_closed_unexpectedly
2020-06-24 00:37:26.978 [error] <0.571.0> gen_server <0.571.0> terminated with reason: socket_closed_unexpectedly
2020-06-24 00:37:26.978 [error] <0.574.0> CRASH REPORT Process <0.574.0> with 0 neighbours exited with reason: socket_closed_unexpectedly in gen_server:handle_common_reply/8 line 751
2020-06-24 00:37:26.979 [error] <0.568.0> gen_server <0.568.0> terminated with reason: socket_closed_unexpectedly
2020-06-24 00:37:26.979 [error] <0.580.0> CRASH REPORT Process <0.580.0> with 0 neighbours exited with reason: socket_closed_unexpectedly in gen_server:handle_common_reply/8 line 751
2020-06-24 00:37:26.979 [error] <0.572.0> Supervisor {<0.572.0>,amqp_connection_sup} had child connection started with amqp_gen_connection:start_link(<0.573.0>, {amqp_params_network,<<"guest">>,{plaintext,<<"guest">>},<<"/">>,"localhost",5672,0,0,10,50000,none,...}) at <0.574.0> exit with reason socket_closed_unexpectedly in context child_terminated
2020-06-24 00:37:26.980 [error] <0.572.0> Supervisor {<0.572.0>,amqp_connection_sup} had child connection started with amqp_gen_connection:start_link(<0.573.0>, {amqp_params_network,<<"guest">>,{plaintext,<<"guest">>},<<"/">>,"localhost",5672,0,0,10,50000,none,...}) at <0.574.0> exit with reason reached_max_restart_intensity in context shutdown
2020-06-24 00:37:26.981 [error] <0.578.0> Supervisor {<0.578.0>,amqp_connection_sup} had child connection started with amqp_gen_connection:start_link(<0.579.0>, {amqp_params_network,<<"guest">>,{plaintext,<<"guest">>},<<"/">>,"localhost",5672,0,0,10,50000,none,...}) at <0.580.0> exit with reason socket_closed_unexpectedly in context child_terminated
2020-06-24 00:37:26.981 [error] <0.578.0> Supervisor {<0.578.0>,amqp_connection_sup} had child connection started with amqp_gen_connection:start_link(<0.579.0>, {amqp_params_network,<<"guest">>,{plaintext,<<"guest">>},<<"/">>,"localhost",5672,0,0,10,50000,none,...}) at <0.580.0> exit with reason reached_max_restart_intensity in context shutdown
2020-06-24 00:37:26.981 [error] <0.571.0> CRASH REPORT Process <0.571.0> with 0 neighbours exited with reason: socket_closed_unexpectedly in gen_server:handle_common_reply/8 line 751
2020-06-24 00:37:26.982 [error] <0.569.0> Supervisor {<0.569.0>,amqp_connection_sup} had child connection started with amqp_gen_connection:start_link(<0.570.0>, {amqp_params_network,<<"guest">>,{plaintext,<<"guest">>},<<"/">>,"localhost",5672,0,0,10,50000,none,...}) at <0.571.0> exit with reason socket_closed_unexpectedly in context child_terminated
2020-06-24 00:37:26.983 [error] <0.569.0> Supervisor {<0.569.0>,amqp_connection_sup} had child connection started with amqp_gen_connection:start_link(<0.570.0>, {amqp_params_network,<<"guest">>,{plaintext,<<"guest">>},<<"/">>,"localhost",5672,0,0,10,50000,none,...}) at <0.571.0> exit with reason reached_max_restart_intensity in context shutdown
2020-06-24 00:37:26.983 [error] <0.577.0> CRASH REPORT Process <0.577.0> with 0 neighbours exited with reason: socket_closed_unexpectedly in gen_server:handle_common_reply/8 line 751
2020-06-24 00:37:26.984 [error] <0.568.0> CRASH REPORT Process <0.568.0> with 0 neighbours exited with reason: socket_closed_unexpectedly in gen_server:handle_common_reply/8 line 751
2020-06-24 00:37:26.984 [error] <0.575.0> Supervisor {<0.575.0>,amqp_connection_sup} had child connection started with amqp_gen_connection:start_link(<0.576.0>, {amqp_params_network,<<"guest">>,{plaintext,<<"guest">>},<<"/">>,"localhost",5672,0,0,10,50000,none,...}) at <0.577.0> exit with reason socket_closed_unexpectedly in context child_terminated
2020-06-24 00:37:26.985 [error] <0.575.0> Supervisor {<0.575.0>,amqp_connection_sup} had child connection started with amqp_gen_connection:start_link(<0.576.0>, {amqp_params_network,<<"guest">>,{plaintext,<<"guest">>},<<"/">>,"localhost",5672,0,0,10,50000,none,...}) at <0.577.0> exit with reason reached_max_restart_intensity in context shutdown
2020-06-24 00:37:26.986 [error] <0.566.0> Supervisor {<0.566.0>,amqp_connection_sup} had child connection started with amqp_gen_connection:start_link(<0.567.0>, {amqp_params_network,<<"guest">>,{plaintext,<<"guest">>},<<"/">>,"localhost",5672,0,0,10,50000,none,...}) at <0.568.0> exit with reason socket_closed_unexpectedly in context child_terminated
2020-06-24 00:37:26.986 [error] <0.566.0> Supervisor {<0.566.0>,amqp_connection_sup} had child connection started with amqp_gen_connection:start_link(<0.567.0>, {amqp_params_network,<<"guest">>,{plaintext,<<"guest">>},<<"/">>,"localhost",5672,0,0,10,50000,none,...}) at <0.568.0> exit with reason reached_max_restart_intensity in context shutdown
2020-06-24 00:53:03.895 [error] <0.1091.0> CRASH REPORT Process <0.1091.0> with 0 neighbours exited with reason: {{#{'__exception__' => true,'__struct__' => 'Elixir.ArgumentError',message => <<"assign @users not available in eex template.\n\nPlease make sure all proper assigns have been set. If this\nis a child template, ensure assigns are given explicitly by\nthe parent template as they are not automatically forwarded.\n\nAvailable assigns: [:flash, :live_action, :live_module, :socket]\n">>},[{'Elixir.Phoenix.LiveView.Engine','fetch_assign!',2,[{file,"lib/phoenix_live_view/engine.ex"},{line,861}]},{'Elixir.GqlgatewayWeb.UserLive.Index',...},...]},...} in 'Elixir.Phoenix.Endpoint.Cowboy2Handler':exit_on_error/4 line 130 in 'Elixir.Phoenix.Endpoint.Cowboy2Handler':exit_on_error/4 line 130
2020-06-24 00:53:03.896 [error] <0.1091.0> Cowboy stream 2 with ranch listener 'Elixir.GqlgatewayWeb.Endpoint.HTTP' and connection process <0.1082.0> had its request process exit with reason: {{#{'__exception__' => true,'__struct__' => 'Elixir.ArgumentError',message => <<"assign @users not available in eex template.\n\nPlease make sure all proper assigns have been set. If this\nis a child template, ensure assigns are given explicitly by\nthe parent template as they are not automatically forwarded.\n\nAvailable assigns: [:flash, :live_action, :live_module, :socket]\n">>},[{'Elixir.Phoenix.LiveView.Engine','fetch_assign!',2,[{file,"lib/phoenix_live_view/engine.ex"},{line,861}]},{'Elixir.GqlgatewayWeb.UserLive.Index',...},...]},...} in 'Elixir.Phoenix.Endpoint.Cowboy2Handler':exit_on_error/4 line 130
2020-06-24 00:53:09.644 [error] <0.1092.0> CRASH REPORT Process <0.1092.0> with 0 neighbours exited with reason: {{#{'__exception__' => true,'__struct__' => 'Elixir.ArgumentError',message => <<"assign @users not available in eex template.\n\nPlease make sure all proper assigns have been set. If this\nis a child template, ensure assigns are given explicitly by\nthe parent template as they are not automatically forwarded.\n\nAvailable assigns: [:flash, :live_action, :live_module, :socket]\n">>},[{'Elixir.Phoenix.LiveView.Engine','fetch_assign!',2,[{file,"lib/phoenix_live_view/engine.ex"},{line,861}]},{'Elixir.GqlgatewayWeb.UserLive.Index',...},...]},...} in 'Elixir.Phoenix.Endpoint.Cowboy2Handler':exit_on_error/4 line 130 in 'Elixir.Phoenix.Endpoint.Cowboy2Handler':exit_on_error/4 line 130
2020-06-24 00:53:09.645 [error] <0.1092.0> Cowboy stream 3 with ranch listener 'Elixir.GqlgatewayWeb.Endpoint.HTTP' and connection process <0.1082.0> had its request process exit with reason: {{#{'__exception__' => true,'__struct__' => 'Elixir.ArgumentError',message => <<"assign @users not available in eex template.\n\nPlease make sure all proper assigns have been set. If this\nis a child template, ensure assigns are given explicitly by\nthe parent template as they are not automatically forwarded.\n\nAvailable assigns: [:flash, :live_action, :live_module, :socket]\n">>},[{'Elixir.Phoenix.LiveView.Engine','fetch_assign!',2,[{file,"lib/phoenix_live_view/engine.ex"},{line,861}]},{'Elixir.GqlgatewayWeb.UserLive.Index',...},...]},...} in 'Elixir.Phoenix.Endpoint.Cowboy2Handler':exit_on_error/4 line 130
2020-06-24 00:59:12.990 [error] <0.1101.0> CRASH REPORT Process <0.1101.0> with 0 neighbours exited with reason: {{#{'__exception__' => true,'__struct__' => 'Elixir.ArgumentError',message => <<"assign @users not available in eex template.\n\nPlease make sure all proper assigns have been set. If this\nis a child template, ensure assigns are given explicitly by\nthe parent template as they are not automatically forwarded.\n\nAvailable assigns: [:flash, :live_action, :live_module, :socket]\n">>},[{'Elixir.Phoenix.LiveView.Engine','fetch_assign!',2,[{file,"lib/phoenix_live_view/engine.ex"},{line,861}]},{'Elixir.GqlgatewayWeb.UserLive.Index',...},...]},...} in 'Elixir.Phoenix.Endpoint.Cowboy2Handler':exit_on_error/4 line 130 in 'Elixir.Phoenix.Endpoint.Cowboy2Handler':exit_on_error/4 line 130
2020-06-24 00:59:12.994 [error] <0.1101.0> Cowboy stream 1 with ranch listener 'Elixir.GqlgatewayWeb.Endpoint.HTTP' and connection process <0.1100.0> had its request process exit with reason: {{#{'__exception__' => true,'__struct__' => 'Elixir.ArgumentError',message => <<"assign @users not available in eex template.\n\nPlease make sure all proper assigns have been set. If this\nis a child template, ensure assigns are given explicitly by\nthe parent template as they are not automatically forwarded.\n\nAvailable assigns: [:flash, :live_action, :live_module, :socket]\n">>},[{'Elixir.Phoenix.LiveView.Engine','fetch_assign!',2,[{file,"lib/phoenix_live_view/engine.ex"},{line,861}]},{'Elixir.GqlgatewayWeb.UserLive.Index',...},...]},...} in 'Elixir.Phoenix.Endpoint.Cowboy2Handler':exit_on_error/4 line 130
2020-06-24 00:59:18.106 [error] <0.1102.0> CRASH REPORT Process <0.1102.0> with 0 neighbours exited with reason: {{#{'__exception__' => true,'__struct__' => 'Elixir.ArgumentError',message => <<"assign @users not available in eex template.\n\nPlease make sure all proper assigns have been set. If this\nis a child template, ensure assigns are given explicitly by\nthe parent template as they are not automatically forwarded.\n\nAvailable assigns: [:flash, :live_action, :live_module, :socket]\n">>},[{'Elixir.Phoenix.LiveView.Engine','fetch_assign!',2,[{file,"lib/phoenix_live_view/engine.ex"},{line,861}]},{'Elixir.GqlgatewayWeb.UserLive.Index',...},...]},...} in 'Elixir.Phoenix.Endpoint.Cowboy2Handler':exit_on_error/4 line 130 in 'Elixir.Phoenix.Endpoint.Cowboy2Handler':exit_on_error/4 line 130
2020-06-24 00:59:18.107 [error] <0.1102.0> Cowboy stream 2 with ranch listener 'Elixir.GqlgatewayWeb.Endpoint.HTTP' and connection process <0.1100.0> had its request process exit with reason: {{#{'__exception__' => true,'__struct__' => 'Elixir.ArgumentError',message => <<"assign @users not available in eex template.\n\nPlease make sure all proper assigns have been set. If this\nis a child template, ensure assigns are given explicitly by\nthe parent template as they are not automatically forwarded.\n\nAvailable assigns: [:flash, :live_action, :live_module, :socket]\n">>},[{'Elixir.Phoenix.LiveView.Engine','fetch_assign!',2,[{file,"lib/phoenix_live_view/engine.ex"},{line,861}]},{'Elixir.GqlgatewayWeb.UserLive.Index',...},...]},...} in 'Elixir.Phoenix.Endpoint.Cowboy2Handler':exit_on_error/4 line 130
2020-06-24 00:59:21.724 [error] <0.1103.0> CRASH REPORT Process <0.1103.0> with 0 neighbours exited with reason: {{#{'__exception__' => true,'__struct__' => 'Elixir.Phoenix.Router.NoRouteError',conn => #{'__struct__' => 'Elixir.Plug.Conn',adapter => {'Elixir.Plug.Cowboy.Conn',#{bindings => #{},body_length => 0,cert => undefined,has_body => false,headers => #{<<"accept">> => <<"text/html,application/xhtml+xml,application/xml;q=0.9,image/webp,image/apng,*/*;q=0.8,application/signed-exchange;v=b3;q=0.9">>,<<"accept-encoding">> => <<"gzip, deflate, br">>,<<"accept-language">> => <<"en-US,en;q=0.9,pt-PT...">>,...},...}},...},...},...},...} in 'Elixir.Phoenix.Endpoint.Cowboy2Handler':exit_on_error/4 line 130 in 'Elixir.Phoenix.Endpoint.Cowboy2Handler':exit_on_error/4 line 130
2020-06-24 00:59:21.726 [error] <0.1103.0> Cowboy stream 3 with ranch listener 'Elixir.GqlgatewayWeb.Endpoint.HTTP' and connection process <0.1100.0> had its request process exit with reason: {{#{'__exception__' => true,'__struct__' => 'Elixir.Phoenix.Router.NoRouteError',conn => #{'__struct__' => 'Elixir.Plug.Conn',adapter => {'Elixir.Plug.Cowboy.Conn',#{bindings => #{},body_length => 0,cert => undefined,has_body => false,headers => #{<<"accept">> => <<"text/html,application/xhtml+xml,application/xml;q=0.9,image/webp,image/apng,*/*;q=0.8,application/signed-exchange;v=b3;q=0.9">>,<<"accept-encoding">> => <<"gzip, deflate, br">>,<<"accept-language">> => <<"en-US,en;q=0.9,pt-PT...">>,...},...}},...},...},...},...} in 'Elixir.Phoenix.Endpoint.Cowboy2Handler':exit_on_error/4 line 130
2020-06-24 01:03:12.288 [error] <0.938.0> CRASH REPORT Process <0.938.0> with 0 neighbours exited with reason: {{#{'__exception__' => true,'__struct__' => 'Elixir.ArgumentError',message => <<"assign @users not available in eex template.\n\nPlease make sure all proper assigns have been set. If this\nis a child template, ensure assigns are given explicitly by\nthe parent template as they are not automatically forwarded.\n\nAvailable assigns: [:flash, :live_action, :live_module, :socket]\n">>},[{'Elixir.Phoenix.LiveView.Engine','fetch_assign!',2,[{file,"lib/phoenix_live_view/engine.ex"},{line,861}]},{'Elixir.GqlgatewayWeb.UserLive.Index',...},...]},...} in 'Elixir.Phoenix.Endpoint.Cowboy2Handler':exit_on_error/4 line 130 in 'Elixir.Phoenix.Endpoint.Cowboy2Handler':exit_on_error/4 line 130
2020-06-24 01:03:12.301 [error] <0.938.0> Cowboy stream 1 with ranch listener 'Elixir.GqlgatewayWeb.Endpoint.HTTP' and connection process <0.937.0> had its request process exit with reason: {{#{'__exception__' => true,'__struct__' => 'Elixir.ArgumentError',message => <<"assign @users not available in eex template.\n\nPlease make sure all proper assigns have been set. If this\nis a child template, ensure assigns are given explicitly by\nthe parent template as they are not automatically forwarded.\n\nAvailable assigns: [:flash, :live_action, :live_module, :socket]\n">>},[{'Elixir.Phoenix.LiveView.Engine','fetch_assign!',2,[{file,"lib/phoenix_live_view/engine.ex"},{line,861}]},{'Elixir.GqlgatewayWeb.UserLive.Index',...},...]},...} in 'Elixir.Phoenix.Endpoint.Cowboy2Handler':exit_on_error/4 line 130
2020-06-24 01:03:15.728 [error] <0.939.0> CRASH REPORT Process <0.939.0> with 0 neighbours exited with reason: {{#{'__exception__' => true,'__struct__' => 'Elixir.ArgumentError',message => <<"assign @users not available in eex template.\n\nPlease make sure all proper assigns have been set. If this\nis a child template, ensure assigns are given explicitly by\nthe parent template as they are not automatically forwarded.\n\nAvailable assigns: [:flash, :live_action, :live_module, :socket]\n">>},[{'Elixir.Phoenix.LiveView.Engine','fetch_assign!',2,[{file,"lib/phoenix_live_view/engine.ex"},{line,861}]},{'Elixir.GqlgatewayWeb.UserLive.Index',...},...]},...} in 'Elixir.Phoenix.Endpoint.Cowboy2Handler':exit_on_error/4 line 130 in 'Elixir.Phoenix.Endpoint.Cowboy2Handler':exit_on_error/4 line 130
2020-06-24 01:03:15.730 [error] <0.939.0> Cowboy stream 2 with ranch listener 'Elixir.GqlgatewayWeb.Endpoint.HTTP' and connection process <0.937.0> had its request process exit with reason: {{#{'__exception__' => true,'__struct__' => 'Elixir.ArgumentError',message => <<"assign @users not available in eex template.\n\nPlease make sure all proper assigns have been set. If this\nis a child template, ensure assigns are given explicitly by\nthe parent template as they are not automatically forwarded.\n\nAvailable assigns: [:flash, :live_action, :live_module, :socket]\n">>},[{'Elixir.Phoenix.LiveView.Engine','fetch_assign!',2,[{file,"lib/phoenix_live_view/engine.ex"},{line,861}]},{'Elixir.GqlgatewayWeb.UserLive.Index',...},...]},...} in 'Elixir.Phoenix.Endpoint.Cowboy2Handler':exit_on_error/4 line 130
