2020-05-03 21:48:04.562 [error] <0.432.0> gen_server <0.432.0> terminated with reason: {socket_error,timeout}
2020-05-03 21:48:04.562 [error] <0.460.0> gen_server <0.460.0> terminated with reason: {socket_error,timeout}
2020-05-03 21:48:04.562 [error] <0.463.0> gen_server <0.463.0> terminated with reason: {socket_error,timeout}
2020-05-03 21:48:04.562 [error] <0.428.0> gen_server <0.428.0> terminated with reason: {socket_error,timeout}
2020-05-03 21:48:04.563 [error] <0.462.0> gen_server <0.462.0> terminated with reason: {socket_error,timeout}
2020-05-03 21:48:04.563 [error] <0.461.0> gen_server <0.461.0> terminated with reason: {socket_error,timeout}
2020-05-03 21:48:04.563 [error] <0.435.0> gen_server <0.435.0> terminated with reason: {socket_error,timeout}
2020-05-03 21:48:04.563 [error] <0.459.0> gen_server <0.459.0> terminated with reason: {socket_error,timeout}
2020-05-03 21:48:04.564 [error] <0.438.0> gen_server <0.438.0> terminated with reason: {socket_error,timeout}
2020-05-03 21:48:04.564 [error] <0.441.0> gen_server <0.441.0> terminated with reason: {socket_error,timeout}
2020-05-03 21:48:04.566 [error] <0.432.0> CRASH REPORT Process <0.432.0> with 0 neighbours exited with reason: {socket_error,timeout} in gen_server:handle_common_reply/8 line 751
2020-05-03 21:48:04.566 [error] <0.438.0> CRASH REPORT Process <0.438.0> with 0 neighbours exited with reason: {socket_error,timeout} in gen_server:handle_common_reply/8 line 751
2020-05-03 21:48:04.567 [error] <0.435.0> CRASH REPORT Process <0.435.0> with 0 neighbours exited with reason: {socket_error,timeout} in gen_server:handle_common_reply/8 line 751
2020-05-03 21:48:04.567 [error] <0.428.0> CRASH REPORT Process <0.428.0> with 0 neighbours exited with reason: {socket_error,timeout} in gen_server:handle_common_reply/8 line 751
2020-05-03 21:48:04.568 [error] <0.430.0> Supervisor {<0.430.0>,amqp_connection_sup} had child connection started with amqp_gen_connection:start_link(<0.431.0>, {amqp_params_network,<<"guest">>,<<"WXbiYoxjNQsnjd4ZoauYGc4O3FX3KPAu9H7as3jStJB+pBMveI4Fv9O1ijDTm2...">>,...}) at <0.432.0> exit with reason {socket_error,timeout} in context child_terminated
2020-05-03 21:48:04.568 [error] <0.430.0> Supervisor {<0.430.0>,amqp_connection_sup} had child connection started with amqp_gen_connection:start_link(<0.431.0>, {amqp_params_network,<<"guest">>,<<"WXbiYoxjNQsnjd4ZoauYGc4O3FX3KPAu9H7as3jStJB+pBMveI4Fv9O1ijDTm2...">>,...}) at <0.432.0> exit with reason reached_max_restart_intensity in context shutdown
2020-05-03 21:48:04.569 [error] <0.433.0> Supervisor {<0.433.0>,amqp_connection_sup} had child connection started with amqp_gen_connection:start_link(<0.434.0>, {amqp_params_network,<<"guest">>,<<"3OX+VbgKjbZy34/i6XEVvcDvpEwHD4rioXGBSO8MN0s8x/e8iNRNdFtKlxTUTf...">>,...}) at <0.435.0> exit with reason {socket_error,timeout} in context child_terminated
2020-05-03 21:48:04.569 [error] <0.441.0> CRASH REPORT Process <0.441.0> with 0 neighbours exited with reason: {socket_error,timeout} in gen_server:handle_common_reply/8 line 751
2020-05-03 21:48:04.570 [error] <0.433.0> Supervisor {<0.433.0>,amqp_connection_sup} had child connection started with amqp_gen_connection:start_link(<0.434.0>, {amqp_params_network,<<"guest">>,<<"3OX+VbgKjbZy34/i6XEVvcDvpEwHD4rioXGBSO8MN0s8x/e8iNRNdFtKlxTUTf...">>,...}) at <0.435.0> exit with reason reached_max_restart_intensity in context shutdown
2020-05-03 21:48:04.571 [error] <0.439.0> Supervisor {<0.439.0>,amqp_connection_sup} had child connection started with amqp_gen_connection:start_link(<0.440.0>, {amqp_params_network,<<"guest">>,<<"ZdUFJn+7a+0IQsyBglUbFmQe0NdL3AlRKOCzj23LnjTikDmhLgzBc8roWL4i4i...">>,...}) at <0.441.0> exit with reason {socket_error,timeout} in context child_terminated
2020-05-03 21:48:04.571 [error] <0.424.0> Supervisor {<0.424.0>,amqp_connection_sup} had child connection started with amqp_gen_connection:start_link(<0.427.0>, {amqp_params_network,<<"guest">>,<<"Ws9MTE8zmFKDPlfYxxfl2rauC5tfVWUnJwS4GYXRQm7f9gVzO1UhAFH1nDgwPV...">>,...}) at <0.428.0> exit with reason {socket_error,timeout} in context child_terminated
2020-05-03 21:48:04.572 [error] <0.436.0> Supervisor {<0.436.0>,amqp_connection_sup} had child connection started with amqp_gen_connection:start_link(<0.437.0>, {amqp_params_network,<<"guest">>,<<"CSmf1buCokUep23isY48LLAL4c7sW1A1ksWhayvNATAejQKvyWJkVt6Unyr2lo...">>,...}) at <0.438.0> exit with reason {socket_error,timeout} in context child_terminated
2020-05-03 21:48:04.572 [error] <0.439.0> Supervisor {<0.439.0>,amqp_connection_sup} had child connection started with amqp_gen_connection:start_link(<0.440.0>, {amqp_params_network,<<"guest">>,<<"ZdUFJn+7a+0IQsyBglUbFmQe0NdL3AlRKOCzj23LnjTikDmhLgzBc8roWL4i4i...">>,...}) at <0.441.0> exit with reason reached_max_restart_intensity in context shutdown
2020-05-03 21:48:04.573 [error] <0.424.0> Supervisor {<0.424.0>,amqp_connection_sup} had child connection started with amqp_gen_connection:start_link(<0.427.0>, {amqp_params_network,<<"guest">>,<<"Ws9MTE8zmFKDPlfYxxfl2rauC5tfVWUnJwS4GYXRQm7f9gVzO1UhAFH1nDgwPV...">>,...}) at <0.428.0> exit with reason reached_max_restart_intensity in context shutdown
2020-05-03 21:48:04.574 [error] <0.436.0> Supervisor {<0.436.0>,amqp_connection_sup} had child connection started with amqp_gen_connection:start_link(<0.437.0>, {amqp_params_network,<<"guest">>,<<"CSmf1buCokUep23isY48LLAL4c7sW1A1ksWhayvNATAejQKvyWJkVt6Unyr2lo...">>,...}) at <0.438.0> exit with reason reached_max_restart_intensity in context shutdown
2020-05-03 22:51:01.424 [error] <0.586.0> gen_server <0.586.0> terminated with reason: {socket_error,timeout}
2020-05-03 22:51:01.424 [error] <0.589.0> gen_server <0.589.0> terminated with reason: {socket_error,timeout}
2020-05-03 22:51:01.424 [error] <0.585.0> gen_server <0.585.0> terminated with reason: {socket_error,timeout}
2020-05-03 22:51:01.424 [error] <0.560.0> gen_server <0.560.0> terminated with reason: {socket_error,timeout}
2020-05-03 22:51:01.425 [error] <0.587.0> gen_server <0.587.0> terminated with reason: {socket_error,timeout}
2020-05-03 22:51:01.425 [error] <0.589.0> CRASH REPORT Process <0.589.0> with 0 neighbours exited with reason: {socket_error,timeout} in gen_server:handle_common_reply/8 line 751
2020-05-03 22:51:01.425 [error] <0.588.0> gen_server <0.588.0> terminated with reason: {socket_error,timeout}
2020-05-03 22:51:01.426 [error] <0.586.0> CRASH REPORT Process <0.586.0> with 0 neighbours exited with reason: {socket_error,timeout} in gen_server:handle_common_reply/8 line 751
2020-05-03 22:51:01.426 [error] <0.585.0> CRASH REPORT Process <0.585.0> with 0 neighbours exited with reason: {socket_error,timeout} in gen_server:handle_common_reply/8 line 751
2020-05-03 22:51:01.426 [error] <0.566.0> gen_server <0.566.0> terminated with reason: socket_closed_unexpectedly
2020-05-03 22:51:01.427 [error] <0.562.0> Supervisor {<0.562.0>,amqp_connection_type_sup} had child main_reader started with amqp_main_reader:start_link(#Port<0.12>, <0.563.0>, <0.575.0>, {method,rabbit_framing_amqp_0_9_1}, <<"client 192.168.1.73:40325 -> 192.168.1.64:32771">>) at <0.586.0> exit with reason {socket_error,timeout} in context child_terminated
2020-05-03 22:51:01.427 [error] <0.587.0> CRASH REPORT Process <0.587.0> with 0 neighbours exited with reason: {socket_error,timeout} in gen_server:handle_common_reply/8 line 751
2020-05-03 22:51:01.427 [error] <0.563.0> gen_server <0.563.0> terminated with reason: {socket_error,timeout}
2020-05-03 22:51:01.428 [error] <0.562.0> Supervisor {<0.562.0>,amqp_connection_type_sup} had child main_reader started with amqp_main_reader:start_link(#Port<0.12>, <0.563.0>, <0.575.0>, {method,rabbit_framing_amqp_0_9_1}, <<"client 192.168.1.73:40325 -> 192.168.1.64:32771">>) at <0.586.0> exit with reason reached_max_restart_intensity in context shutdown
2020-05-03 22:51:01.429 [error] <0.557.0> gen_server <0.557.0> terminated with reason: {socket_error,timeout}
2020-05-03 22:51:01.430 [error] <0.559.0> Supervisor {<0.559.0>,amqp_connection_type_sup} had child main_reader started with amqp_main_reader:start_link(#Port<0.14>, <0.560.0>, <0.579.0>, {method,rabbit_framing_amqp_0_9_1}, <<"client 192.168.1.73:41503 -> 192.168.1.64:32771">>) at <0.589.0> exit with reason {socket_error,timeout} in context child_terminated
2020-05-03 22:51:01.430 [error] <0.588.0> CRASH REPORT Process <0.588.0> with 0 neighbours exited with reason: {socket_error,timeout} in gen_server:handle_common_reply/8 line 751
2020-05-03 22:51:01.430 [error] <0.559.0> Supervisor {<0.559.0>,amqp_connection_type_sup} had child main_reader started with amqp_main_reader:start_link(#Port<0.14>, <0.560.0>, <0.579.0>, {method,rabbit_framing_amqp_0_9_1}, <<"client 192.168.1.73:41503 -> 192.168.1.64:32771">>) at <0.589.0> exit with reason reached_max_restart_intensity in context shutdown
2020-05-03 22:51:01.431 [error] <0.565.0> Supervisor {<0.565.0>,amqp_connection_type_sup} had child main_reader started with amqp_main_reader:start_link(#Port<0.13>, <0.566.0>, <0.576.0>, {method,rabbit_framing_amqp_0_9_1}, <<"client 192.168.1.73:49675 -> 192.168.1.64:32771">>) at <0.587.0> exit with reason {socket_error,timeout} in context child_terminated
2020-05-03 22:51:01.432 [error] <0.565.0> Supervisor {<0.565.0>,amqp_connection_type_sup} had child main_reader started with amqp_main_reader:start_link(#Port<0.13>, <0.566.0>, <0.576.0>, {method,rabbit_framing_amqp_0_9_1}, <<"client 192.168.1.73:49675 -> 192.168.1.64:32771">>) at <0.587.0> exit with reason reached_max_restart_intensity in context shutdown
2020-05-03 22:51:01.432 [error] <0.556.0> Supervisor {<0.556.0>,amqp_connection_type_sup} had child main_reader started with amqp_main_reader:start_link(#Port<0.15>, <0.557.0>, <0.577.0>, {method,rabbit_framing_amqp_0_9_1}, <<"client 192.168.1.73:47097 -> 192.168.1.64:32771">>) at <0.588.0> exit with reason {socket_error,timeout} in context child_terminated
2020-05-03 22:51:01.433 [error] <0.556.0> Supervisor {<0.556.0>,amqp_connection_type_sup} had child main_reader started with amqp_main_reader:start_link(#Port<0.15>, <0.557.0>, <0.577.0>, {method,rabbit_framing_amqp_0_9_1}, <<"client 192.168.1.73:47097 -> 192.168.1.64:32771">>) at <0.588.0> exit with reason reached_max_restart_intensity in context shutdown
2020-05-03 22:51:01.434 [error] <0.569.0> gen_server <0.569.0> terminated with reason: {socket_error,timeout}
2020-05-03 22:51:01.435 [error] <0.568.0> Supervisor {<0.568.0>,amqp_connection_type_sup} had child main_reader started with amqp_main_reader:start_link(#Port<0.16>, <0.569.0>, <0.578.0>, {method,rabbit_framing_amqp_0_9_1}, <<"client 192.168.1.73:53547 -> 192.168.1.64:32771">>) at <0.585.0> exit with reason {socket_error,timeout} in context child_terminated
2020-05-03 22:51:01.435 [error] <0.568.0> Supervisor {<0.568.0>,amqp_connection_type_sup} had child main_reader started with amqp_main_reader:start_link(#Port<0.16>, <0.569.0>, <0.578.0>, {method,rabbit_framing_amqp_0_9_1}, <<"client 192.168.1.73:53547 -> 192.168.1.64:32771">>) at <0.585.0> exit with reason reached_max_restart_intensity in context shutdown
2020-05-03 22:51:01.436 [error] <0.566.0> CRASH REPORT Process <0.566.0> with 0 neighbours exited with reason: socket_closed_unexpectedly in gen_server:handle_common_reply/8 line 751
2020-05-03 22:51:01.436 [error] <0.560.0> CRASH REPORT Process <0.560.0> with 0 neighbours exited with reason: {socket_error,timeout} in gen_server:handle_common_reply/8 line 751
2020-05-03 22:51:01.437 [error] <0.564.0> Supervisor {<0.564.0>,amqp_connection_sup} had child connection started with amqp_gen_connection:start_link(<0.565.0>, {amqp_params_network,<<"guest">>,<<"9DHkNif3RAHUjblFV6yscTuHd7vNQ/1NbKAzCIqPHL0FmFVAf7FNRQn0Sah6nV...">>,...}) at <0.566.0> exit with reason socket_closed_unexpectedly in context child_terminated
2020-05-03 22:51:01.437 [error] <0.564.0> Supervisor {<0.564.0>,amqp_connection_sup} had child connection started with amqp_gen_connection:start_link(<0.565.0>, {amqp_params_network,<<"guest">>,<<"9DHkNif3RAHUjblFV6yscTuHd7vNQ/1NbKAzCIqPHL0FmFVAf7FNRQn0Sah6nV...">>,...}) at <0.566.0> exit with reason reached_max_restart_intensity in context shutdown
2020-05-03 22:51:01.438 [error] <0.558.0> Supervisor {<0.558.0>,amqp_connection_sup} had child connection started with amqp_gen_connection:start_link(<0.559.0>, {amqp_params_network,<<"guest">>,<<"E+KVjD/a67Gvw6LRyd7oLsN8kGxUE/z6hDshyxhf786+KrjHfW/i6KL0HS7LcX...">>,...}) at <0.560.0> exit with reason {socket_error,timeout} in context child_terminated
2020-05-03 22:51:01.438 [error] <0.557.0> CRASH REPORT Process <0.557.0> with 0 neighbours exited with reason: {socket_error,timeout} in gen_server:handle_common_reply/8 line 751
2020-05-03 22:51:01.439 [error] <0.558.0> Supervisor {<0.558.0>,amqp_connection_sup} had child connection started with amqp_gen_connection:start_link(<0.559.0>, {amqp_params_network,<<"guest">>,<<"E+KVjD/a67Gvw6LRyd7oLsN8kGxUE/z6hDshyxhf786+KrjHfW/i6KL0HS7LcX...">>,...}) at <0.560.0> exit with reason reached_max_restart_intensity in context shutdown
2020-05-03 22:51:01.439 [error] <0.555.0> Supervisor {<0.555.0>,amqp_connection_sup} had child connection started with amqp_gen_connection:start_link(<0.556.0>, {amqp_params_network,<<"guest">>,<<"8Gu9gjdGcHuHcp4aAQ+3lqxNXJNutGd5AUunbfH9Wr8/5X/99EFjpBSXTF3V+Q...">>,...}) at <0.557.0> exit with reason {socket_error,timeout} in context child_terminated
2020-05-03 22:51:01.440 [error] <0.555.0> Supervisor {<0.555.0>,amqp_connection_sup} had child connection started with amqp_gen_connection:start_link(<0.556.0>, {amqp_params_network,<<"guest">>,<<"8Gu9gjdGcHuHcp4aAQ+3lqxNXJNutGd5AUunbfH9Wr8/5X/99EFjpBSXTF3V+Q...">>,...}) at <0.557.0> exit with reason reached_max_restart_intensity in context shutdown
2020-05-03 22:51:01.440 [error] <0.563.0> CRASH REPORT Process <0.563.0> with 0 neighbours exited with reason: {socket_error,timeout} in gen_server:handle_common_reply/8 line 751
2020-05-03 22:51:01.440 [error] <0.569.0> CRASH REPORT Process <0.569.0> with 0 neighbours exited with reason: {socket_error,timeout} in gen_server:handle_common_reply/8 line 751
2020-05-03 22:51:01.441 [error] <0.561.0> Supervisor {<0.561.0>,amqp_connection_sup} had child connection started with amqp_gen_connection:start_link(<0.562.0>, {amqp_params_network,<<"guest">>,<<"LBpfNCbyP9bAQKYnXlWDHVXHM1cmc0TX6GzQQfD6FT3cNCDd8MS+BBUH9HbZMi...">>,...}) at <0.563.0> exit with reason {socket_error,timeout} in context child_terminated
2020-05-03 22:51:01.441 [error] <0.561.0> Supervisor {<0.561.0>,amqp_connection_sup} had child connection started with amqp_gen_connection:start_link(<0.562.0>, {amqp_params_network,<<"guest">>,<<"LBpfNCbyP9bAQKYnXlWDHVXHM1cmc0TX6GzQQfD6FT3cNCDd8MS+BBUH9HbZMi...">>,...}) at <0.563.0> exit with reason reached_max_restart_intensity in context shutdown
2020-05-03 22:51:01.442 [error] <0.567.0> Supervisor {<0.567.0>,amqp_connection_sup} had child connection started with amqp_gen_connection:start_link(<0.568.0>, {amqp_params_network,<<"guest">>,<<"Tvvo2DcezHo+NdTUtyFRdmFAipdYBLk/PNx/KNseMPn0X6FalysKDSJiDjJkih...">>,...}) at <0.569.0> exit with reason {socket_error,timeout} in context child_terminated
2020-05-03 22:51:01.442 [error] <0.567.0> Supervisor {<0.567.0>,amqp_connection_sup} had child connection started with amqp_gen_connection:start_link(<0.568.0>, {amqp_params_network,<<"guest">>,<<"Tvvo2DcezHo+NdTUtyFRdmFAipdYBLk/PNx/KNseMPn0X6FalysKDSJiDjJkih...">>,...}) at <0.569.0> exit with reason reached_max_restart_intensity in context shutdown
2020-05-05 22:07:20.466 [error] <0.488.0> gen_server <0.488.0> terminated with reason: socket_closed_unexpectedly
2020-05-05 22:07:20.482 [error] <0.488.0> CRASH REPORT Process <0.488.0> with 0 neighbours exited with reason: socket_closed_unexpectedly in gen_server:handle_common_reply/8 line 751
2020-05-05 22:07:20.483 [error] <0.486.0> Supervisor {<0.486.0>,amqp_connection_sup} had child connection started with amqp_gen_connection:start_link(<0.487.0>, {amqp_params_network,<<"guest">>,<<"pKnPEuoDauD8iwxVqtZHpdLvFF1VNH+vjHuXPZTlLseplkxOfE/1HZIb8EoObz...">>,...}) at <0.488.0> exit with reason socket_closed_unexpectedly in context child_terminated
2020-05-05 22:07:20.484 [error] <0.486.0> Supervisor {<0.486.0>,amqp_connection_sup} had child connection started with amqp_gen_connection:start_link(<0.487.0>, {amqp_params_network,<<"guest">>,<<"pKnPEuoDauD8iwxVqtZHpdLvFF1VNH+vjHuXPZTlLseplkxOfE/1HZIb8EoObz...">>,...}) at <0.488.0> exit with reason reached_max_restart_intensity in context shutdown
2020-05-05 22:07:20.490 [error] <0.491.0> gen_server <0.491.0> terminated with reason: socket_closed_unexpectedly
2020-05-05 22:07:20.490 [error] <0.494.0> gen_server <0.494.0> terminated with reason: socket_closed_unexpectedly
2020-05-05 22:07:20.490 [error] <0.494.0> CRASH REPORT Process <0.494.0> with 0 neighbours exited with reason: socket_closed_unexpectedly in gen_server:handle_common_reply/8 line 751
2020-05-05 22:07:20.491 [error] <0.492.0> Supervisor {<0.492.0>,amqp_connection_sup} had child connection started with amqp_gen_connection:start_link(<0.493.0>, {amqp_params_network,<<"guest">>,<<"0p0CKsVml1ZPfGuov9zn5KkEUbHYmuHTsqH+QpniRe51fGI+i/7iPxCpm/Keho...">>,...}) at <0.494.0> exit with reason socket_closed_unexpectedly in context child_terminated
2020-05-05 22:07:20.491 [error] <0.482.0> gen_server <0.482.0> terminated with reason: socket_closed_unexpectedly
2020-05-05 22:07:20.492 [error] <0.492.0> Supervisor {<0.492.0>,amqp_connection_sup} had child connection started with amqp_gen_connection:start_link(<0.493.0>, {amqp_params_network,<<"guest">>,<<"0p0CKsVml1ZPfGuov9zn5KkEUbHYmuHTsqH+QpniRe51fGI+i/7iPxCpm/Keho...">>,...}) at <0.494.0> exit with reason reached_max_restart_intensity in context shutdown
2020-05-05 22:07:20.492 [error] <0.485.0> gen_server <0.485.0> terminated with reason: socket_closed_unexpectedly
2020-05-05 22:07:20.492 [error] <0.491.0> CRASH REPORT Process <0.491.0> with 0 neighbours exited with reason: socket_closed_unexpectedly in gen_server:handle_common_reply/8 line 751
2020-05-05 22:07:20.493 [error] <0.489.0> Supervisor {<0.489.0>,amqp_connection_sup} had child connection started with amqp_gen_connection:start_link(<0.490.0>, {amqp_params_network,<<"guest">>,<<"8V8Bq9pcsFwECJc70gs32GFDtNMhwBINFZiX/R8I1BsSY+GJuwaQkxp90XGx2B...">>,...}) at <0.491.0> exit with reason socket_closed_unexpectedly in context child_terminated
2020-05-05 22:07:20.493 [error] <0.489.0> Supervisor {<0.489.0>,amqp_connection_sup} had child connection started with amqp_gen_connection:start_link(<0.490.0>, {amqp_params_network,<<"guest">>,<<"8V8Bq9pcsFwECJc70gs32GFDtNMhwBINFZiX/R8I1BsSY+GJuwaQkxp90XGx2B...">>,...}) at <0.491.0> exit with reason reached_max_restart_intensity in context shutdown
2020-05-05 22:07:20.494 [error] <0.482.0> CRASH REPORT Process <0.482.0> with 0 neighbours exited with reason: socket_closed_unexpectedly in gen_server:handle_common_reply/8 line 751
2020-05-05 22:07:20.494 [error] <0.477.0> Supervisor {<0.477.0>,amqp_connection_sup} had child connection started with amqp_gen_connection:start_link(<0.480.0>, {amqp_params_network,<<"guest">>,<<"kZ3jtHcJjW+S/gJKskCch0o0j//S4Srr5Z/98k2KXppNkrd8GwLjO7mQojHWNE...">>,...}) at <0.482.0> exit with reason socket_closed_unexpectedly in context child_terminated
2020-05-05 22:07:20.495 [error] <0.477.0> Supervisor {<0.477.0>,amqp_connection_sup} had child connection started with amqp_gen_connection:start_link(<0.480.0>, {amqp_params_network,<<"guest">>,<<"kZ3jtHcJjW+S/gJKskCch0o0j//S4Srr5Z/98k2KXppNkrd8GwLjO7mQojHWNE...">>,...}) at <0.482.0> exit with reason reached_max_restart_intensity in context shutdown
2020-05-05 22:07:20.495 [error] <0.485.0> CRASH REPORT Process <0.485.0> with 0 neighbours exited with reason: socket_closed_unexpectedly in gen_server:handle_common_reply/8 line 751
2020-05-05 22:07:20.496 [error] <0.483.0> Supervisor {<0.483.0>,amqp_connection_sup} had child connection started with amqp_gen_connection:start_link(<0.484.0>, {amqp_params_network,<<"guest">>,<<"hsrzaRrgwQpGY7wz78K4XpKktgSAodLHl8hN/2il2jxd/p6pMP1HlY06Wlz7BJ...">>,...}) at <0.485.0> exit with reason socket_closed_unexpectedly in context child_terminated
2020-05-05 22:07:20.496 [error] <0.483.0> Supervisor {<0.483.0>,amqp_connection_sup} had child connection started with amqp_gen_connection:start_link(<0.484.0>, {amqp_params_network,<<"guest">>,<<"hsrzaRrgwQpGY7wz78K4XpKktgSAodLHl8hN/2il2jxd/p6pMP1HlY06Wlz7BJ...">>,...}) at <0.485.0> exit with reason reached_max_restart_intensity in context shutdown
2020-05-12 22:50:46.261 [error] <0.8842.0> gen_server 'Elixir.FidelityRuleEngine.Consumer.Broadway.Producer_0' terminated with reason: #{'__exception__' => true,'__struct__' => 'Elixir.RuntimeError',message => <<"unexpected error when connecting to RabbitMQ broker">>} in 'Elixir.BroadwayRabbitMQ.Producer':handle_connection_failure/2 line 425
2020-05-12 22:50:46.261 [error] <0.8845.0> gen_server 'Elixir.FidelityRuleEngine.Consumer.Broadway.Producer_3' terminated with reason: #{'__exception__' => true,'__struct__' => 'Elixir.RuntimeError',message => <<"unexpected error when connecting to RabbitMQ broker">>} in 'Elixir.BroadwayRabbitMQ.Producer':handle_connection_failure/2 line 425
2020-05-12 22:50:46.262 [error] <0.8846.0> gen_server 'Elixir.FidelityRuleEngine.Consumer.Broadway.Producer_4' terminated with reason: #{'__exception__' => true,'__struct__' => 'Elixir.RuntimeError',message => <<"unexpected error when connecting to RabbitMQ broker">>} in 'Elixir.BroadwayRabbitMQ.Producer':handle_connection_failure/2 line 425
2020-05-12 22:50:46.262 [error] <0.8843.0> gen_server 'Elixir.FidelityRuleEngine.Consumer.Broadway.Producer_1' terminated with reason: #{'__exception__' => true,'__struct__' => 'Elixir.RuntimeError',message => <<"unexpected error when connecting to RabbitMQ broker">>} in 'Elixir.BroadwayRabbitMQ.Producer':handle_connection_failure/2 line 425
2020-05-12 22:50:46.262 [error] <0.8844.0> gen_server 'Elixir.FidelityRuleEngine.Consumer.Broadway.Producer_2' terminated with reason: #{'__exception__' => true,'__struct__' => 'Elixir.RuntimeError',message => <<"unexpected error when connecting to RabbitMQ broker">>} in 'Elixir.BroadwayRabbitMQ.Producer':handle_connection_failure/2 line 425
2020-05-12 22:50:46.262 [error] <0.8845.0> CRASH REPORT Process 'Elixir.FidelityRuleEngine.Consumer.Broadway.Producer_3' with 0 neighbours crashed with reason: #{'__exception__' => true,'__struct__' => 'Elixir.RuntimeError',message => <<"unexpected error when connecting to RabbitMQ broker">>} in 'Elixir.BroadwayRabbitMQ.Producer':handle_connection_failure/2 line 425
2020-05-12 22:50:46.263 [error] <0.8841.0> Supervisor 'Elixir.FidelityRuleEngine.Consumer.Broadway.ProducerSupervisor' had child 'Elixir.FidelityRuleEngine.Consumer.Broadway.Producer_3' started with 'Elixir.Broadway.Producer':start_link([{broadway,[{hibernate_after,15000},{batchers,[]},{context,context_not_set},{resubscribe_interval,...},...]},...], 3, [{name,'Elixir.FidelityRuleEngine.Consumer.Broadway.Producer_3'},{hibernate_after,15000}]) at <0.8845.0> exit with reason #{'__exception__' => true,'__struct__' => 'Elixir.RuntimeError',message => <<"unexpected error when connecting to RabbitMQ broker">>} in 'Elixir.BroadwayRabbitMQ.Producer':handle_connection_failure/2 line 425 in context child_terminated
2020-05-12 22:50:46.263 [error] <0.8844.0> CRASH REPORT Process 'Elixir.FidelityRuleEngine.Consumer.Broadway.Producer_2' with 0 neighbours crashed with reason: #{'__exception__' => true,'__struct__' => 'Elixir.RuntimeError',message => <<"unexpected error when connecting to RabbitMQ broker">>} in 'Elixir.BroadwayRabbitMQ.Producer':handle_connection_failure/2 line 425
2020-05-12 22:50:46.263 [error] <0.8843.0> CRASH REPORT Process 'Elixir.FidelityRuleEngine.Consumer.Broadway.Producer_1' with 0 neighbours crashed with reason: #{'__exception__' => true,'__struct__' => 'Elixir.RuntimeError',message => <<"unexpected error when connecting to RabbitMQ broker">>} in 'Elixir.BroadwayRabbitMQ.Producer':handle_connection_failure/2 line 425
2020-05-12 22:50:46.263 [error] <0.8846.0> CRASH REPORT Process 'Elixir.FidelityRuleEngine.Consumer.Broadway.Producer_4' with 0 neighbours crashed with reason: #{'__exception__' => true,'__struct__' => 'Elixir.RuntimeError',message => <<"unexpected error when connecting to RabbitMQ broker">>} in 'Elixir.BroadwayRabbitMQ.Producer':handle_connection_failure/2 line 425
2020-05-12 22:50:46.264 [error] <0.8841.0> Supervisor 'Elixir.FidelityRuleEngine.Consumer.Broadway.ProducerSupervisor' had child 'Elixir.FidelityRuleEngine.Consumer.Broadway.Producer_2' started with 'Elixir.Broadway.Producer':start_link([{broadway,[{hibernate_after,15000},{batchers,[]},{context,context_not_set},{resubscribe_interval,...},...]},...], 2, [{name,'Elixir.FidelityRuleEngine.Consumer.Broadway.Producer_2'},{hibernate_after,15000}]) at <0.8844.0> exit with reason #{'__exception__' => true,'__struct__' => 'Elixir.RuntimeError',message => <<"unexpected error when connecting to RabbitMQ broker">>} in 'Elixir.BroadwayRabbitMQ.Producer':handle_connection_failure/2 line 425 in context child_terminated
2020-05-12 22:50:46.265 [error] <0.8841.0> Supervisor 'Elixir.FidelityRuleEngine.Consumer.Broadway.ProducerSupervisor' had child 'Elixir.FidelityRuleEngine.Consumer.Broadway.Producer_1' started with 'Elixir.Broadway.Producer':start_link([{broadway,[{hibernate_after,15000},{batchers,[]},{context,context_not_set},{resubscribe_interval,...},...]},...], 1, [{name,'Elixir.FidelityRuleEngine.Consumer.Broadway.Producer_1'},{hibernate_after,15000}]) at <0.8843.0> exit with reason #{'__exception__' => true,'__struct__' => 'Elixir.RuntimeError',message => <<"unexpected error when connecting to RabbitMQ broker">>} in 'Elixir.BroadwayRabbitMQ.Producer':handle_connection_failure/2 line 425 in context child_terminated
2020-05-12 22:50:46.265 [error] <0.8841.0> Supervisor 'Elixir.FidelityRuleEngine.Consumer.Broadway.ProducerSupervisor' had child 'Elixir.FidelityRuleEngine.Consumer.Broadway.Producer_4' started with 'Elixir.Broadway.Producer':start_link([{broadway,[{hibernate_after,15000},{batchers,[]},{context,context_not_set},{resubscribe_interval,...},...]},...], 4, [{name,'Elixir.FidelityRuleEngine.Consumer.Broadway.Producer_4'},{hibernate_after,15000}]) at <0.8846.0> exit with reason #{'__exception__' => true,'__struct__' => 'Elixir.RuntimeError',message => <<"unexpected error when connecting to RabbitMQ broker">>} in 'Elixir.BroadwayRabbitMQ.Producer':handle_connection_failure/2 line 425 in context child_terminated
2020-05-12 22:50:46.266 [error] <0.8842.0> CRASH REPORT Process 'Elixir.FidelityRuleEngine.Consumer.Broadway.Producer_0' with 0 neighbours crashed with reason: #{'__exception__' => true,'__struct__' => 'Elixir.RuntimeError',message => <<"unexpected error when connecting to RabbitMQ broker">>} in 'Elixir.BroadwayRabbitMQ.Producer':handle_connection_failure/2 line 425
2020-05-12 22:50:46.266 [error] <0.8841.0> Supervisor 'Elixir.FidelityRuleEngine.Consumer.Broadway.ProducerSupervisor' had child 'Elixir.FidelityRuleEngine.Consumer.Broadway.Producer_0' started with 'Elixir.Broadway.Producer':start_link([{broadway,[{hibernate_after,15000},{batchers,[]},{context,context_not_set},{resubscribe_interval,...},...]},...], 0, [{name,'Elixir.FidelityRuleEngine.Consumer.Broadway.Producer_0'},{hibernate_after,15000}]) at <0.8842.0> exit with reason #{'__exception__' => true,'__struct__' => 'Elixir.RuntimeError',message => <<"unexpected error when connecting to RabbitMQ broker">>} in 'Elixir.BroadwayRabbitMQ.Producer':handle_connection_failure/2 line 425 in context child_terminated
2020-05-12 22:50:49.331 [error] <0.9031.0> gen_server 'Elixir.FidelityRuleEngine.Consumer.Broadway.Producer_2' terminated with reason: #{'__exception__' => true,'__struct__' => 'Elixir.RuntimeError',message => <<"unexpected error when connecting to RabbitMQ broker">>} in 'Elixir.BroadwayRabbitMQ.Producer':handle_connection_failure/2 line 425
2020-05-12 22:50:49.333 [error] <0.9030.0> gen_server 'Elixir.FidelityRuleEngine.Consumer.Broadway.Producer_3' terminated with reason: #{'__exception__' => true,'__struct__' => 'Elixir.RuntimeError',message => <<"unexpected error when connecting to RabbitMQ broker">>} in 'Elixir.BroadwayRabbitMQ.Producer':handle_connection_failure/2 line 425
2020-05-12 22:50:49.333 [error] <0.9032.0> gen_server 'Elixir.FidelityRuleEngine.Consumer.Broadway.Producer_1' terminated with reason: #{'__exception__' => true,'__struct__' => 'Elixir.RuntimeError',message => <<"unexpected error when connecting to RabbitMQ broker">>} in 'Elixir.BroadwayRabbitMQ.Producer':handle_connection_failure/2 line 425
2020-05-12 22:50:49.334 [error] <0.9033.0> gen_server 'Elixir.FidelityRuleEngine.Consumer.Broadway.Producer_4' terminated with reason: #{'__exception__' => true,'__struct__' => 'Elixir.RuntimeError',message => <<"unexpected error when connecting to RabbitMQ broker">>} in 'Elixir.BroadwayRabbitMQ.Producer':handle_connection_failure/2 line 425
2020-05-12 22:50:49.334 [error] <0.9034.0> gen_server 'Elixir.FidelityRuleEngine.Consumer.Broadway.Producer_0' terminated with reason: #{'__exception__' => true,'__struct__' => 'Elixir.RuntimeError',message => <<"unexpected error when connecting to RabbitMQ broker">>} in 'Elixir.BroadwayRabbitMQ.Producer':handle_connection_failure/2 line 425
2020-05-12 22:50:49.334 [error] <0.9033.0> CRASH REPORT Process 'Elixir.FidelityRuleEngine.Consumer.Broadway.Producer_4' with 0 neighbours crashed with reason: #{'__exception__' => true,'__struct__' => 'Elixir.RuntimeError',message => <<"unexpected error when connecting to RabbitMQ broker">>} in 'Elixir.BroadwayRabbitMQ.Producer':handle_connection_failure/2 line 425
2020-05-12 22:50:49.336 [error] <0.8841.0> Supervisor 'Elixir.FidelityRuleEngine.Consumer.Broadway.ProducerSupervisor' had child 'Elixir.FidelityRuleEngine.Consumer.Broadway.Producer_4' started with 'Elixir.Broadway.Producer':start_link([{broadway,[{hibernate_after,15000},{batchers,[]},{context,context_not_set},{resubscribe_interval,...},...]},...], 4, [{name,'Elixir.FidelityRuleEngine.Consumer.Broadway.Producer_4'},{hibernate_after,15000}]) at <0.9033.0> exit with reason #{'__exception__' => true,'__struct__' => 'Elixir.RuntimeError',message => <<"unexpected error when connecting to RabbitMQ broker">>} in 'Elixir.BroadwayRabbitMQ.Producer':handle_connection_failure/2 line 425 in context child_terminated
2020-05-12 22:50:49.336 [error] <0.9031.0> CRASH REPORT Process 'Elixir.FidelityRuleEngine.Consumer.Broadway.Producer_2' with 0 neighbours crashed with reason: #{'__exception__' => true,'__struct__' => 'Elixir.RuntimeError',message => <<"unexpected error when connecting to RabbitMQ broker">>} in 'Elixir.BroadwayRabbitMQ.Producer':handle_connection_failure/2 line 425
2020-05-12 22:50:49.337 [error] <0.8841.0> Supervisor 'Elixir.FidelityRuleEngine.Consumer.Broadway.ProducerSupervisor' had child 'Elixir.FidelityRuleEngine.Consumer.Broadway.Producer_2' started with 'Elixir.Broadway.Producer':start_link([{broadway,[{hibernate_after,15000},{batchers,[]},{context,context_not_set},{resubscribe_interval,...},...]},...], 2, [{name,'Elixir.FidelityRuleEngine.Consumer.Broadway.Producer_2'},{hibernate_after,15000}]) at <0.9031.0> exit with reason #{'__exception__' => true,'__struct__' => 'Elixir.RuntimeError',message => <<"unexpected error when connecting to RabbitMQ broker">>} in 'Elixir.BroadwayRabbitMQ.Producer':handle_connection_failure/2 line 425 in context child_terminated
2020-05-12 22:50:49.338 [error] <0.9030.0> CRASH REPORT Process 'Elixir.FidelityRuleEngine.Consumer.Broadway.Producer_3' with 0 neighbours crashed with reason: #{'__exception__' => true,'__struct__' => 'Elixir.RuntimeError',message => <<"unexpected error when connecting to RabbitMQ broker">>} in 'Elixir.BroadwayRabbitMQ.Producer':handle_connection_failure/2 line 425
2020-05-12 22:50:49.339 [error] <0.8841.0> Supervisor 'Elixir.FidelityRuleEngine.Consumer.Broadway.ProducerSupervisor' had child 'Elixir.FidelityRuleEngine.Consumer.Broadway.Producer_3' started with 'Elixir.Broadway.Producer':start_link([{broadway,[{hibernate_after,15000},{batchers,[]},{context,context_not_set},{resubscribe_interval,...},...]},...], 3, [{name,'Elixir.FidelityRuleEngine.Consumer.Broadway.Producer_3'},{hibernate_after,15000}]) at <0.9030.0> exit with reason #{'__exception__' => true,'__struct__' => 'Elixir.RuntimeError',message => <<"unexpected error when connecting to RabbitMQ broker">>} in 'Elixir.BroadwayRabbitMQ.Producer':handle_connection_failure/2 line 425 in context child_terminated
2020-05-12 22:50:49.340 [error] <0.9034.0> CRASH REPORT Process 'Elixir.FidelityRuleEngine.Consumer.Broadway.Producer_0' with 0 neighbours crashed with reason: #{'__exception__' => true,'__struct__' => 'Elixir.RuntimeError',message => <<"unexpected error when connecting to RabbitMQ broker">>} in 'Elixir.BroadwayRabbitMQ.Producer':handle_connection_failure/2 line 425
2020-05-12 22:50:49.340 [error] <0.9032.0> CRASH REPORT Process 'Elixir.FidelityRuleEngine.Consumer.Broadway.Producer_1' with 0 neighbours crashed with reason: #{'__exception__' => true,'__struct__' => 'Elixir.RuntimeError',message => <<"unexpected error when connecting to RabbitMQ broker">>} in 'Elixir.BroadwayRabbitMQ.Producer':handle_connection_failure/2 line 425
2020-05-12 22:50:49.341 [error] <0.8841.0> Supervisor 'Elixir.FidelityRuleEngine.Consumer.Broadway.ProducerSupervisor' had child 'Elixir.FidelityRuleEngine.Consumer.Broadway.Producer_0' started with 'Elixir.Broadway.Producer':start_link([{broadway,[{hibernate_after,15000},{batchers,[]},{context,context_not_set},{resubscribe_interval,...},...]},...], 0, [{name,'Elixir.FidelityRuleEngine.Consumer.Broadway.Producer_0'},{hibernate_after,15000}]) at <0.9034.0> exit with reason #{'__exception__' => true,'__struct__' => 'Elixir.RuntimeError',message => <<"unexpected error when connecting to RabbitMQ broker">>} in 'Elixir.BroadwayRabbitMQ.Producer':handle_connection_failure/2 line 425 in context child_terminated
2020-05-12 22:50:49.343 [error] <0.8841.0> Supervisor 'Elixir.FidelityRuleEngine.Consumer.Broadway.ProducerSupervisor' had child 'Elixir.FidelityRuleEngine.Consumer.Broadway.Producer_1' started with 'Elixir.Broadway.Producer':start_link([{broadway,[{hibernate_after,15000},{batchers,[]},{context,context_not_set},{resubscribe_interval,...},...]},...], 1, [{name,'Elixir.FidelityRuleEngine.Consumer.Broadway.Producer_1'},{hibernate_after,15000}]) at <0.9032.0> exit with reason #{'__exception__' => true,'__struct__' => 'Elixir.RuntimeError',message => <<"unexpected error when connecting to RabbitMQ broker">>} in 'Elixir.BroadwayRabbitMQ.Producer':handle_connection_failure/2 line 425 in context child_terminated
2020-05-12 22:50:52.397 [error] <0.9050.0> gen_server 'Elixir.FidelityRuleEngine.Consumer.Broadway.Producer_4' terminated with reason: #{'__exception__' => true,'__struct__' => 'Elixir.RuntimeError',message => <<"unexpected error when connecting to RabbitMQ broker">>} in 'Elixir.BroadwayRabbitMQ.Producer':handle_connection_failure/2 line 425
2020-05-12 22:50:52.398 [error] <0.9054.0> gen_server 'Elixir.FidelityRuleEngine.Consumer.Broadway.Producer_1' terminated with reason: #{'__exception__' => true,'__struct__' => 'Elixir.RuntimeError',message => <<"unexpected error when connecting to RabbitMQ broker">>} in 'Elixir.BroadwayRabbitMQ.Producer':handle_connection_failure/2 line 425
2020-05-12 22:50:52.399 [error] <0.9052.0> gen_server 'Elixir.FidelityRuleEngine.Consumer.Broadway.Producer_3' terminated with reason: #{'__exception__' => true,'__struct__' => 'Elixir.RuntimeError',message => <<"unexpected error when connecting to RabbitMQ broker">>} in 'Elixir.BroadwayRabbitMQ.Producer':handle_connection_failure/2 line 425
2020-05-12 22:50:52.399 [error] <0.9053.0> gen_server 'Elixir.FidelityRuleEngine.Consumer.Broadway.Producer_0' terminated with reason: #{'__exception__' => true,'__struct__' => 'Elixir.RuntimeError',message => <<"unexpected error when connecting to RabbitMQ broker">>} in 'Elixir.BroadwayRabbitMQ.Producer':handle_connection_failure/2 line 425
2020-05-12 22:50:52.400 [error] <0.9051.0> gen_server 'Elixir.FidelityRuleEngine.Consumer.Broadway.Producer_2' terminated with reason: #{'__exception__' => true,'__struct__' => 'Elixir.RuntimeError',message => <<"unexpected error when connecting to RabbitMQ broker">>} in 'Elixir.BroadwayRabbitMQ.Producer':handle_connection_failure/2 line 425
2020-05-12 22:50:52.401 [error] <0.9050.0> CRASH REPORT Process 'Elixir.FidelityRuleEngine.Consumer.Broadway.Producer_4' with 0 neighbours crashed with reason: #{'__exception__' => true,'__struct__' => 'Elixir.RuntimeError',message => <<"unexpected error when connecting to RabbitMQ broker">>} in 'Elixir.BroadwayRabbitMQ.Producer':handle_connection_failure/2 line 425
2020-05-12 22:50:52.402 [error] <0.8841.0> Supervisor 'Elixir.FidelityRuleEngine.Consumer.Broadway.ProducerSupervisor' had child 'Elixir.FidelityRuleEngine.Consumer.Broadway.Producer_4' started with 'Elixir.Broadway.Producer':start_link([{broadway,[{hibernate_after,15000},{batchers,[]},{context,context_not_set},{resubscribe_interval,...},...]},...], 4, [{name,'Elixir.FidelityRuleEngine.Consumer.Broadway.Producer_4'},{hibernate_after,15000}]) at <0.9050.0> exit with reason #{'__exception__' => true,'__struct__' => 'Elixir.RuntimeError',message => <<"unexpected error when connecting to RabbitMQ broker">>} in 'Elixir.BroadwayRabbitMQ.Producer':handle_connection_failure/2 line 425 in context child_terminated
2020-05-12 22:50:52.403 [error] <0.9051.0> CRASH REPORT Process 'Elixir.FidelityRuleEngine.Consumer.Broadway.Producer_2' with 0 neighbours crashed with reason: #{'__exception__' => true,'__struct__' => 'Elixir.RuntimeError',message => <<"unexpected error when connecting to RabbitMQ broker">>} in 'Elixir.BroadwayRabbitMQ.Producer':handle_connection_failure/2 line 425
2020-05-12 22:50:52.403 [error] <0.9052.0> CRASH REPORT Process 'Elixir.FidelityRuleEngine.Consumer.Broadway.Producer_3' with 0 neighbours crashed with reason: #{'__exception__' => true,'__struct__' => 'Elixir.RuntimeError',message => <<"unexpected error when connecting to RabbitMQ broker">>} in 'Elixir.BroadwayRabbitMQ.Producer':handle_connection_failure/2 line 425
2020-05-12 22:50:52.404 [error] <0.9054.0> CRASH REPORT Process 'Elixir.FidelityRuleEngine.Consumer.Broadway.Producer_1' with 0 neighbours crashed with reason: #{'__exception__' => true,'__struct__' => 'Elixir.RuntimeError',message => <<"unexpected error when connecting to RabbitMQ broker">>} in 'Elixir.BroadwayRabbitMQ.Producer':handle_connection_failure/2 line 425
2020-05-12 22:50:52.405 [error] <0.8841.0> Supervisor 'Elixir.FidelityRuleEngine.Consumer.Broadway.ProducerSupervisor' had child 'Elixir.FidelityRuleEngine.Consumer.Broadway.Producer_2' started with 'Elixir.Broadway.Producer':start_link([{broadway,[{hibernate_after,15000},{batchers,[]},{context,context_not_set},{resubscribe_interval,...},...]},...], 2, [{name,'Elixir.FidelityRuleEngine.Consumer.Broadway.Producer_2'},{hibernate_after,15000}]) at <0.9051.0> exit with reason #{'__exception__' => true,'__struct__' => 'Elixir.RuntimeError',message => <<"unexpected error when connecting to RabbitMQ broker">>} in 'Elixir.BroadwayRabbitMQ.Producer':handle_connection_failure/2 line 425 in context child_terminated
2020-05-12 22:50:52.405 [error] <0.9053.0> CRASH REPORT Process 'Elixir.FidelityRuleEngine.Consumer.Broadway.Producer_0' with 0 neighbours crashed with reason: #{'__exception__' => true,'__struct__' => 'Elixir.RuntimeError',message => <<"unexpected error when connecting to RabbitMQ broker">>} in 'Elixir.BroadwayRabbitMQ.Producer':handle_connection_failure/2 line 425
2020-05-12 22:50:52.407 [error] <0.8841.0> Supervisor 'Elixir.FidelityRuleEngine.Consumer.Broadway.ProducerSupervisor' had child 'Elixir.FidelityRuleEngine.Consumer.Broadway.Producer_3' started with 'Elixir.Broadway.Producer':start_link([{broadway,[{hibernate_after,15000},{batchers,[]},{context,context_not_set},{resubscribe_interval,...},...]},...], 3, [{name,'Elixir.FidelityRuleEngine.Consumer.Broadway.Producer_3'},{hibernate_after,15000}]) at <0.9052.0> exit with reason #{'__exception__' => true,'__struct__' => 'Elixir.RuntimeError',message => <<"unexpected error when connecting to RabbitMQ broker">>} in 'Elixir.BroadwayRabbitMQ.Producer':handle_connection_failure/2 line 425 in context child_terminated
2020-05-12 22:50:52.408 [error] <0.8841.0> Supervisor 'Elixir.FidelityRuleEngine.Consumer.Broadway.ProducerSupervisor' had child 'Elixir.FidelityRuleEngine.Consumer.Broadway.Producer_1' started with 'Elixir.Broadway.Producer':start_link([{broadway,[{hibernate_after,15000},{batchers,[]},{context,context_not_set},{resubscribe_interval,...},...]},...], 1, [{name,'Elixir.FidelityRuleEngine.Consumer.Broadway.Producer_1'},{hibernate_after,15000}]) at <0.9054.0> exit with reason #{'__exception__' => true,'__struct__' => 'Elixir.RuntimeError',message => <<"unexpected error when connecting to RabbitMQ broker">>} in 'Elixir.BroadwayRabbitMQ.Producer':handle_connection_failure/2 line 425 in context child_terminated
2020-05-12 22:50:52.409 [error] <0.8841.0> Supervisor 'Elixir.FidelityRuleEngine.Consumer.Broadway.ProducerSupervisor' had child 'Elixir.FidelityRuleEngine.Consumer.Broadway.Producer_0' started with 'Elixir.Broadway.Producer':start_link([{broadway,[{hibernate_after,15000},{batchers,[]},{context,context_not_set},{resubscribe_interval,...},...]},...], 0, [{name,'Elixir.FidelityRuleEngine.Consumer.Broadway.Producer_0'},{hibernate_after,15000}]) at <0.9053.0> exit with reason #{'__exception__' => true,'__struct__' => 'Elixir.RuntimeError',message => <<"unexpected error when connecting to RabbitMQ broker">>} in 'Elixir.BroadwayRabbitMQ.Producer':handle_connection_failure/2 line 425 in context child_terminated
2020-05-12 22:50:55.472 [error] <0.9073.0> gen_server 'Elixir.FidelityRuleEngine.Consumer.Broadway.Producer_1' terminated with reason: #{'__exception__' => true,'__struct__' => 'Elixir.RuntimeError',message => <<"unexpected error when connecting to RabbitMQ broker">>} in 'Elixir.BroadwayRabbitMQ.Producer':handle_connection_failure/2 line 425
2020-05-12 22:50:55.473 [error] <0.9070.0> gen_server 'Elixir.FidelityRuleEngine.Consumer.Broadway.Producer_4' terminated with reason: #{'__exception__' => true,'__struct__' => 'Elixir.RuntimeError',message => <<"unexpected error when connecting to RabbitMQ broker">>} in 'Elixir.BroadwayRabbitMQ.Producer':handle_connection_failure/2 line 425
2020-05-12 22:50:55.474 [error] <0.9071.0> gen_server 'Elixir.FidelityRuleEngine.Consumer.Broadway.Producer_2' terminated with reason: #{'__exception__' => true,'__struct__' => 'Elixir.RuntimeError',message => <<"unexpected error when connecting to RabbitMQ broker">>} in 'Elixir.BroadwayRabbitMQ.Producer':handle_connection_failure/2 line 425
2020-05-12 22:50:55.474 [error] <0.9072.0> gen_server 'Elixir.FidelityRuleEngine.Consumer.Broadway.Producer_3' terminated with reason: #{'__exception__' => true,'__struct__' => 'Elixir.RuntimeError',message => <<"unexpected error when connecting to RabbitMQ broker">>} in 'Elixir.BroadwayRabbitMQ.Producer':handle_connection_failure/2 line 425
2020-05-12 22:50:55.475 [error] <0.9074.0> gen_server 'Elixir.FidelityRuleEngine.Consumer.Broadway.Producer_0' terminated with reason: #{'__exception__' => true,'__struct__' => 'Elixir.RuntimeError',message => <<"unexpected error when connecting to RabbitMQ broker">>} in 'Elixir.BroadwayRabbitMQ.Producer':handle_connection_failure/2 line 425
2020-05-12 22:50:55.475 [error] <0.9072.0> CRASH REPORT Process 'Elixir.FidelityRuleEngine.Consumer.Broadway.Producer_3' with 0 neighbours crashed with reason: #{'__exception__' => true,'__struct__' => 'Elixir.RuntimeError',message => <<"unexpected error when connecting to RabbitMQ broker">>} in 'Elixir.BroadwayRabbitMQ.Producer':handle_connection_failure/2 line 425
2020-05-12 22:50:55.476 [error] <0.8841.0> Supervisor 'Elixir.FidelityRuleEngine.Consumer.Broadway.ProducerSupervisor' had child 'Elixir.FidelityRuleEngine.Consumer.Broadway.Producer_3' started with 'Elixir.Broadway.Producer':start_link([{broadway,[{hibernate_after,15000},{batchers,[]},{context,context_not_set},{resubscribe_interval,...},...]},...], 3, [{name,'Elixir.FidelityRuleEngine.Consumer.Broadway.Producer_3'},{hibernate_after,15000}]) at <0.9072.0> exit with reason #{'__exception__' => true,'__struct__' => 'Elixir.RuntimeError',message => <<"unexpected error when connecting to RabbitMQ broker">>} in 'Elixir.BroadwayRabbitMQ.Producer':handle_connection_failure/2 line 425 in context child_terminated
2020-05-12 22:50:55.477 [error] <0.9071.0> CRASH REPORT Process 'Elixir.FidelityRuleEngine.Consumer.Broadway.Producer_2' with 0 neighbours crashed with reason: #{'__exception__' => true,'__struct__' => 'Elixir.RuntimeError',message => <<"unexpected error when connecting to RabbitMQ broker">>} in 'Elixir.BroadwayRabbitMQ.Producer':handle_connection_failure/2 line 425
2020-05-12 22:50:55.477 [error] <0.9070.0> CRASH REPORT Process 'Elixir.FidelityRuleEngine.Consumer.Broadway.Producer_4' with 0 neighbours crashed with reason: #{'__exception__' => true,'__struct__' => 'Elixir.RuntimeError',message => <<"unexpected error when connecting to RabbitMQ broker">>} in 'Elixir.BroadwayRabbitMQ.Producer':handle_connection_failure/2 line 425
2020-05-12 22:50:55.478 [error] <0.8841.0> Supervisor 'Elixir.FidelityRuleEngine.Consumer.Broadway.ProducerSupervisor' had child 'Elixir.FidelityRuleEngine.Consumer.Broadway.Producer_2' started with 'Elixir.Broadway.Producer':start_link([{broadway,[{hibernate_after,15000},{batchers,[]},{context,context_not_set},{resubscribe_interval,...},...]},...], 2, [{name,'Elixir.FidelityRuleEngine.Consumer.Broadway.Producer_2'},{hibernate_after,15000}]) at <0.9071.0> exit with reason #{'__exception__' => true,'__struct__' => 'Elixir.RuntimeError',message => <<"unexpected error when connecting to RabbitMQ broker">>} in 'Elixir.BroadwayRabbitMQ.Producer':handle_connection_failure/2 line 425 in context child_terminated
2020-05-12 22:50:55.480 [error] <0.8841.0> Supervisor 'Elixir.FidelityRuleEngine.Consumer.Broadway.ProducerSupervisor' had child 'Elixir.FidelityRuleEngine.Consumer.Broadway.Producer_4' started with 'Elixir.Broadway.Producer':start_link([{broadway,[{hibernate_after,15000},{batchers,[]},{context,context_not_set},{resubscribe_interval,...},...]},...], 4, [{name,'Elixir.FidelityRuleEngine.Consumer.Broadway.Producer_4'},{hibernate_after,15000}]) at <0.9070.0> exit with reason #{'__exception__' => true,'__struct__' => 'Elixir.RuntimeError',message => <<"unexpected error when connecting to RabbitMQ broker">>} in 'Elixir.BroadwayRabbitMQ.Producer':handle_connection_failure/2 line 425 in context child_terminated
2020-05-12 22:50:55.480 [error] <0.9073.0> CRASH REPORT Process 'Elixir.FidelityRuleEngine.Consumer.Broadway.Producer_1' with 0 neighbours crashed with reason: #{'__exception__' => true,'__struct__' => 'Elixir.RuntimeError',message => <<"unexpected error when connecting to RabbitMQ broker">>} in 'Elixir.BroadwayRabbitMQ.Producer':handle_connection_failure/2 line 425
2020-05-12 22:50:55.482 [error] <0.8841.0> Supervisor 'Elixir.FidelityRuleEngine.Consumer.Broadway.ProducerSupervisor' had child 'Elixir.FidelityRuleEngine.Consumer.Broadway.Producer_1' started with 'Elixir.Broadway.Producer':start_link([{broadway,[{hibernate_after,15000},{batchers,[]},{context,context_not_set},{resubscribe_interval,...},...]},...], 1, [{name,'Elixir.FidelityRuleEngine.Consumer.Broadway.Producer_1'},{hibernate_after,15000}]) at <0.9073.0> exit with reason #{'__exception__' => true,'__struct__' => 'Elixir.RuntimeError',message => <<"unexpected error when connecting to RabbitMQ broker">>} in 'Elixir.BroadwayRabbitMQ.Producer':handle_connection_failure/2 line 425 in context child_terminated
2020-05-12 22:50:55.482 [error] <0.9074.0> CRASH REPORT Process 'Elixir.FidelityRuleEngine.Consumer.Broadway.Producer_0' with 0 neighbours crashed with reason: #{'__exception__' => true,'__struct__' => 'Elixir.RuntimeError',message => <<"unexpected error when connecting to RabbitMQ broker">>} in 'Elixir.BroadwayRabbitMQ.Producer':handle_connection_failure/2 line 425
2020-05-12 22:50:55.484 [error] <0.8841.0> Supervisor 'Elixir.FidelityRuleEngine.Consumer.Broadway.ProducerSupervisor' had child 'Elixir.FidelityRuleEngine.Consumer.Broadway.Producer_0' started with 'Elixir.Broadway.Producer':start_link([{broadway,[{hibernate_after,15000},{batchers,[]},{context,context_not_set},{resubscribe_interval,...},...]},...], 0, [{name,'Elixir.FidelityRuleEngine.Consumer.Broadway.Producer_0'},{hibernate_after,15000}]) at <0.9074.0> exit with reason #{'__exception__' => true,'__struct__' => 'Elixir.RuntimeError',message => <<"unexpected error when connecting to RabbitMQ broker">>} in 'Elixir.BroadwayRabbitMQ.Producer':handle_connection_failure/2 line 425 in context child_terminated
2020-05-12 22:50:58.541 [error] <0.9091.0> gen_server 'Elixir.FidelityRuleEngine.Consumer.Broadway.Producer_2' terminated with reason: #{'__exception__' => true,'__struct__' => 'Elixir.RuntimeError',message => <<"unexpected error when connecting to RabbitMQ broker">>} in 'Elixir.BroadwayRabbitMQ.Producer':handle_connection_failure/2 line 425
2020-05-12 22:50:58.541 [error] <0.9092.0> gen_server 'Elixir.FidelityRuleEngine.Consumer.Broadway.Producer_4' terminated with reason: #{'__exception__' => true,'__struct__' => 'Elixir.RuntimeError',message => <<"unexpected error when connecting to RabbitMQ broker">>} in 'Elixir.BroadwayRabbitMQ.Producer':handle_connection_failure/2 line 425
2020-05-12 22:50:58.542 [error] <0.9093.0> gen_server 'Elixir.FidelityRuleEngine.Consumer.Broadway.Producer_1' terminated with reason: #{'__exception__' => true,'__struct__' => 'Elixir.RuntimeError',message => <<"unexpected error when connecting to RabbitMQ broker">>} in 'Elixir.BroadwayRabbitMQ.Producer':handle_connection_failure/2 line 425
2020-05-12 22:50:58.543 [error] <0.9090.0> gen_server 'Elixir.FidelityRuleEngine.Consumer.Broadway.Producer_3' terminated with reason: #{'__exception__' => true,'__struct__' => 'Elixir.RuntimeError',message => <<"unexpected error when connecting to RabbitMQ broker">>} in 'Elixir.BroadwayRabbitMQ.Producer':handle_connection_failure/2 line 425
2020-05-12 22:50:58.543 [error] <0.9094.0> gen_server 'Elixir.FidelityRuleEngine.Consumer.Broadway.Producer_0' terminated with reason: #{'__exception__' => true,'__struct__' => 'Elixir.RuntimeError',message => <<"unexpected error when connecting to RabbitMQ broker">>} in 'Elixir.BroadwayRabbitMQ.Producer':handle_connection_failure/2 line 425
2020-05-12 22:50:58.546 [error] <0.9091.0> CRASH REPORT Process 'Elixir.FidelityRuleEngine.Consumer.Broadway.Producer_2' with 0 neighbours crashed with reason: #{'__exception__' => true,'__struct__' => 'Elixir.RuntimeError',message => <<"unexpected error when connecting to RabbitMQ broker">>} in 'Elixir.BroadwayRabbitMQ.Producer':handle_connection_failure/2 line 425
2020-05-12 22:50:58.547 [error] <0.8841.0> Supervisor 'Elixir.FidelityRuleEngine.Consumer.Broadway.ProducerSupervisor' had child 'Elixir.FidelityRuleEngine.Consumer.Broadway.Producer_2' started with 'Elixir.Broadway.Producer':start_link([{broadway,[{hibernate_after,15000},{batchers,[]},{context,context_not_set},{resubscribe_interval,...},...]},...], 2, [{name,'Elixir.FidelityRuleEngine.Consumer.Broadway.Producer_2'},{hibernate_after,15000}]) at <0.9091.0> exit with reason #{'__exception__' => true,'__struct__' => 'Elixir.RuntimeError',message => <<"unexpected error when connecting to RabbitMQ broker">>} in 'Elixir.BroadwayRabbitMQ.Producer':handle_connection_failure/2 line 425 in context child_terminated
2020-05-12 22:50:58.548 [error] <0.9093.0> CRASH REPORT Process 'Elixir.FidelityRuleEngine.Consumer.Broadway.Producer_1' with 0 neighbours crashed with reason: #{'__exception__' => true,'__struct__' => 'Elixir.RuntimeError',message => <<"unexpected error when connecting to RabbitMQ broker">>} in 'Elixir.BroadwayRabbitMQ.Producer':handle_connection_failure/2 line 425
2020-05-12 22:50:58.549 [error] <0.9092.0> CRASH REPORT Process 'Elixir.FidelityRuleEngine.Consumer.Broadway.Producer_4' with 0 neighbours crashed with reason: #{'__exception__' => true,'__struct__' => 'Elixir.RuntimeError',message => <<"unexpected error when connecting to RabbitMQ broker">>} in 'Elixir.BroadwayRabbitMQ.Producer':handle_connection_failure/2 line 425
2020-05-12 22:50:58.550 [error] <0.8841.0> Supervisor 'Elixir.FidelityRuleEngine.Consumer.Broadway.ProducerSupervisor' had child 'Elixir.FidelityRuleEngine.Consumer.Broadway.Producer_1' started with 'Elixir.Broadway.Producer':start_link([{broadway,[{hibernate_after,15000},{batchers,[]},{context,context_not_set},{resubscribe_interval,...},...]},...], 1, [{name,'Elixir.FidelityRuleEngine.Consumer.Broadway.Producer_1'},{hibernate_after,15000}]) at <0.9093.0> exit with reason #{'__exception__' => true,'__struct__' => 'Elixir.RuntimeError',message => <<"unexpected error when connecting to RabbitMQ broker">>} in 'Elixir.BroadwayRabbitMQ.Producer':handle_connection_failure/2 line 425 in context child_terminated
2020-05-12 22:50:58.550 [error] <0.9094.0> CRASH REPORT Process 'Elixir.FidelityRuleEngine.Consumer.Broadway.Producer_0' with 0 neighbours crashed with reason: #{'__exception__' => true,'__struct__' => 'Elixir.RuntimeError',message => <<"unexpected error when connecting to RabbitMQ broker">>} in 'Elixir.BroadwayRabbitMQ.Producer':handle_connection_failure/2 line 425
2020-05-12 22:50:58.552 [error] <0.8841.0> Supervisor 'Elixir.FidelityRuleEngine.Consumer.Broadway.ProducerSupervisor' had child 'Elixir.FidelityRuleEngine.Consumer.Broadway.Producer_4' started with 'Elixir.Broadway.Producer':start_link([{broadway,[{hibernate_after,15000},{batchers,[]},{context,context_not_set},{resubscribe_interval,...},...]},...], 4, [{name,'Elixir.FidelityRuleEngine.Consumer.Broadway.Producer_4'},{hibernate_after,15000}]) at <0.9092.0> exit with reason #{'__exception__' => true,'__struct__' => 'Elixir.RuntimeError',message => <<"unexpected error when connecting to RabbitMQ broker">>} in 'Elixir.BroadwayRabbitMQ.Producer':handle_connection_failure/2 line 425 in context child_terminated
2020-05-12 22:50:58.552 [error] <0.9090.0> CRASH REPORT Process 'Elixir.FidelityRuleEngine.Consumer.Broadway.Producer_3' with 0 neighbours crashed with reason: #{'__exception__' => true,'__struct__' => 'Elixir.RuntimeError',message => <<"unexpected error when connecting to RabbitMQ broker">>} in 'Elixir.BroadwayRabbitMQ.Producer':handle_connection_failure/2 line 425
2020-05-12 22:50:58.555 [error] <0.8841.0> Supervisor 'Elixir.FidelityRuleEngine.Consumer.Broadway.ProducerSupervisor' had child 'Elixir.FidelityRuleEngine.Consumer.Broadway.Producer_0' started with 'Elixir.Broadway.Producer':start_link([{broadway,[{hibernate_after,15000},{batchers,[]},{context,context_not_set},{resubscribe_interval,...},...]},...], 0, [{name,'Elixir.FidelityRuleEngine.Consumer.Broadway.Producer_0'},{hibernate_after,15000}]) at <0.9094.0> exit with reason #{'__exception__' => true,'__struct__' => 'Elixir.RuntimeError',message => <<"unexpected error when connecting to RabbitMQ broker">>} in 'Elixir.BroadwayRabbitMQ.Producer':handle_connection_failure/2 line 425 in context child_terminated
2020-05-12 22:50:58.556 [error] <0.8841.0> Supervisor 'Elixir.FidelityRuleEngine.Consumer.Broadway.ProducerSupervisor' had child 'Elixir.FidelityRuleEngine.Consumer.Broadway.Producer_3' started with 'Elixir.Broadway.Producer':start_link([{broadway,[{hibernate_after,15000},{batchers,[]},{context,context_not_set},{resubscribe_interval,...},...]},...], 3, [{name,'Elixir.FidelityRuleEngine.Consumer.Broadway.Producer_3'},{hibernate_after,15000}]) at <0.9090.0> exit with reason #{'__exception__' => true,'__struct__' => 'Elixir.RuntimeError',message => <<"unexpected error when connecting to RabbitMQ broker">>} in 'Elixir.BroadwayRabbitMQ.Producer':handle_connection_failure/2 line 425 in context child_terminated
